Workbook
Name CostoVentasBase: Inputs!$C$40
Name DeltaModQ2: Inputs!$D$75
Name DeltaModQ3: Inputs!$D$76
Name DeltaModQ4: Inputs!$D$77
Name DeltaVtasQ2: Inputs!$E$75
Name DeltaVtasQ3: Inputs!$E$76
Name DeltaVtasQ4: Inputs!$E$77
Name GtosAdminBase: Inputs!$C$44
Name GtosNoOpBase: Inputs!$C$54
Name GtosOpInflado: Inputs!$D$55
Name GtosVentasBase: Inputs!$C$48
Name InflacionAnual: Inputs!$C$11
Name IngNoOpBase: Inputs!$C$53
Name TasaDeudaLp: Inputs!$C$28
Name TasaImpuesto: Inputs!$C$25
Name TrmLargoPlazo: Inputs!$C$6

Sheet Auditoría
A1: INFORME DE AUDITORÍA DE MODELO
A2: Modelo Presupuesto Completo COCO V3 — alcance: 11 hojas, 8.100 fórmulas. Revisión al 13-ago-2026.
A4: OPINIÓN GENERAL
A5: El modelo está bien construido en su mecánica: el balance cuadra en los 13 períodos, no hay errores de fórmula ni vínculos externos, la circularidad está resuelta y las correcciones previas están documentadas celda por celda. Pero NO es confiable hoy para presentarlo a junta, banco o inversionista, por una razón que no es mecánica sino de contenido: el presupuesto de agosto a diciembre no fue re-basificado a los resultados reales y el costo de ventas quedó congelado. El resultado es una utilidad bruta sobreestimada en aproximadamente COP 2.371 millones en el semestre y una proyección de caja que ya arroja saldos negativos. Corregidos los tres hallazgos críticos, el modelo es apto para decidir.
A7: HALLAZGOS CRÍTICOS — el modelo no debe usarse hasta corregirlos
A8: ID | B8: Hoja | C8: Celdas | D8: Impacto COP | E8: Hallazgo y evidencia | F8: Corrección recomendada
A9: C-1 | B9: Modelo Base | C9: M52:Q52 (fila 52) | D9: =-('Modelo Base'!M51+'Modelo Base'!N51+'Modelo Base'!O51+'Modelo Base'!P51+'Modelo Base'!Q51)*(1-'Modelo Base'!L54)+SUM('Modelo Base'!M52:Q52) -> -2.3756143e+09 | E9: Costo de ventas congelado ago-dic en 352,5 MM (ago-oct) y 362,6 MM (nov-dic) mientras el ingreso crece de 1.573,6 a 1.939,3 MM. El margen bruto salta de 52,7% real en julio a 77,6%-81,3% presupuestado. El costo no está atado al ingreso: no hay driver. | F9: Definir el costo de ventas como % del ingreso en una celda de supuesto (52,7% según julio real; 47,3% de costo) y proyectar =Ingreso × (1 - margen). El impacto en D9 es la utilidad bruta sobreestimada.
A10: C-2 | B10: Modelo Base / Consol. Pptos | C10: fila 51, filas 21:23 | D10: =('Modelo Base'!M51/'Modelo Base'!L51-1) -> 1.3145285 | E10: Presupuesto ago-dic no re-basificado a los reales. Julio real cerró en 679,9 MM contra un presupuesto de 1.360,0 MM (cumplimiento 50,0%), y agosto presupuesta 1.573,6 MM — 2,31 veces el real de julio. El salto que muestra D10 no tiene sustento operativo en la serie real ene-jul (612 a 826 MM). | F10: Re-basificar la curva ago-dic al run-rate real y documentar el puente (precio, volumen, nuevos canales) que justifique cualquier salto. Sin ese puente, usar el escenario Conservador.
A11: C-3 | B11: Modelo Base | C11: M189, N189, O189 | D11: ='Modelo Base'!M189 -> -8.6773382e+08 | E11: Caja de cierre negativa tres meses seguidos: (867,7) MM en agosto, (554,4) MM en septiembre y (181,5) MM en octubre. El balance cuadra porque la caja actúa de plug, así que el déficit no se ve en el check de la fila 105. La línea intercompañía de 750,4 MM es insuficiente: la propia alerta M191 dice que faltan 1.067,7 MM en agosto. | F11: El déficit se reduce fuerte al corregir C-1 y C-2. Lo que quede debe cerrarse con una fuente identificada (capitalización, cupo bancario o recuperación de otros deudores) y modelarse como línea de financiación, no dejarse como caja negativa.
A13: HALLAZGOS IMPORTANTES
A14: I-1 | B14: Modelo Base | C14: J228, K228 | E14: El check de capital de trabajo del propio modelo está fallando: 117,2 MM en mayo y (69,4) MM en junio. Además el check está definido con dos fórmulas distintas — F:I usa =F224-(-(F79-E79)+(F89-E89)+(F90-E90)) y J:Q usa =ROUND((J119-I119)+SUM(J164:J166),0). Un check con dos definiciones no es un check. | F14: Unificar una sola definición en toda la fila y resolver el descuadre de mayo-junio antes de firmar el mes.
A15: I-2 | B15: Modelo Base | C15: J136:Q136 | E15: El interés de la CxP con Coco Delaware está apagado con =0*$T$30 de mayo a diciembre, mientras ene-abr usa =$T$30*AVERAGE(...)/12. Hoy T30=0% así que no cambia cifras, pero el driver está muerto: sobre un saldo de 2.641 a 3.392 MM, cada punto de tasa vale ~28 MM al año que el modelo nunca reconocería. | F15: Reemplazar por =$T$30*AVERAGE(J141,J144)/12 en J:Q, igual que ene-abr. Si la tasa es realmente 0%, dejarlo referenciado a T30 de todas formas.
A16: I-3 | B16: Modelo Base | C16: F137:I137 vs J137:Q137 | E16: Base de cálculo del interés de tarjetas inconsistente: ene-abr sobre saldo promedio, may-dic sobre saldo inicial. | F16: Elegir una convención (saldo inicial evita circularidad) y aplicarla a los doce meses.
A17: I-4 | B17: Modelo Base | C17: I126, I124, J124 | E17: PP&E neto de abril entra como 3.433,0 MM desde Inputs!$G$97, frente a 218-226 MM en todos los demás meses. Eso genera un CapEx de +3.213 MM en abril y de (3.150) MM en mayo dentro del cronograma. El flujo de caja ya se blindó (filas 174 usan la variación del balance), pero el cronograma de PP&E quedó inservible y M123 tuvo que forzarse al saldo real de julio. | F17: Verificar qué contiene Inputs!G97 (no parece ser PP&E) y reconectar I126 al PP&E neto real de abril.
A18: I-5 | B18: Modelo Base | C18: E31 = 100% | E18: Impuestos por pagar = 100% del impuesto causado, es decir el modelo no paga un peso de impuesto en caja en todo el año y acumula 381,3 MM al cierre. Prueba de estrés: al ponerlo en 0% la caja de agosto empeora de (867,7) a (1.127) MM y sigue negativa hasta noviembre. | F18: Modelar el calendario real de pagos (anticipos de renta, retenciones, ICA, IVA) en vez de un porcentaje único.
A19: I-6 | B19: Modelo Base | C19: E28 = 52 días | E19: DPO presupuestado de 52 días contra 37,6 días reales en julio (CxP 403,8 MM sobre costo 321,9 MM). Sobreestima la CxP en unos 150 MM, que el modelo lee como caja disponible. | F19: Bajar el DPO al real observado o justificar la extensión de plazo con proveedores.
A20: I-7 | B20: Modelo Base | C20: L142 vs M142:Q142 | E20: Dos definiciones de capacidad remanente de la línea: julio usa $T$29-L141 y ago-dic usa $T$29-(M141-$L$94). | F20: Unificar la fórmula en L:Q.
A21: I-8 | B21: Modelo Base | C21: T28, T29 | E21: La capacidad de la línea es la caja de EE.UU. al 31-jul (USD 302.332) convertida a TRM de largo plazo, y se mantiene constante. La nota de la propia celda reconoce que no modela la quema de EE.UU. (~USD 12.128 al mes), ni hay sensibilidad a TRM. La capacidad está sobreestimada y crece el error con el tiempo. | F21: Proyectar la caja de EE.UU. mes a mes restando su quema, y usar la TRM del mes en vez de la de largo plazo.
A22: I-9 | B22: Modelo Base | C22: D167, D168, D169 = 0 | E22: Otros deudores (~882 MM), fiducia y obligaciones laborales congelados en cero variación. Es conservador, pero implica que ninguna de esas fuentes de caja se activa; la nota de D167 señala que al 25% mensual otros deudores liberaría ~882 MM el primer mes — más que el faltante de octubre. | F22: Definir un supuesto de recuperación defendible: es la palanca de caja más grande y más barata que tiene el modelo sin tocar el ingreso.
A23: I-10 | B23: Informe Accionista | C23: C56:I57 | E23: Enlace roto: las filas de Churn (-) y Contracción (-) apuntan a 'Consol. Pptos' filas 243 y 244, que pertenecen a otra tabla y devuelven cero. Deben apuntar a las filas 226 y 227. Efecto: la composición de ingresos no cuadra con su propio total en ningún mes — faltan USD 15.867 en mayo, 23.800 en junio y 31.733 en julio. | F23: Cambiar C56 a ='Consol. Pptos'!D226 y C57 a ='Consol. Pptos'!D227, y arrastrar hasta la columna I.
A24: I-11 | B24: Consolidado | C24: G11, L11, Q11, C11, E11 | E24: El bloque consolidado por mes no concilia con el P&G acumulado: la suma de los cuatro períodos da USD 217.562 de EBITDA contra USD 127.717 del acumulado, una diferencia de USD 89.844. El 98% está en gastos de administración, porque en enero-abril la administración de Estados Unidos entra en NEGATIVO (USD (46.372,59)) y la de Costa Rica también (USD (17.320,22)). Un gasto negativo infla el EBITDA. Segunda causa: el acumulado convierte Colombia a tasa única de 3.505,27 mientras cada mes usa la suya. Tercera: la fórmula de administración toma de Perú la línea PROINNOVATE en ene-abr, mayo y junio (D22, I22, N22) pero la de administración en julio (S11). | F24: Reconstruir el bloque mensual desde los auxiliares con signos correctos, unificar la base de Perú en las cuatro columnas y declarar la tasa de conversión usada. Mientras tanto, para cifras consolidadas usar solo el P&G acumulado (filas 34-49).
A25: MENORES / BUENAS PRÁCTICAS
A26: M-1 | B26: Modelo Base | C26: filas 56, 57, 58 (M:Q) | E26: Gastos de administración, ventas y operativos planos ago-dic (135,4 / 230,9 / 113,0 MM) sin driver de crecimiento ni inflación mensual, mientras el ingreso crece 23% en el mismo tramo.
A27: M-2 | B27: Modelo Base | C27: fila 105 | E27: El check de balance usa tolerancias distintas por columna: E sin tolerancia, F hasta 2 pesos, G:Q hasta 5 pesos. Homogenizar para que el check sea comparable.
A28: M-3 | B28: Modelo Base | C28: E21, E22 | E28: Etiquetas de escenario con espacio final ('Conservador ') — frágil si alguna vez se usan en búsquedas o coincidencias.
A29: M-4 | B29: Ppto Ene. 2026 / Ppto Combinado 2026 | C29: 44 fórmulas | E29: 44 fórmulas con IFERROR que pueden estar silenciando errores reales en vez de mostrarlos. Revisar qué esconden.
A30: M-5 | B30: Todo el libro | C30: 1.182 casos | E30: 1.182 constantes numéricas dentro de fórmulas. La mayoría es escalado /1.000.000 en textos de alerta (inocuo), pero E18 codifica 47/52/57 como números de fila de la hoja Revenue dentro de un IF — se rompe silenciosamente si se insertan filas.
A32: PRUEBAS DE ESTRÉS (drivers revertidos a su valor original tras la prueba)
A33: Prueba | B33: Caja dic-26 | C33: Caja ago-26 | E33: Lectura
A34: Caso base (DSO 84 d, impuestos 100% diferidos) | B34: 200000000 | C34: -867733822 | E34: Balance cuadra en los 13 períodos.
A35: DSO 84 → 120 días | B35: -1595000000 | C35: -2756000000 | E35: Responde correctamente: CxC de agosto sube de 4.406 a 6.295 MM y la caja se hunde los cinco meses. Balance sigue cuadrando.
A36: Impuestos por pagar 100% → 0% (pago de caja) | B36: 200000000 | C36: -1127000000 | E36: Responde correctamente: la caja empeora y la recuperación se corre de noviembre a diciembre. Balance sigue cuadrando.
A38: ASPECTOS BIEN RESUELTOS
A39: El balance cuadra exactamente en los 13 períodos y sigue cuadrando bajo estrés de DSO y de impuestos — está cuadrado por construcción, no por una plug forzada.
A40: Cero errores de fórmula (#REF!, #DIV/0!, #N/A, #VALUE!) en las 11 hojas y ningún vínculo a archivos externos: el modelo es autocontenido.
A41: La circularidad pasivo → caja → barrido → pasivo fue identificada y eliminada explícitamente (nota en M182), sin recurrir a cálculo iterativo.
A42: El doble conteo del pasivo con Coco Delaware (2.641,6 MM) fue detectado y corregido en la fila 88 de agosto a diciembre.
A43: Las alertas de caja bajo mínimo y de suficiencia de la línea intercompañía (filas 190-191) están bien construidas y son visibles — el modelo avisa de su propio problema de caja.
A44: Documentación por notas de celda sobresaliente: prácticamente cada corrección histórica deja su rastro con el 'antes' y el 'por qué'. Es lo que permitió auditar este modelo en horas y no en días.
A46: ALCANCE Y LIMITACIONES
...

Sheet Pack Junta Jul-26
A1: PACK JUNTA — JULIO 2026 · P&G mensual real y puente presupuesto → real
A2: Perímetro: COCO Tecnologías COLOMBIA (entidad legal). NO incluye Coco Delaware (EE.UU.). Cifras en COP millones salvo donde se indique. Fuente: 'Modelo Base' filas 51-72.
A4: 1. P&G MENSUAL REAL ENE-JUL 2026 — COLOMBIA (COP millones)
A5: Línea | B5: ='Modelo Base'!F50 -> Ene-26 | C5: ='Modelo Base'!G50 -> Feb-26 | D5: ='Modelo Base'!H50 -> Mar-26 | E5: ='Modelo Base'!I50 -> Abr-26 | F5: ='Modelo Base'!J50 -> May-26 | G5: ='Modelo Base'!K50 -> Jun-26 | H5: ='Modelo Base'!L50 -> Jul-26 | I5: Acum Ene-Jul
A6: Ingresos netos | B6: ='Modelo Base'!F51/10^6 -> 612.2477 | C6: ='Modelo Base'!G51/10^6 -> 744.21814 | D6: ='Modelo Base'!H51/10^6 -> 787.04119 | E6: ='Modelo Base'!I51/10^6 -> 750.86766 | F6: ='Modelo Base'!J51/10^6 -> 826.51475 | G6: ='Modelo Base'!K51/10^6 -> 751.45331 | H6: ='Modelo Base'!L51/10^6 -> 679.89055 | I6: =SUM(B6:H6) -> 5152.2333
A7: Costo del servicio | B7: ='Modelo Base'!F52/10^6 -> 238.53579 | C7: ='Modelo Base'!G52/10^6 -> 343.30879 | D7: ='Modelo Base'!H52/10^6 -> 455.6392 | E7: ='Modelo Base'!I52/10^6 -> 379.27359 | F7: ='Modelo Base'!J52/10^6 -> 355.47052 | G7: ='Modelo Base'!K52/10^6 -> 348.47761 | H7: ='Modelo Base'!L52/10^6 -> 321.91784 | I7: =SUM(B7:H7) -> 2442.6233
A8: Utilidad bruta | B8: =B6-B7 -> 373.71191 | C8: =C6-C7 -> 400.90935 | D8: =D6-D7 -> 331.40199 | E8: =E6-E7 -> 371.59407 | F8: =F6-F7 -> 471.04422 | G8: =G6-G7 -> 402.97571 | H8: =H6-H7 -> 357.97271 | I8: =SUM(B8:H8) -> 2709.61
A9: Margen bruto % | B9: =IF(B6=0,0,B8/B6) -> 0.61039332 | C9: =IF(C6=0,0,C8/C6) -> 0.5386987 | D9: =IF(D6=0,0,D8/D6) -> 0.42107324 | E9: =IF(E6=0,0,E8/E6) -> 0.49488623 | F9: =IF(F6=0,0,F8/F6) -> 0.5699163 | G9: =IF(G6=0,0,G8/G6) -> 0.5362618 | H9: =IF(H6=0,0,H8/H6) -> 0.52651521 | I9: =IF(I6=0,0,I8/I6) -> 0.52590979
A10: Gastos de administración | B10: ='Modelo Base'!F56/10^6 -> 98.722435 | C10: ='Modelo Base'!G56/10^6 -> 105.63347 | D10: ='Modelo Base'!H56/10^6 -> 141.81187 | E10: ='Modelo Base'!I56/10^6 -> 114.28089 | F10: ='Modelo Base'!J56/10^6 -> 116.80882 | G10: ='Modelo Base'!K56/10^6 -> 112.28869 | H10: ='Modelo Base'!L56/10^6 -> 107.93274 | I10: =SUM(B10:H10) -> 797.47892
A11: Gastos de ventas | B11: ='Modelo Base'!F57/10^6 -> 131.60026 | C11: ='Modelo Base'!G57/10^6 -> 173.6322 | D11: ='Modelo Base'!H57/10^6 -> 139.61578 | E11: ='Modelo Base'!I57/10^6 -> 130.09042 | F11: ='Modelo Base'!J57/10^6 -> 120.23321 | G11: ='Modelo Base'!K57/10^6 -> 146.80346 | H11: ='Modelo Base'!L57/10^6 -> 117.76124 | I11: =SUM(B11:H11) -> 959.73656
A12: Gastos de operación / proyectos | B12: ='Modelo Base'!F58/10^6 -> 73.409852 | C12: ='Modelo Base'!G58/10^6 -> 75.509638 | D12: ='Modelo Base'!H58/10^6 -> 72.217138 | E12: ='Modelo Base'!I58/10^6 -> 122.38451 | F12: ='Modelo Base'!J58/10^6 -> 120.99271 | G12: ='Modelo Base'!K58/10^6 -> 108.90806 | H12: ='Modelo Base'!L58/10^6 -> 102.93637 | I12: =SUM(B12:H12) -> 676.35829
A13: EBITDA | B13: =B8-B10-B11-B12 -> 69.979361 | C13: =C8-C10-C11-C12 -> 46.134032 | D13: =D8-D10-D11-D12 -> -22.242793 | E13: =E8-E10-E11-E12 -> 4.838252 | F13: =F8-F10-F11-F12 -> 113.00947 | G13: =G8-G10-G11-G12 -> 34.975495 | H13: =H8-H10-H11-H12 -> 29.342362 | I13: =SUM(B13:H13) -> 276.03618
A14: Margen EBITDA % | B14: =IF(B6=0,0,B13/B6) -> 0.1142991 | C14: =IF(C6=0,0,C13/C6) -> 0.061989932 | D14: =IF(D6=0,0,D13/D6) -> -0.028261282 | E14: =IF(E6=0,0,E13/E6) -> 0.0064435482 | F14: =IF(F6=0,0,F13/F6) -> 0.13673014 | G14: =IF(G6=0,0,G13/G6) -> 0.046543803 | H14: =IF(H6=0,0,H13/H6) -> 0.043157479 | I14: =IF(I6=0,0,I13/I6) -> 0.053576026
A15: Utilidad antes de impuestos | B15: ='Modelo Base'!F67/10^6 -> 63.485497 | C15: ='Modelo Base'!G67/10^6 -> 54.048915 | D15: ='Modelo Base'!H67/10^6 -> -37.938007 | E15: ='Modelo Base'!I67/10^6 -> 0.706203 | F15: ='Modelo Base'!J67/10^6 -> 108.37497 | G15: ='Modelo Base'!K67/10^6 -> 33.34365 | H15: ='Modelo Base'!L67/10^6 -> 24.707052 | I15: =SUM(B15:H15) -> 246.72828
A16: Impuesto de renta registrado | B16: ='Modelo Base'!F69/10^6 -> 0 | C16: ='Modelo Base'!G69/10^6 -> 0 | D16: ='Modelo Base'!H69/10^6 -> 0 | E16: ='Modelo Base'!I69/10^6 -> 0 | F16: ='Modelo Base'!J69/10^6 -> 0 | G16: ='Modelo Base'!K69/10^6 -> 0 | H16: ='Modelo Base'!L69/10^6 -> 0 | I16: =SUM(B16:H16) -> 0
A17: Utilidad neta (según EEFF) | B17: =B15-B16 -> 63.485497 | C17: =C15-C16 -> 54.048915 | D17: =D15-D16 -> -37.938007 | E17: =E15-E16 -> 0.706203 | F17: =F15-F16 -> 108.37497 | G17: =G15-G16 -> 33.34365 | H17: =H15-H16 -> 24.707052 | I17: =SUM(B17:H17) -> 246.72828
A18: Margen neto % | B18: =IF(B6=0,0,B17/B6) -> 0.1036925 | C18: =IF(C6=0,0,C17/C6) -> 0.072625098 | D18: =IF(D6=0,0,D17/D6) -> -0.048203331 | E18: =IF(E6=0,0,E17/E6) -> 0.00094051593 | F18: =IF(F6=0,0,F17/F6) -> 0.13112285 | G18: =IF(G6=0,0,G17/G6) -> 0.044372218 | H18: =IF(H6=0,0,H17/H6) -> 0.036339749 | I18: =IF(I6=0,0,I17/I6) -> 0.047887637
A19: Memo: provisión de renta 35% no registrada | B19: ='Modelo Base'!F72/10^6 -> 22.219924 | C19: ='Modelo Base'!G72/10^6 -> 18.91712 | D19: ='Modelo Base'!H72/10^6 -> 0 | E19: ='Modelo Base'!I72/10^6 -> 0.24717105 | F19: ='Modelo Base'!J72/10^6 -> 37.931239 | G19: ='Modelo Base'!K72/10^6 -> 11.670277 | H19: ='Modelo Base'!L72/10^6 -> 8.6474682 | I19: =SUM(B19:H19) -> 99.6332
A20: Memo: utilidad neta con renta provisionada | B20: =B17-B19 -> 41.265573 | C20: =C17-C19 -> 35.131795 | D20: =D17-D19 -> -37.938007 | E20: =E17-E19 -> 0.45903195 | F20: =F17-F19 -> 70.443729 | G20: =G17-G19 -> 21.673372 | H20: =H17-H19 -> 16.059584 | I20: =SUM(B20:H20) -> 147.09508
A22: 2. P&G PRESUPUESTADO DE JULIO 2026 vs REAL
A23: Línea | B23: Ppto orig. Ene (USD) | C23: Ppto orig. Ene (COP MM) | D23: Real jul (COP MM) | E23: Var COP MM | F23: Cumpl. %
A24: Ingresos netos | B24: ='Informe Accionista'!I65 -> 388085 | C24: =B24*'Ppto Combinado 2026'!$C$5/10^6 -> 1552.34 | D24: =H6 -> 679.89055 | E24: =D24-C24 -> -872.44945 | F24: =IF(C24=0,0,D24/C24) -> 0.43797786
A25: Costo del servicio | B25: ='Informe Accionista'!I66 -> 111362 | C25: =B25*'Ppto Combinado 2026'!$C$5/10^6 -> 445.448 | D25: =H7 -> 321.91784 | E25: =D25-C25 -> -123.53016 | F25: =IF(C25=0,0,D25/C25) -> 0.72268332
A26: Utilidad bruta | B26: =B24-B25 -> 276723 | C26: =C24-C25 -> 1106.892 | D26: =D24-D25 -> 357.97271 | E26: =D26-C26 -> -748.91929 | F26: =IF(C26=0,0,D26/C26) -> 0.32340347
A27: Gastos de administración | B27: ='Informe Accionista'!I68 -> 33545 | C27: =B27*'Ppto Combinado 2026'!$C$5/10^6 -> 134.18 | D27: =H10 -> 107.93274 | E27: =D27-C27 -> -26.247258 | F27: =IF(C27=0,0,D27/C27) -> 0.8043877
A28: Gastos de ventas | B28: ='Informe Accionista'!I69 -> 54010 | C28: =B28*'Ppto Combinado 2026'!$C$5/10^6 -> 216.04 | D28: =H11 -> 117.76124 | E28: =D28-C28 -> -98.278764 | F28: =IF(C28=0,0,D28/C28) -> 0.54508996
A29: Gastos de operación / proyectos | B29: 0 | C29: =B29*'Ppto Combinado 2026'!$C$5/10^6 -> 0 | D29: =H12 -> 102.93637 | E29: =D29-C29 -> 102.93637 | F29: n/a
A30: EBITDA | B30: =B26-B27-B28-B29 -> 189168 | C30: =C26-C27-C28-C29 -> 756.672 | D30: =D26-D27-D28-D29 -> 29.342362 | E30: =D30-C30 -> -727.32964 | F30: =IF(C30=0,0,D30/C30) -> 0.038778179
A31: Margen EBITDA % | C31: =IF(C24=0,0,C30/C24) -> 0.48743961 | D31: =IF(D24=0,0,D30/D24) -> 0.043157479
A32: Utilidad neta | B32: ='Informe Accionista'!I74 -> 122166 | C32: =B32*'Ppto Combinado 2026'!$C$5/10^6 -> 488.664 | D32: =H17 -> 24.707052 | E32: =D32-C32 -> -463.95695 | F32: =IF(C32=0,0,D32/C32) -> 0.05056041
A33: Memo — Ppto REVISADO mayo (USD 4,07 MM): solo línea de ingresos | B33: ='Ppto Combinado 2026'!J12 -> 283850.12 | C33: ='Ppto Combinado 2026'!J13/10^6 -> 1047.4069 | D33: =H6 -> 679.89055 | E33: =D33-C33 -> -367.51639 | F33: =IF(C33=0,0,D33/C33) -> 0.64911786
A35: 3. PUENTE DE EBITDA JULIO 2026: PRESUPUESTO → REAL (COP millones)
A36: EBITDA presupuestado julio (ppto original enero) | B36: =C30 -> 756.672
A37: Efecto brecha de ingresos | B37: =E24 -> -872.44945
A38: Efecto costo del servicio (menor costo) | B38: =-E25 -> 123.53016
A39: Efecto gastos de administración | B39: =-E27 -> 26.247258
A40: Efecto gastos de ventas | B40: =-E28 -> 98.278764
A41: Efecto gastos de operación no presupuestados | B41: =-E29 -> -102.93637
A42: EBITDA real julio | B42: =SUM(B36:B41) -> 29.342362
A43: Check: puente vs EBITDA real del P&G | B43: =ROUND(B42-H13,6) -> 0
...

Sheet Burn & RunW
B2: ANÁLISIS CONSOLIDADO — INGRESOS, MÁRGENES, FCF BURN Y RUNWAY
B6: INDICADORES ACUMULADOS CONSOLIDADOS — ENE-JUL 2026 (Colombia y internacional reales a julio)
B7: Indicador | C7: Valor | D7: Unidad | E7: Explicación / criterio
B8: Ingresos acumulados año | C8: =(Inputs!$N$132+SUM('Consolidado '!C6:E7)*'Consolidado '!F4+SUM('Consolidado '!H6:J7)*'Consolidado '!K4+SUM('Consolidado '!M6:O7)*'Consolidado '!P4+SUM('Consolidado '!R6:T7)*'Consolidado '!U4)/1000000 -> 5756.178 | D8: COP MM | E8: Ingresos reales consolidados: Colombia enero-julio (estados financieros) más USA, Perú y Costa Rica de abril a julio; sin doble contar Colombia.
B9: Ingresos acumulados presupuesto | C9: =(SUM('Informe Accionista'!C65:F65)*'Informe Accionista'!$M$3+SUM('Informe Accionista'!G58:I58)*'Informe Accionista'!$M$2)/1000000 -> 8516.2305 | D9: COP MM | E9: Presupuesto acumulado consolidado: enero-abril utiliza el presupuesto original anual de USD 4,555,726; mayo-julio utiliza el nuevo presupuesto consolidado anual de USD 4,067,468 (~USD 4.0MM).
B10: Quema neta acumulada año — Colombia | C10: =MAX(0,('Modelo Base'!$E$34-Inputs!$J$93)/1000000) -> 57.192074 | D10: COP MM | E10: Acumulado enero-julio 2026. Fórmula: MAX(0, Caja inicial al 31-dic-2025 − Caja final al 31-jul-2026). Equivale a sumar todas las variaciones mensuales de la caja histórica de Colombia. No utiliza CapEx estimado.
B11: Quema neta acumulada año — otros países | C11: =MAX(0,-SUM(C15:C18)) -> 381.94731 | D11: COP MM | E11: Acumulado 2026 con información de abril a julio para USA, Perú y Costa Rica. Fórmula: MAX(0, −SUMA de los flujos netos mensuales). Julio usa el movimiento bancario real; abril-junio usan la utilidad contable como aproximación.
B12: Quema neta acumulada año — consolidada | C12: =C10+C11 -> 439.13939 | D12: COP MM | E12: Acumulado 2026: quema neta histórica de Colombia a julio más quema neta de USA, Perú y Costa Rica de abril a julio.
B14: Cumplimeinto Acumulado Presupuesto | C14: =C8/C9 -> 0.67590678
B15: Flujo neto ene-abr — otros países | C15: =SUM(_xlfn.XLOOKUP("Utilidad",'Consolidado '!$B$6:$B$17,'Consolidado '!$C$6:$E$17))*'Consolidado '!$F$4/1000000 -> -154.56619 | D15: COP MM | E15: XLOOKUP busca la fila Utilidad y suma USA, Perú y Costa Rica del acumulado enero-abril.
B16: Flujo neto mayo — otros países | C16: =SUM(_xlfn.XLOOKUP("Utilidad",'Consolidado '!$B$6:$B$17,'Consolidado '!$H$6:$J$17))*'Consolidado '!$K$4/1000000 -> -105.79334 | D16: COP MM | E16: XLOOKUP busca la fila Utilidad y suma USA, Perú y Costa Rica de mayo.
B17: Flujo neto junio — otros países | C17: =SUM(_xlfn.XLOOKUP("Utilidad",'Consolidado '!$B$6:$B$17,'Consolidado '!$M$6:$O$17))*'Consolidado '!$P$4/1000000 -> -81.203976 | D17: COP MM | E17: XLOOKUP busca la fila Utilidad y suma USA, Perú y Costa Rica de junio.
B18: Flujo neto julio — otros países | C18: =SUM('Consolidado '!R25:T25)*'Consolidado '!U4/1000000 -> -40.383806 | D18: COP MM | E18: Movimiento neto de bancos de julio: USA -12.127,75 USD, Perú -166,82 soles y Costa Rica -176,94 USD. No usa la utilidad contable porque Costa Rica facturó 134.104 USD que quedaron por cobrar, no en caja.
B19: El análisis usa la caja total consolidada y el FCF burn consolidado. Colombia proviene de los estados financieros (reales hasta julio); USA, Perú y Costa Rica están incorporados hasta julio, excluyendo Colombia del Consolidado USD para evitar doble conteo.
B20: FCF BURN Y CAMBIO DE CAJA MENSUAL — ENE-JUL 2026 (COP MM)
B21: Mes | C21: CFO Colombia | D21: CapEx Colombia | E21: Flujo caja internacional | F21: FCF / Flujo caja consolidado | G21: FCF Burn | H21: Pre-WC Burn | I21: Cambio neto caja consolidado | J21: Lectura
B22: Ene-26 | C22: ='Modelo Base'!F171/1000000 -> 218.72727 | D22: ='Modelo Base'!F174/1000000 -> -7.359954 | F22: =SUM(C22:E22) -> 211.36731 | G22: =MAX(0,-F22) -> 0 | H22: =MAX(0,-(('Informe Accionista'!C129/1000000)+D22)) -> 0 | I22: ='Modelo Base'!F182/1000000 -> 194.13595 | J22: Enero concentra el mayor FCF burn del periodo.
B23: Feb-26 | C23: ='Modelo Base'!G171/1000000 -> -304.7186 | D23: ='Modelo Base'!G174/1000000 -> -6.269 | F23: =SUM(C23:E23) -> -310.9876 | G23: =MAX(0,-F23) -> 310.9876 | H23: =MAX(0,-(('Informe Accionista'!D129/1000000)+D23)) -> 0 | I23: ='Modelo Base'!G182/1000000 -> -305.29309 | J23: Este mes explica el burn del periodo.
B24: Mar-26 | C24: ='Modelo Base'!H171/1000000 -> 125.65051 | D24: ='Modelo Base'!H174/1000000 -> -0.289048 | F24: =SUM(C24:E24) -> 125.36147 | G24: =MAX(0,-F24) -> 0 | H24: =MAX(0,-(('Informe Accionista'!E129/1000000)+D24)) -> 22.531841 | I24: ='Modelo Base'!H182/1000000 -> 149.18717 | J24: FCF positivo; solo se ve presión en la vista pre-WC.
B25: Abr-26 | C25: ='Modelo Base'!I171/1000000 -> 73.339722 | D25: ='Modelo Base'!I174/1000000 -> 1.2286356 | E25: =(('Consolidado '!C6+'Consolidado '!C11)+('Consolidado '!D6-'Consolidado '!D15)+('Consolidado '!E6+'Consolidado '!E7+'Consolidado '!E11+'Consolidado '!E15))*'Consolidado '!F4/1000000 -> -154.56619 | F25: =SUM(C25:E25) -> -79.997836 | G25: =MAX(0,-F25) -> 79.997836 | H25: =MAX(0,-(('Informe Accionista'!F129/1000000)+D25)) -> 0 | I25: ='Modelo Base'!I182/1000000 -> 88.268448 | J25: Abr: flujo histórico Colombia más caja internacional real disponible.
B26: May-26 | C26: =(Inputs!H155+(Inputs!H109-Inputs!G109)+(Inputs!H113-Inputs!G113)+(Inputs!H112-Inputs!G112)-(Inputs!H96-Inputs!G96)-(Inputs!H94-Inputs!G94)-(Inputs!H97-Inputs!G97))/1000000 -> -86.36183 | D26: =-(Inputs!H101-Inputs!G101)/1000000 -> -7.792981 | E26: =(SUM('Consolidado '!H6:J7)-SUM('Consolidado '!H9:J9,'Consolidado '!H11:J13,'Consolidado '!H15:J15))*'Consolidado '!K4/1000000 -> -105.79334 | F26: =SUM(C26:E26) -> -199.94815 | G26: =MAX(0,-F26) -> 199.94815 | H26: =MAX(0,-('Informe Accionista'!G129/1000000+D26)) -> 0 | I26: =(Inputs!H93-Inputs!G93)/1000000 -> -112.93482 | J26: May: flujo histórico Colombia más caja internacional real disponible.
B27: Jun-26 | C27: =(Inputs!I155+(Inputs!I109-Inputs!H109)+(Inputs!I113-Inputs!H113)+(Inputs!I112-Inputs!H112)-(Inputs!I96-Inputs!H96)-(Inputs!I94-Inputs!H94)-(Inputs!I97-Inputs!H97))/1000000 -> -112.21246 | D27: =-(Inputs!I101-Inputs!H101)/1000000 -> 0 | E27: =J48 -> -81.203976 | F27: =SUM(C27:E27) -> -193.41644 | G27: =MAX(0,-F27) -> 193.41644 | H27: =MAX(0,-(('Informe Accionista'!H129/1000000)+D27)) -> 0 | I27: =(Inputs!I93-Inputs!H93)/1000000+E27 -> -210.58496 | J27: Jun: Colombia más flujo bancario de USA, Perú y Costa Rica calculado solo con filas 1–16 del consolidado.
B28: Jul-26 | C28: =(Inputs!J155+(Inputs!J109-Inputs!I109)+(Inputs!J113-Inputs!I113)+(Inputs!J112-Inputs!I112)-(Inputs!J96-Inputs!I96)-(Inputs!J94-Inputs!I94)-(Inputs!J97-Inputs!I97))/1000000 -> 37.553515 | D28: =-(Inputs!J101-Inputs!I101)/1000000 -> 0 | E28: =C18 -> -40.383806 | F28: =SUM(C28:E28) -> -2.8302914 | G28: =MAX(0,-F28) -> 2.8302914 | H28: =MAX(0,-(('Informe Accionista'!I129/1000000)+D28)) -> 0 | I28: =(Inputs!J93-Inputs!I93)/1000000+E28 -> 18.441758 | J28: Jul: solo Colombia (estados financieros julio); flujo internacional de julio pendiente — Consolidado llega a junio.
B29: YTD Ene-Jul | C29: =SUM(C22:C28) -> -48.021874 | D29: =SUM(D22:D28) -> -20.482347 | E29: =SUM(E22:E28) -> -381.94731 | F29: =SUM(F22:F28) -> -450.45153 | G29: =SUM(G22:G28) -> 787.18031 | H29: =SUM(H22:H28) -> 22.531841 | I29: =SUM(I22:I28) -> -178.77953 | J29: Acumulado Ene-Jun. FCF neto total incluye junio.
B30: Promedio 3M May-Jul | C30: =AVERAGE(C26:C28) -> -53.673592 | D30: =AVERAGE(D26:D28) -> -2.5976603 | E30: =AVERAGE(E26:E28) -> -75.793706 | F30: =AVERAGE(F26:F28) -> -132.06496 | G30: =AVERAGE(G26:G28) -> 132.06496 | H30: =AVERAGE(H26:H28) -> 0 | I30: =AVERAGE(I26:I28) -> -101.69267 | J30: Promedio 3M (Abr-Jun) usado para runway.
B32: Ingresos presupuesto vs ejecutado (USD MM y COP MM) — Ene a Jul 2026
B33: Mes | C33: Ppto USD MM | D33: Ejec. USD MM | E33: Gap USD MM | F33: Cumplimiento % | G33: Ppto COP MM | H33: Ejec. COP MM | I33: Gap COP MM
B34: Ene-26 | C34: 0.186 | D34: ='Informe Accionista'!C122/Inputs!$C$27/1000000 -> 0.16592079 | E34: =D34-C34 -> -0.020079214 | F34: =IF(C34=0,"N/A",D34/C34) -> 0.89204724 | G34: =C34*Inputs!$C$27 -> 686.34 | H34: ='Informe Accionista'!C122/1000000 -> 612.2477 | I34: =H34-G34 -> -74.092299
B35: Feb-26 | C35: 0.354 | D35: ='Informe Accionista'!D122/Inputs!$C$27/1000000 -> 0.20168513 | E35: =D35-C35 -> -0.15231487 | F35: =IF(C35=0,"N/A",D35/C35) -> 0.56973201 | G35: =C35*Inputs!$C$27 -> 1306.26 | H35: ='Informe Accionista'!D122/1000000 -> 744.21814 | I35: =H35-G35 -> -562.04186
B36: Mar-26 | C36: 0.396 | D36: ='Informe Accionista'!E122/Inputs!$C$27/1000000 -> 0.21329029 | E36: =D36-C36 -> -0.18270971 | F36: =IF(C36=0,"N/A",D36/C36) -> 0.53861185 | G36: =C36*Inputs!$C$27 -> 1461.24 | H36: ='Informe Accionista'!E122/1000000 -> 787.04119 | I36: =H36-G36 -> -674.19881
B37: Abr-26 | C37: 0.359 | D37: ='Informe Accionista'!F122/Inputs!$C$27/1000000 -> 0.20348717 | E37: =D37-C37 -> -0.15551283 | F37: =IF(C37=0,"N/A",D37/C37) -> 0.56681663 | G37: =C37*Inputs!$C$27 -> 1324.71 | H37: ='Informe Accionista'!F122/1000000 -> 750.86766 | I37: =H37-G37 -> -573.84234
B38: May-26 | C38: 0.403 | D38: ='Informe Accionista'!G122/Inputs!$C$27/1000000 -> 0.22398774 | E38: =D38-C38 -> -0.17901226 | F38: =IF(C38=0,"N/A",D38/C38) -> 0.55580083 | G38: =C38*Inputs!$C$27 -> 1487.07 | H38: ='Informe Accionista'!G122/1000000 -> 826.51475 | I38: =H38-G38 -> -660.55525
B39: Jun-26 | C39: ='Informe Accionista'!H65/1000000 -> 0.375559 | D39: ='Informe Accionista'!H122/Inputs!$C$27/1000000 -> 0.20364588 | E39: =D39-C39 -> -0.17191312 | F39: =IF(C39=0,"N/A",D39/C39) -> 0.54224738 | G39: =C39*Inputs!$C$27 -> 1385.8127 | H39: ='Informe Accionista'!H122/1000000 -> 751.45331 | I39: =H39-G39 -> -634.3594
B40: Jul-26 | C40: ='Informe Accionista'!I65/1000000 -> 0.388085 | D40: ='Modelo Base'!L51/Inputs!$C$27/1000000 -> 0.18425218 | E40: =D40-C40 -> -0.20383282 | F40: =IF(C40=0,"N/A",D40/C40) -> 0.47477275 | G40: =C40*Inputs!$C$27 -> 1432.0337 | H40: ='Modelo Base'!L51/1000000 -> 679.89055 | I40: =H40-G40 -> -752.1431
B41: Total Ene-Jul | C41: =SUM(C34:C40) -> 2.461644 | D41: =SUM(D34:D40) -> 1.3962692 | E41: =D41-C41 -> -1.0653748 | F41: =IF(C41=0,"N/A",D41/C41) -> 0.56721004 | G41: =SUM(G34:G40) -> 9083.4664 | H41: =SUM(H34:H40) -> 5152.2333 | I41: =H41-G41 -> -3931.2331
B43: Puente de caja Jun → Jul 2026 (COP MM) | F43: Flujo de caja internacional — Jun-26 (excluye Colombia)
B44: Concepto | C44: COP MM | D44: Comentario | F44: País | G44: Ingresos USD | H44: Egresos USD | I44: Flujo neto USD | J44: Flujo neto COP MM
B45: Caja inicial (jun-26) | C45: =Inputs!I93/1000000 -> 115.44136 | F45: USA | G45: =SUM('Consolidado '!M6:M7) -> 5664.45 | H45: =-SUM('Consolidado '!M9,'Consolidado '!M11:M13,'Consolidado '!M15) -> -27968.27 | I45: =SUM(G45:H45) -> -22303.82 | J45: =I45*$J$50/1000000 -> -78.180874
B46: (+) Utilidad neta de julio | C46: =Inputs!J155/1000000 -> 24.707052 | D46: Julio fue rentable | F46: Perú | G46: =SUM('Consolidado '!N6:N7) -> 1821.5125 | H46: =-SUM('Consolidado '!N9,'Consolidado '!N11:N13,'Consolidado '!N15) -> -11.967695 | I46: =SUM(G46:H46) -> 1809.5448 | J46: =I46*$J$50/1000000 -> 6.34294
B47: (−) Aumento de Clientes (CxC) | C47: =-(Inputs!J96-Inputs!I96)/1000000 -> 110.97319 | D47: Recuperación de cartera: cobros superaron la facturación a crédito | F47: Costa Rica | G47: =SUM('Consolidado '!O6:O7) -> 0 | H47: =-SUM('Consolidado '!O9,'Consolidado '!O11:O13,'Consolidado '!O15) -> -2671.99 | I47: =SUM(G47:H47) -> -2671.99 | J47: =I47*$J$50/1000000 -> -9.3660419
...

Sheet Ppto Ene. 2026
A1: COCO TECNOLOGÍAS — P&L × 3 Escenarios 2026
C5: Inflación | H5: 0.051
C6: Tasa de Cambio | H6: 4000
B7: P&L 2026 — Monthly (Level 4) — Phase 1: Revenue lines (COP & USD)
U9: Total 2026
A10: PUC | B10: Account | E10: Currency | G10: 2026-01 | H10: 2026-02 | I10: 2026-03 | J10: 2026-04 | K10: 2026-05 | L10: 2026-06 | M10: 2026-07 | N10: 2026-08 | O10: 2026-09 | P10: 2026-10 | Q10: 2026-11 | R10: 2026-12
U11: =SUM(G12:R12) -> 1.8222904e+10
A12: 4170 | B12: Otras actividades de servicios comunitarios, sociales y personales | E12: COP | G12: 7.4492961e+08 | H12: 1.4172832e+09 | I12: 1.5849544e+09 | J12: 1.436763e+09 | K12: 1.6123205e+09 | L12: 1.5022355e+09 | M12: 1.5523381e+09 | N12: 1.5343577e+09 | O12: 1.6970537e+09 | P12: 1.6798161e+09 | Q12: 1.692867e+09 | R12: 1.7679851e+09
U13: =SUM(G14:R14) -> 4555726
A14: 4170 | B14: Otras actividades de servicios comunitarios, sociales y personales | E14: USD | G14: 186232.4 | H14: 354320.8 | I14: 396238.6 | J14: 359190.75 | K14: 403080.12 | L14: 375558.87 | M14: 388084.53 | N14: 383589.42 | O14: 424263.43 | P14: 419954.03 | Q14: 423216.76 | R14: 441996.28
F16: Ponderador Mensual
D17: Cifra 2025 | E17: Cifra 2026 | F17: =1/12 -> 0.083333333
F19: =G10 -> 2026-01 | G19: =H10 -> 2026-02 | H19: =I10 -> 2026-03 | I19: =J10 -> 2026-04 | J19: =K10 -> 2026-05 | K19: =L10 -> 2026-06 | L19: =M10 -> 2026-07 | M19: =N10 -> 2026-08 | ... Q19: =R10 -> 2026-12 | S19: =U9 -> Total 2026
A20: Moneda COP
A22: Ingresos Operacionales | F22: =G12 -> 7.4492961e+08 | G22: =H12 -> 1.4172832e+09 | H22: =I12 -> 1.5849544e+09 | I22: =J12 -> 1.436763e+09 | J22: =K12 -> 1.6123205e+09 | K22: =L12 -> 1.5022355e+09 | L22: =M12 -> 1.5523381e+09 | M22: =N12 -> 1.5343577e+09 | ... Q22: =R12 -> 1.7679851e+09 | S22: =SUM(F22:Q22) -> 1.8222904e+10
D24: %
A25: Costo de Ventas | B25: 5.0860033e+09 | C25: =B25*(1+$H$5) -> 5.3453895e+09 | F25: =$C25*$F$17 -> 4.4544912e+08 | G25: =$C25*$F$17 -> 4.4544912e+08 | H25: =$C25*$F$17 -> 4.4544912e+08 | I25: =$C25*$F$17 -> 4.4544912e+08 | J25: =$C25*$F$17 -> 4.4544912e+08 | K25: =$C25*$F$17 -> 4.4544912e+08 | L25: =$C25*$F$17 -> 4.4544912e+08 | M25: =$C25*$F$17 -> 4.4544912e+08 | ... Q25: =$C25*$F$17 -> 4.4544912e+08 | S25: =SUM(F25:Q25) -> 5.3453895e+09
A26: Mano de Obra Directa | B26: 3.096729e+09 | C26: =B26*(1+$H$5) -> 3.2546622e+09 | F26: =$C26*$F$17 -> 2.7122185e+08 | G26: =$C26*$F$17 -> 2.7122185e+08 | H26: =$C26*$F$17 -> 2.7122185e+08 | I26: =$C26*$F$17 -> 2.7122185e+08 | J26: =$C26*$F$17 -> 2.7122185e+08 | K26: =$C26*$F$17 -> 2.7122185e+08 | L26: =$C26*$F$17 -> 2.7122185e+08 | M26: =$C26*$F$17 -> 2.7122185e+08 | ... Q26: =$C26*$F$17 -> 2.7122185e+08 | S26: =SUM(F26:Q26) -> 3.2546622e+09
A27: Operacionales de Desarrollo | B27: 1.9892743e+09 | C27: =B27*(1+$H$5) -> 2.0907273e+09 | F27: =$C27*$F$17 -> 1.7422727e+08 | G27: =$C27*$F$17 -> 1.7422727e+08 | H27: =$C27*$F$17 -> 1.7422727e+08 | I27: =$C27*$F$17 -> 1.7422727e+08 | J27: =$C27*$F$17 -> 1.7422727e+08 | K27: =$C27*$F$17 -> 1.7422727e+08 | L27: =$C27*$F$17 -> 1.7422727e+08 | M27: =$C27*$F$17 -> 1.7422727e+08 | ... Q27: =$C27*$F$17 -> 1.7422727e+08 | S27: =SUM(F27:Q27) -> 2.0907273e+09
A29: Utilidad Bruta | F29: =F22-F26-F27 -> 2.9948049e+08 | G29: =G22-G26-G27 -> 9.7183409e+08 | H29: =H22-H26-H27 -> 1.1395053e+09 | I29: =I22-I26-I27 -> 9.9131388e+08 | J29: =J22-J26-J27 -> 1.1668714e+09 | K29: =K22-K26-K27 -> 1.0567864e+09 | L29: =L22-L26-L27 -> 1.106889e+09 | M29: =M22-M26-M27 -> 1.0889086e+09 | ... Q29: =Q22-Q26-Q27 -> 1.322536e+09 | S29: =SUM(F29:Q29) -> 1.2877515e+10
A32: Operacionales de Administración | B32: 1.5320319e+09 | C32: =B32*(1+$H$5) -> 1.6101656e+09 | F32: =$C32*$F$17 -> 1.3418046e+08 | G32: =$C32*$F$17 -> 1.3418046e+08 | H32: =$C32*$F$17 -> 1.3418046e+08 | I32: =$C32*$F$17 -> 1.3418046e+08 | J32: =$C32*$F$17 -> 1.3418046e+08 | K32: =$C32*$F$17 -> 1.3418046e+08 | L32: =$C32*$F$17 -> 1.3418046e+08 | M32: =$C32*$F$17 -> 1.3418046e+08 | ... Q32: =$C32*$F$17 -> 1.3418046e+08 | S32: =SUM(F32:Q32) -> 1.6101656e+09
A33: Gastos de Personal | B33: 705937048 | C33: =B33*(1+$H$5) -> 7.4193984e+08 | D33: 0.46 | F33: =$C33*$F$17 -> 61828320 | G33: =$C33*$F$17 -> 61828320 | H33: =$C33*$F$17 -> 61828320 | I33: =$C33*$F$17 -> 61828320 | J33: =$C33*$F$17 -> 61828320 | K33: =$C33*$F$17 -> 61828320 | L33: =$C33*$F$17 -> 61828320 | M33: =$C33*$F$17 -> 61828320 | ... Q33: =$C33*$F$17 -> 61828320 | S33: =SUM(F33:Q33) -> 7.4193984e+08
A34: Otros Gastos de Administración Operacionales | B34: 8.2609489e+08 | C34: =B34*(1+$H$5) -> 8.6822573e+08 | F34: =$C34*$F$17 -> 72352144 | G34: =$C34*$F$17 -> 72352144 | H34: =$C34*$F$17 -> 72352144 | I34: =$C34*$F$17 -> 72352144 | J34: =$C34*$F$17 -> 72352144 | K34: =$C34*$F$17 -> 72352144 | L34: =$C34*$F$17 -> 72352144 | M34: =$C34*$F$17 -> 72352144 | ... Q34: =$C34*$F$17 -> 72352144 | S34: =SUM(F34:Q34) -> 8.6822573e+08
S35: =SUM(F35:Q35) -> 0
S36: =SUM(F36:Q36) -> 0
A37: Operacionales de Ventas | B37: 2.4666933e+09 | C37: =B37*(1+$H$5) -> 2.5924947e+09 | F37: =$C37*$F$17 -> 2.1604123e+08 | G37: =$C37*$F$17 -> 2.1604123e+08 | H37: =$C37*$F$17 -> 2.1604123e+08 | I37: =$C37*$F$17 -> 2.1604123e+08 | J37: =$C37*$F$17 -> 2.1604123e+08 | K37: =$C37*$F$17 -> 2.1604123e+08 | L37: =$C37*$F$17 -> 2.1604123e+08 | M37: =$C37*$F$17 -> 2.1604123e+08 | ... Q37: =$C37*$F$17 -> 2.1604123e+08 | S37: =SUM(F37:Q37) -> 2.5924947e+09
A38: Gastos de Personal | B38: 1099685429 | C38: =B38*(1+$H$5) -> 1.1557694e+09 | F38: =$C38*$F$17 -> 96314115 | G38: =$C38*$F$17 -> 96314115 | H38: =$C38*$F$17 -> 96314115 | I38: =$C38*$F$17 -> 96314115 | J38: =$C38*$F$17 -> 96314115 | K38: =$C38*$F$17 -> 96314115 | L38: =$C38*$F$17 -> 96314115 | M38: =$C38*$F$17 -> 96314115 | ... Q38: =$C38*$F$17 -> 96314115 | S38: =SUM(F38:Q38) -> 1.1557694e+09
A39: Honorarios | B39: 4.6489068e+08 | C39: =B39*(1+$H$5) -> 4.8860011e+08 | F39: =$C39*$F$17 -> 40716675 | G39: =$C39*$F$17 -> 40716675 | H39: =$C39*$F$17 -> 40716675 | I39: =$C39*$F$17 -> 40716675 | J39: =$C39*$F$17 -> 40716675 | K39: =$C39*$F$17 -> 40716675 | L39: =$C39*$F$17 -> 40716675 | M39: =$C39*$F$17 -> 40716675 | ... Q39: =$C39*$F$17 -> 40716675 | S39: =SUM(F39:Q39) -> 4.8860011e+08
A40: Otros Gastos de Ventas Operacionales | B40: 9.0211724e+08 | C40: =B40*(1+$H$5) -> 9.4812522e+08 | F40: =$C40*$F$17 -> 79010435 | G40: =$C40*$F$17 -> 79010435 | H40: =$C40*$F$17 -> 79010435 | I40: =$C40*$F$17 -> 79010435 | J40: =$C40*$F$17 -> 79010435 | K40: =$C40*$F$17 -> 79010435 | L40: =$C40*$F$17 -> 79010435 | M40: =$C40*$F$17 -> 79010435 | ... Q40: =$C40*$F$17 -> 79010435 | S40: =SUM(F40:Q40) -> 9.4812522e+08
S41: =SUM(F41:Q41) -> 0
A42: Utilidad Operacional | F42: =F29-F32-F37 -> -50741202 | G42: =G29-G32-G37 -> 6.2161241e+08 | H42: =H29-H32-H37 -> 7.8928359e+08 | I42: =I29-I32-I37 -> 6.4109219e+08 | J42: =J29-J32-J37 -> 8.1664966e+08 | K42: =K29-K32-K37 -> 7.0656469e+08 | L42: =L29-L32-L37 -> 7.566673e+08 | M42: =M29-M32-M37 -> 7.3868689e+08 | ... Q42: =Q29-Q32-Q37 -> 9.7231431e+08 | S42: =SUM(F42:Q42) -> 8.6748543e+09
S43: =SUM(F43:Q43) -> 0
A44: Ingresos no Operacionales | B44: 36272911 | C44: =B44*(1+$H$5) -> 38122829 | F44: =$C44*$F$17 -> 3176902.4 | G44: =$C44*$F$17 -> 3176902.4 | H44: =$C44*$F$17 -> 3176902.4 | I44: =$C44*$F$17 -> 3176902.4 | J44: =$C44*$F$17 -> 3176902.4 | K44: =$C44*$F$17 -> 3176902.4 | L44: =$C44*$F$17 -> 3176902.4 | M44: =$C44*$F$17 -> 3176902.4 | ... Q44: =$C44*$F$17 -> 3176902.4 | S44: =SUM(F44:Q44) -> 38122829
A45: Gastos no Operacionales | B45: 92043202 | C45: =B45*(1+$H$5) -> 96737405 | F45: =$C45*$F$17 -> 8061450.4 | G45: =$C45*$F$17 -> 8061450.4 | H45: =$C45*$F$17 -> 8061450.4 | I45: =$C45*$F$17 -> 8061450.4 | J45: =$C45*$F$17 -> 8061450.4 | K45: =$C45*$F$17 -> 8061450.4 | L45: =$C45*$F$17 -> 8061450.4 | M45: =$C45*$F$17 -> 8061450.4 | ... Q45: =$C45*$F$17 -> 8061450.4 | S45: =SUM(F45:Q45) -> 96737405
A47: Utilidad Antes de Impuestos | F47: =F42+F44-F45 -> -55625750 | G47: =G42+G44-G45 -> 6.1672786e+08 | H47: =H42+H44-H45 -> 7.8439904e+08 | I47: =I42+I44-I45 -> 6.3620764e+08 | J47: =J42+J44-J45 -> 8.1176512e+08 | K47: =K42+K44-K45 -> 7.0168014e+08 | L47: =L42+L44-L45 -> 7.5178275e+08 | M47: =M42+M44-M45 -> 7.3380234e+08 | ... Q47: =Q42+Q44-Q45 -> 9.6742977e+08 | S47: =SUM(F47:Q47) -> 8.6162397e+09
A49: Impuestos | F49: =IF(F47>0,F47*35%,0) -> 0 | G49: =IF(G47>0,G47*35%,0) -> 2.1585475e+08 | H49: =IF(H47>0,H47*35%,0) -> 2.7453966e+08 | I49: =IF(I47>0,I47*35%,0) -> 2.2267268e+08 | J49: =IF(J47>0,J47*35%,0) -> 2.8411779e+08 | K49: =IF(K47>0,K47*35%,0) -> 2.4558805e+08 | L49: =IF(L47>0,L47*35%,0) -> 2.6312396e+08 | M49: =IF(M47>0,M47*35%,0) -> 2.5683082e+08 | ... Q49: =IF(Q47>0,Q47*35%,0) -> 3.3860042e+08 | S49: =SUM(F49:Q49) -> 3.0351529e+09
S50: =SUM(F50:Q50) -> 0
A51: Utilidad Neta | F51: =F47-F49 -> -55625750 | G51: =G47-G49 -> 4.0087311e+08 | H51: =H47-H49 -> 5.0985938e+08 | I51: =I47-I49 -> 4.1353497e+08 | J51: =J47-J49 -> 5.2764733e+08 | K51: =K47-K49 -> 4.5609209e+08 | L51: =L47-L49 -> 4.8865879e+08 | M51: =M47-M49 -> 4.7697152e+08 | ... Q51: =Q47-Q49 -> 6.2882935e+08 | S51: =SUM(F51:Q51) -> 5.5810868e+09
S52: =SUM(F52:Q52) -> 0
AB56: Objetivo de Ingresos | AC56: 1
...

Sheet Revenue
B3: Plan Comercial 2026 (USD) + Puente de MRR
B4: Legacy drivers (not used after target alignment)
B5: Stream | C5: Annual Target (USD) | D5: 2026-01 | E5: 2026-02 | F5: 2026-03 | G5: 2026-04 | H5: 2026-05 | I5: 2026-06 | J5: 2026-07 | K5: 2026-08 | L5: 2026-09 | M5: 2026-10 | N5: 2026-11 | O5: 2026-12 | P5: Total 2026
B6: MRR | C6: =Inputs!$H$5*(Inputs!C58/SUM(Inputs!$C$58:$C$61)) -> 1257936.3 | D6: =$C6*Inputs!D$31 -> 79848.386 | E6: =$C6*Inputs!E$31 -> 86653.102 | F6: =$C6*Inputs!F$31 -> 106779.87 | G6: =$C6*Inputs!G$31 -> 88804.185 | H6: =$C6*Inputs!H$31 -> 110006.49 | I6: =$C6*Inputs!I$31 -> 96642.16 | J6: =$C6*Inputs!J$31 -> 102662.68 | K6: =$C6*Inputs!K$31 -> 100444.21 | L6: =$C6*Inputs!N$31 -> 120090.02 | M6: =$C6*Inputs!O$31 -> 117961.4 | N6: =$C6*Inputs!P$31 -> 119498.08 | O6: =$C6*Inputs!Q$31 -> 128545.71 | P6: =SUM(D6:O6) -> 1257936.3
B7: Upsell / Cross-sell (expansion) | C7: =Inputs!$H$5*(Inputs!C59/SUM(Inputs!$C$58:$C$61)) -> 262373.56 | D7: =$C7*Inputs!D$31 -> 16654.345 | E7: =$C7*Inputs!E$31 -> 18073.636 | F7: =$C7*Inputs!F$31 -> 22271.568 | G7: =$C7*Inputs!G$31 -> 18522.297 | H7: =$C7*Inputs!H$31 -> 22944.56 | I7: =$C7*Inputs!I$31 -> 20157.1 | J7: =$C7*Inputs!J$31 -> 21412.828 | K7: =$C7*Inputs!K$31 -> 20950.111 | L7: =$C7*Inputs!N$31 -> 25047.728 | M7: =$C7*Inputs!O$31 -> 24603.752 | N7: =$C7*Inputs!P$31 -> 24924.264 | O7: =$C7*Inputs!Q$31 -> 26811.369 | P7: =SUM(D7:O7) -> 262373.56
B8: New Business LATAM | C8: =Inputs!$H$5*(Inputs!C60/SUM(Inputs!$C$58:$C$61)) -> 787120.74 | D8: =$C8*Inputs!D$31 -> 49963.04 | E8: =$C8*Inputs!E$31 -> 54220.913 | F8: =$C8*Inputs!F$31 -> 66814.709 | G8: =$C8*Inputs!G$31 -> 55566.897 | H8: =$C8*Inputs!H$31 -> 68833.685 | I8: =$C8*Inputs!I$31 -> 60471.305 | J8: =$C8*Inputs!J$31 -> 64238.489 | K8: =$C8*Inputs!K$31 -> 62850.34 | L8: =$C8*Inputs!N$31 -> 75143.191 | M8: =$C8*Inputs!O$31 -> 73811.263 | N8: =$C8*Inputs!P$31 -> 74772.798 | O8: =$C8*Inputs!Q$31 -> 80434.115 | P8: =SUM(D8:O8) -> 787120.74
B9: New Business Gobierno y Enterprise | C9: =Inputs!$H$5*(Inputs!C61/SUM(Inputs!$C$58:$C$61)) -> 728569.41 | D9: =$C9*Inputs!D$31 -> 46246.453 | E9: =$C9*Inputs!E$31 -> 50187.596 | F9: =$C9*Inputs!F$31 -> 61844.581 | G9: =$C9*Inputs!G$31 -> 51433.457 | H9: =$C9*Inputs!H$31 -> 63713.372 | I9: =$C9*Inputs!I$31 -> 55973.042 | J9: =$C9*Inputs!J$31 -> 59459.998 | K9: =$C9*Inputs!K$31 -> 58175.109 | L9: =$C9*Inputs!N$31 -> 69553.535 | M9: =$C9*Inputs!O$31 -> 68320.684 | N9: =$C9*Inputs!P$31 -> 69210.694 | O9: =$C9*Inputs!Q$31 -> 74450.885 | P9: =SUM(D9:O9) -> 728569.41
B10: One-off (Implementation) | C10: =Inputs!$C$13*Inputs!$C$19 -> 171600 | D10: =$C10*Inputs!D$31 -> 10892.43 | E10: =$C10*Inputs!E$31 -> 11820.688 | F10: =$C10*Inputs!F$31 -> 14566.258 | G10: =$C10*Inputs!G$31 -> 12114.125 | H10: =$C10*Inputs!H$31 -> 15006.415 | I10: =$C10*Inputs!I$31 -> 13183.334 | J10: =$C10*Inputs!J$31 -> 14004.617 | K10: =$C10*Inputs!K$31 -> 13701.987 | L10: =$C10*Inputs!N$31 -> 16381.949 | M10: =$C10*Inputs!O$31 -> 16091.575 | N10: =$C10*Inputs!P$31 -> 16301.199 | O10: =$C10*Inputs!Q$31 -> 17535.422 | P10: =SUM(D10:O10) -> 171600
B11: One-off (Interoperability) | C11: =Inputs!$C$13*Inputs!$C$20 -> 92400 | D11: =$C11*Inputs!D$31 -> 5865.1546 | E11: =$C11*Inputs!E$31 -> 6364.9858 | F11: =$C11*Inputs!F$31 -> 7843.3699 | G11: =$C11*Inputs!G$31 -> 6522.9906 | H11: =$C11*Inputs!H$31 -> 8080.3772 | I11: =$C11*Inputs!I$31 -> 7098.7185 | J11: =$C11*Inputs!J$31 -> 7540.9477 | K11: =$C11*Inputs!K$31 -> 7377.9931 | L11: =$C11*Inputs!N$31 -> 8821.0493 | M11: =$C11*Inputs!O$31 -> 8664.6943 | N11: =$C11*Inputs!P$31 -> 8777.5688 | O11: =$C11*Inputs!Q$31 -> 9442.1502 | P11: =SUM(D11:O11) -> 92400
B12: TOTAL | C12: =SUM(C6:C11) -> 3300000 | D12: =SUM(D6:D11) -> 209469.81 | E12: =SUM(E6:E11) -> 227320.92 | F12: =SUM(F6:F11) -> 280120.35 | G12: =SUM(G6:G11) -> 232963.95 | H12: =SUM(H6:H11) -> 288584.9 | I12: =SUM(I6:I11) -> 253525.66 | J12: =SUM(J6:J11) -> 269319.56 | ... P12: =SUM(P6:P11) -> 3300000
B15: MRR BRIDGE 2026 (USD)
B17: Metric | C17: 2026-01 | D17: 2026-02 | E17: 2026-03 | F17: 2026-04 | G17: 2026-05 | H17: 2026-06 | I17: 2026-07 | J17: 2026-08 | K17: 2026-09 | L17: 2026-10 | M17: 2026-11 | N17: 2026-12 | O17: Total/End
B18: Starting MRR (USD) | C18: =Inputs!$H$6 -> 190988.06 | D18: =C21 -> 382745.34 | E18: =D21 -> 589966.86 | F18: =E21 -> 844727.75 | G18: =F21 -> 1054831 | H18: =G21 -> 1315054.9 | I18: =H21 -> 1541723.2 | J18: =I21 -> 1781788.6 | K18: =J21 -> 2015299.4 | ... O18: =N21 -> 3139866.5
B19: New MRR (from SalesPlan) (USD) | C19: =D6+D7+D8+D9 -> 192712.22 | D19: =E6+E7+E8+E9 -> 209135.25 | E19: =F6+F7+F8+F9 -> 257710.72 | F19: =G6+G7+G8+G9 -> 214326.84 | G19: =H6+H7+H8+H9 -> 265498.11 | H19: =I6+I7+I8+I9 -> 233243.61 | I19: =J6+J7+J8+J9 -> 247774 | J19: =K6+K7+K8+K9 -> 242419.77 | ... N19: =O6+O7+O8+O9 -> 310242.08 | O19: =SUM(C19:N19) -> 3036000
B20: Churned MRR (USD) | C20: =-C18*Inputs!$C$9 -> -954.94031 | D20: =-D18*Inputs!$C$9 -> -1913.7267 | E20: =-E18*Inputs!$C$9 -> -2949.8343 | F20: =-F18*Inputs!$C$9 -> -4223.6388 | G20: =-G18*Inputs!$C$9 -> -5274.1548 | H20: =-H18*Inputs!$C$9 -> -6575.2745 | I20: =-I18*Inputs!$C$9 -> -7708.6162 | J20: =-J18*Inputs!$C$9 -> -8908.9431 | ... O20: =-O18*Inputs!$C$9 -> -15699.333
B21: Ending MRR (USD) | C21: =C18+C19+C20 -> 382745.34 | D21: =D18+D19+D20 -> 589966.86 | E21: =E18+E19+E20 -> 844727.75 | F21: =F18+F19+F20 -> 1054831 | G21: =G18+G19+G20 -> 1315054.9 | H21: =H18+H19+H20 -> 1541723.2 | I21: =I18+I19+I20 -> 1781788.6 | J21: =J18+J19+J20 -> 2015299.4 | ... N21: =N18+N19+N20 -> 3139866.5 | O21: =N21 -> 3139866.5
B23: MRR Promedio mes (USD) | C23: =AVERAGE(C18,C21) -> 286866.7 | D23: =AVERAGE(D18,D21) -> 486356.1 | E23: =AVERAGE(E18,E21) -> 717347.31 | F23: =AVERAGE(F18,F21) -> 949779.35 | G23: =AVERAGE(G18,G21) -> 1184942.9 | H23: =AVERAGE(H18,H21) -> 1428389.1 | I23: =AVERAGE(I18,I21) -> 1661755.9 | J23: =AVERAGE(J18,J21) -> 1898544 | ... O23: =AVERAGE(O18,O21) -> 3139866.5
B25: CHECKS & KPIs (sanity check rápido)
B27: Check | C27: Valor | D27: Status
B28: Target total (recurrente + one-off) (USD) | C28: =Inputs!$C$12 -> 3300000
B29: Total plan comercial (USD) | C29: =P12 -> 3300000
B30: Brecha (USD) | C30: =C29-C28 -> 0 | D30: =IF(ABS(C30)<1000,"OK","GAP") -> OK
B32: MRR final dic-2026 (USD) | C32: =N21 -> 3139866.5
B33: Target run-rate mensual (USD) | C33: =Inputs!$C$15 -> 3036000
B34: Brecha vs target (USD) | C34: =C32-C33 -> 103866.53 | D34: =IF(C34>0,"ABOVE","BELOW") -> ABOVE
B36: Devoluciones implícitas (% bruto, ref) | C36: =Inputs!C21 -> 0.112 | D36: Referencia — modelo usa revenue neto
B38: Ingresos brutos implicitos (USD) | C38: =P12/(1-Inputs!C21) -> 3716216.2
B39: Devoluciones implicitas (USD) | C39: =C38-P12 -> 416216.22
B40: Devoluciones implicitas (COP) | C40: =C39*Inputs!C6 -> 1.5358378e+09
B43: PROYECCIÓN DE INGRESOS 2026 — 3 ESCENARIOS (COP)
B44: Cifras en pesos colombianos (COP). TRM utilizada: INPUTS!B5. Distribución mensual: pesos de estacionalidad INPUTS!C30:N30.
B46: ESCENARIO CONSERVADOR (COP) | C46: Total Anual | D46: Ene | E46: Feb | F46: Mar | G46: Abr | H46: May | I46: Jun | J46: Jul | K46: Ago | L46: Sep | M46: Oct | N46: Nov | O46: Dic | P46: % del total
B47: Ingresos (COP) | C47: =Inputs!$N$7*Inputs!$C$6 -> 8856000000 | D47: =C47*Inputs!D$31 -> 5.6214079e+08 | E47: =C47*Inputs!E$31 -> 6.1004669e+08 | F47: =C47*Inputs!F$31 -> 7.5174116e+08 | G47: =C47*Inputs!G$31 -> 6.2519053e+08 | H47: =C47*Inputs!H$31 -> 7.7445693e+08 | I47: =C47*Inputs!I$31 -> 6.8037068e+08 | J47: =C47*Inputs!J$31 -> 7.2275577e+08 | K47: =C47*Inputs!K$31 -> 7.0713752e+08 | L47: =C47*Inputs!N$31 -> 8.4544602e+08 | M47: =C47*Inputs!O$31 -> 8.3046032e+08 | N47: =C47*Inputs!P$31 -> 8.4127868e+08 | O47: =C47*Inputs!Q$31 -> 9.0497491e+08 | P47: =SUM(D47:O47)/C47 -> 1
B48: Check suma meses | C48: =SUM(D47:O47) -> 8856000000 | D48: =IF(ABS(C47-C48)<1,"OK","ERROR") -> OK
B51: ESCENARIO BASE (COP) | C51: Total Anual | D51: Ene | E51: Feb | F51: Mar | G51: Abr | H51: May | I51: Jun | J51: Jul | K51: Ago | L51: Sep | M51: Oct | N51: Nov | O51: Dic | P51: % del total
B52: Ingresos (COP) | C52: =Inputs!$N$8*Inputs!$C$6 -> 12177000000 | D52: =C52*Inputs!D$31 -> 7.7294359e+08 | E52: =C52*Inputs!E$31 -> 8.388142e+08 | F52: =C52*Inputs!F$31 -> 1.0336441e+09 | G52: =C52*Inputs!G$31 -> 8.5963698e+08 | H52: =C52*Inputs!H$31 -> 1.0648783e+09 | I52: =C52*Inputs!I$31 -> 9.3550969e+08 | J52: =C52*Inputs!J$31 -> 9.9378918e+08 | K52: =C52*Inputs!K$31 -> 9.7231409e+08 | L52: =C52*Inputs!N$31 -> 1.1624883e+09 | M52: =C52*Inputs!O$31 -> 1.1418829e+09 | N52: =C52*Inputs!P$31 -> 1.1567582e+09 | O52: =C52*Inputs!Q$31 -> 1.2443405e+09 | P52: =SUM(D52:O52)/C52 -> 1
B53: Check suma meses | C53: =SUM(D52:O52) -> 12177000000 | D53: =IF(ABS(C52-C53)<1,"OK","ERROR") -> OK
B56: ESCENARIO OPTIMISTA (COP) | C56: Total Anual | D56: Ene | E56: Feb | F56: Mar | G56: Abr | H56: May | I56: Jun | J56: Jul | K56: Ago | L56: Sep | M56: Oct | N56: Nov | O56: Dic | P56: % del total
B57: Ingresos (COP) | C57: =Inputs!$N$9*Inputs!$C$6 -> 16605000000 | D57: =C57*Inputs!D$31 -> 1.054014e+09 | E57: =C57*Inputs!E$31 -> 1.1438375e+09 | F57: =C57*Inputs!F$31 -> 1.4095147e+09 | G57: =C57*Inputs!G$31 -> 1.1722322e+09 | H57: =C57*Inputs!H$31 -> 1.4521067e+09 | I57: =C57*Inputs!I$31 -> 1.275695e+09 | J57: =C57*Inputs!J$31 -> 1.3551671e+09 | K57: =C57*Inputs!K$31 -> 1.3258828e+09 | L57: =C57*Inputs!N$31 -> 1.5852113e+09 | M57: =C57*Inputs!O$31 -> 1.5571131e+09 | N57: =C57*Inputs!P$31 -> 1.5773975e+09 | O57: =C57*Inputs!Q$31 -> 1.696828e+09 | P57: =SUM(D57:O57)/C57 -> 1
B58: Check suma meses | C58: =SUM(D57:O57) -> 1.6605e+10 | D58: =IF(ABS(C57-C58)<1,"OK","ERROR") -> OK
...

Sheet Inputs
B2: INPUTS — CocoTech 2026 Budget Model (All Assumptions Consolidated) | Q2: temp
E4: Calculado | K4: Escenarios target 2026 (USD)
E5: ARR target (USD) = Total - One-off | H5: =C15 -> 3036000 | K5: Escenario | N5: Total target (USD) | O5: One-off (USD) | P5: Recurrente implícito (USD) | Q5: Run-rate mensual (USD)
B6: FX rate (COP per USD) | C6: 3690 | D6: TrmLargoPlazo | E6: Calculado / Referencia | H6: =(C7*(1+C11))/C6 -> 190988.06
B7: MRR Dec-2025 (COP) | C7: 670548000 | D7: MrrDic25 | E7: Referencia: Ene-2026 neto real (COP) | H7: 612247701 | K7: Conservador | N7: 2400000 | O7: =N7*$C$14 -> 192000 | P7: =N7-O7 -> 2208000 | Q7: =P7/12 -> 184000
B8: Customers Dec-2025 (count) | C8: 90 | D8: ClientesDic25 | K8: Base | N8: 3300000 | O8: =N8*$C$14 -> 264000 | P8: =N8-O8 -> 3036000 | Q8: =P8/12 -> 253000
B9: Monthly churn rate (revenue) | C9: 0.005 | D9: ChurnMensual | K9: Optimista | N9: 4500000 | O9: =N9*$C$14 -> 360000 | P9: =N9-O9 -> 4140000 | Q9: =P9/12 -> 345000
B10: Monthly churn rate (revenue) | C10: 0.005 | D10: ChurnMensual
B11: Annual price increase applied in Jan | C11: 0.051 | D11: InflacionAnual | K11: Escenario activo | N11: Base
B12: 2026 Total target (ARR + One-off) (USD) | C12: =INDEX($N$7:$N$9,MATCH($N$11,$K$7:$K$9,0)) -> 3300000 | D12: TargetTotal26
B13: Otros ingresos / One-off anual (USD) | C13: =C12*C14 -> 264000 | D13: OtrosIngresos | K13: Ingreso Meta 2026 por Hoja | N13: Total (USD) | O13: One-off (USD) | P13: Recurrente (USD) | Q13: Run-rate mensual
B14: Procentaje de Otros Ingresos | C14: 0.08 | D14: PctOtrosIng | K14: Conservador | N14: =N7 -> 2400000 | O14: =O7 -> 192000 | P14: =P7 -> 2208000 | Q14: =Q7 -> 184000
B15: Target recurrente anual (USD) | C15: =C12-C13 -> 3036000 | D15: TargetRecurrente | K15: Base | N15: =N8 -> 3300000 | O15: =O8 -> 264000 | P15: =P8 -> 3036000 | Q15: =Q8 -> 253000
B16: Check: Total = Recurrente + One-off | C16: =IF(ABS(C12-C15-C13)<1,"OK","ERROR") -> OK | D16: CheckTotal | K16: Optimista | N16: =N9 -> 4500000 | O16: =O9 -> 360000 | P16: =P9 -> 4140000 | Q16: =Q9 -> 345000
B17: Check: Target anual = Ingresos proyectados | C17: =IF(ABS(C12-SUM(D36:Q36))<100,"OK","ERROR") -> ERROR | D17: CheckIngresos
B18: NRR target | C18: 1.09 | D18: NrrTarget
B19: One-off split: % Implementation | C19: 0.65 | D19: PctImplement
B20: One-off split: % Interoperability | C20: =1-C19 -> 0.35 | D20: PctInterop
B21: Devoluciones (% de ingresos brutos) | C21: 0.112 | D21: PctDevoluciones
B22: FX & Tax Assumptions
B23: FX Low scenario (COP/USD) | C23: 3600 | D23: TrmBajo
B24: FX High scenario (COP/USD) | C24: 4400 | D24: TrmAlto
B25: Tax rate (statutory) | C25: 0.35 | D25: TasaImpuesto
B26: Caja Subsidiaria (USD) | C26: 325080 | D26: CajaSubsidiaria
B27: TRM Subsidiaria (COP/USD) | C27: 3690 | D27: TrmSubsidiaria
B28: Tasa de interés deuda LP (anual) | C28: 0.1 | D28: TasaDeudaLp
B29: Tasa de interés deuda CP (anual) | C29: 0.12 | D29: TasaDeudaCp | E29: Feb | F29: Mar | G29: Abr | H29: May | I29: Jun | J29: Jul | K29: Ago | N29: Sep | O29: Oct | P29: Nov | Q29: Dic | R29: TOTAL
B30: 2025 Monthly Revenue (COP) | C30: COP | D30: 483452000 | E30: 524652000 | F30: 646512000 | G30: 537676000 | H30: 666048000 | I30: 585132000 | J30: 621584000 | K30: 608152000 | N30: 727100000 | O30: 714212000 | P30: 723516000 | Q30: 778296000 | R30: 7616332000
B31: Weights (sum to 1.0) | D31: =D30/SUM($D$30:$Q$30) -> 0.063475699 | E31: =E30/SUM($D$30:$Q$30) -> 0.068885127 | F31: =F30/SUM($D$30:$Q$30) -> 0.084884955 | G31: =G30/SUM($D$30:$Q$30) -> 0.070595137 | H31: =H30/SUM($D$30:$Q$30) -> 0.087449969 | I31: =I30/SUM($D$30:$Q$30) -> 0.076825958 | J31: =J30/SUM($D$30:$Q$30) -> 0.081611989 | K31: =K30/SUM($D$30:$Q$30) -> 0.07984841 | N31: =N30/SUM($D$30:$Q$30) -> 0.095465901 | O31: =O30/SUM($D$30:$Q$30) -> 0.093773748 | P31: =P30/SUM($D$30:$Q$30) -> 0.094995334 | Q31: =Q30/SUM($D$30:$Q$30) -> 0.10218777 | R31: =SUM(D31:Q31) -> 1
B32: Index | C32: x | D32: 0.76170839 | E32: 0.82662153 | F32: 1.0186195 | G32: 0.84718762 | H32: 1.0493891 | I32: 0.92190076 | J32: 0.97934386 | K32: 0.95818092 | N32: 1.1459108 | O32: 1.1251173 | P32: 1.1397767 | Q32: 1.226505 | R32: 12
B33: Check: sum weights = 1 | C33: =SUM(D31:Q31) -> 1 | R33: 1
C34: 0 | R34: 0
B35: MRR PLAN (USD) — Base | D35: Ene | E35: Feb | F35: Mar | G35: Abr | H35: May | I35: Jun | J35: Jul | K35: Ago | N35: Sep | O35: Oct | P35: Nov | Q35: Dic | R35: TOTAL
B36: USD | C36: USD | D36: 176186.49 | E36: 175305.55 | F36: 175643.79 | G36: 230718.12 | H36: 264031.05 | I36: 275673.04 | J36: 274294.68 | K36: 285467.08 | N36: 284039.74 | O36: 282619.54 | P36: 281206.45 | Q36: 279800.41 | R36: 2984986
B37: Check: Total Plan USD | C37: Calc | D37: 2984986 | R37: 2984986
B38: COSTOS BASE 2025 (COP) — Ajustados por inflación en P&L
B39: Cuenta | C39: Base 2025 (COP) | D39: 2026 = Base×(1+Infl.) (COP)
B40: Costo de Ventas | C40: =C135 -> 3795959000 | D40: =C40*(1+$C$11) -> 3.9895529e+09 | E40: CostoVentasBase
C41: 3795959000 | D41: 3989552909
B42: Otros costos directos / desarrollo | C42: 0 | D42: 0
...

Sheet Modelo Base
B2: Coco Tecnologías — Modelo Financiero 3 Estados | E2: Dic-25 | F2: Ene-26 | G2: Feb-26 | H2: Mar-26 | I2: Abr-26 | J2: May-26 | K2: Jun-26 | L2: Jul-26 | M2: Ago-26 | N2: Sep-26 | O2: Oct-26 | P2: Nov-26 | Q2: Dic-26
B4: SUPUESTOS Y DRIVERS (COP)
B5: Cifras en pesos colombianos. Fuente: INPUTS + EEFF reales Feb/Mar-26
B6: Tasa de Cambio (COP/USD) | C6: TRM | E6: =TrmLargoPlazo -> 3690 | F6: 3690 | G6: 3690 | H6: 3690 | I6: 3690 | J6: 3690 | K6: 3690 | L6: 3690 | M6: 3690 | N6: 3690 | O6: 3690 | P6: 3690 | Q6: 3690
B7: Tasa de Impuestos | C7: % Estatutario | E7: =TasaImpuesto -> 0.35 | F7: =TasaImpuesto -> 0.35 | G7: =TasaImpuesto -> 0.35 | H7: =TasaImpuesto -> 0.35 | I7: =TasaImpuesto -> 0.35 | J7: =TasaImpuesto -> 0.35 | K7: =TasaImpuesto -> 0.35 | L7: =TasaImpuesto -> 0.35 | ... Q7: =TasaImpuesto -> 0.35
B9: Drivers del Estado de Resultados | S9: Total COP | T9: Total USD
B10: Ingresos Mensuales (COP) | C10: fuente: P&L | F10: =Inputs!$D$132 -> 612247701 | G10: =Inputs!$E$132 -> 744218137 | H10: =Inputs!$F$132 -> 787041187 | I10: =Inputs!$G$132 -> 750867662 | J10: =Inputs!$H$132 -> 826514746 | K10: =Inputs!$I$132 -> 751453314 | L10: =Inputs!$J$132 -> 679890552 | M10: {=INDEX(Revenue!K:K,$E$18)} -> 9.7231409e+08 | N10: {=INDEX(Revenue!L:L,$E$18)} -> 1.1624883e+09 | O10: {=INDEX(Revenue!M:M,$E$18)} -> 1.1418829e+09 | P10: {=INDEX(Revenue!N:N,$E$18)} -> 1.1567582e+09 | Q10: {=INDEX(Revenue!O:O,$E$18)} -> 1.2443405e+09 | S10: =SUM(F10:Q10) -> 1.0830017e+10 | T10: =S10/TrmLargoPlazo -> 2934964
B11: Costo de Ventas Mensual (COP) | C11: fuente: P&L | F11: =Inputs!$D$135 -> 238535794 | G11: =Inputs!$E$135 -> 343308791 | H11: =Inputs!$F$135 -> 455639201 | I11: =Inputs!$G$135 -> 379273594 | J11: =Inputs!H135 -> 355470523 | K11: =Inputs!I135 -> 348477606 | L11: =Inputs!J135 -> 321917838 | M11: =CostoVentasBase*(1+InflacionAnual)*(1/12)+DeltaModQ3 -> 3.5252106e+08 | N11: =CostoVentasBase*(1+InflacionAnual)*(1/12)+DeltaModQ3 -> 3.5252106e+08 | O11: =CostoVentasBase*(1+InflacionAnual)*(1/12)+DeltaModQ3 -> 3.5252106e+08 | P11: =CostoVentasBase*(1+InflacionAnual)*(1/12)+DeltaModQ4 -> 3.6255022e+08 | Q11: =CostoVentasBase*(1+InflacionAnual)*(1/12)+DeltaModQ4 -> 3.6255022e+08 | S11: =SUM(F11:Q11) -> 4.225287e+09 | T11: =S11/TrmLargoPlazo -> 1145064.2
B12: Gastos Administrativos (COP) | F12: =Inputs!$D$139 -> 98722435 | G12: =Inputs!$E$139 -> 105633472 | H12: =Inputs!$F$139 -> 141811865 | I12: =Inputs!$G$139 -> 114280887 | J12: =Inputs!H139 -> 116808824 | K12: =Inputs!I139 -> 112288693 | L12: =Inputs!J139 -> 107932742 | M12: =GtosAdminBase*(1+InflacionAnual)*(1/12) -> 1.3539998e+08 | N12: =GtosAdminBase*(1+InflacionAnual)*(1/12) -> 1.3539998e+08 | O12: =GtosAdminBase*(1+InflacionAnual)*(1/12) -> 1.3539998e+08 | P12: =GtosAdminBase*(1+InflacionAnual)*(1/12) -> 1.3539998e+08 | Q12: =GtosAdminBase*(1+InflacionAnual)*(1/12) -> 1.3539998e+08 | S12: =SUM(F12:Q12) -> 1.4744788e+09 | T12: =S12/TrmLargoPlazo -> 399587.76
B13: Gastos de Ventas (COP) | F13: =Inputs!$D$142 -> 131600259 | G13: =Inputs!$E$142 -> 173632204 | H13: =Inputs!$F$142 -> 139615776 | I13: =Inputs!$G$142 -> 130090415 | J13: =Inputs!H142 -> 120233213 | K13: =Inputs!I142 -> 146803460 | L13: =Inputs!J142 -> 117761236 | M13: =GtosVentasBase*(1+InflacionAnual)*(1/12)+DeltaVtasQ3 -> 2.3088303e+08 | N13: =GtosVentasBase*(1+InflacionAnual)*(1/12)+DeltaVtasQ3 -> 2.3088303e+08 | O13: =GtosVentasBase*(1+InflacionAnual)*(1/12)+DeltaVtasQ3 -> 2.3088303e+08 | P13: =GtosVentasBase*(1+InflacionAnual)*(1/12)+DeltaVtasQ4 -> 2.3766442e+08 | Q13: =GtosVentasBase*(1+InflacionAnual)*(1/12)+DeltaVtasQ4 -> 2.3766442e+08 | S13: =SUM(F13:Q13) -> 2.1277145e+09 | T13: =S13/TrmLargoPlazo -> 576616.39
B14: Gastos Operativos/Proyectos (COP) | F14: =Inputs!$D$141 -> 73409852 | G14: =Inputs!$E$141 -> 75509638 | H14: =Inputs!$F$141 -> 72217138 | I14: =Inputs!$G$141 -> 122384514 | J14: =Inputs!H141 -> 120992711 | K14: =Inputs!I141 -> 108908060 | L14: =Inputs!J141 -> 102936374 | M14: =GtosOpInflado*(1/12) -> 1.1302524e+08 | N14: =GtosOpInflado*(1/12) -> 1.1302524e+08 | O14: =GtosOpInflado*(1/12) -> 1.1302524e+08 | P14: =GtosOpInflado*(1/12) -> 1.1302524e+08 | Q14: =GtosOpInflado*(1/12) -> 1.1302524e+08 | S14: =SUM(F14:Q14) -> 1.2414845e+09 | T14: =S14/TrmLargoPlazo -> 336445.66
