Workbook

Sheet Resumen MRR
A1: Análisis de Movimiento MRR — Junio vs Julio 2026
A2: MRR mensual = VENCIDA (Mes Anterior) + CORRIENTE (Mes en curso), por cliente. Caja Costa Rica (CCSS) reclasificada como Up Sale — no se cuenta como MRR recurrente.
A4: Categoría | B4: Total MRR | C4: # Clientes
A5: Retenidas MRR | B5: =+Detalle!I117-B11-B6-B10 -> 6.5617871e+08 | C5: =COUNTIF(Detalle!$K$2:$K$116,"Retenida") -> 42
A6: Nuevas Ventas MRR | B6: =SUMIF(Detalle!$K$2:$K$116,"Nueva",Detalle!$L$2:$L$116) -> 9249060 | C6: =COUNTIF(Detalle!$K$2:$K$116,"Nueva") -> 2
A7: Rescatadas MRR | B7: =SUMIF(Detalle!$K$2:$K$116,"Rescatada",Detalle!$L$2:$L$116) -> 0 | C7: =COUNTIF(Detalle!$K$2:$K$116,"Rescatada") -> 0
A8: Expansión MRR | B8: =SUMIF(Detalle!$K$2:$K$116,"Expansión",Detalle!$L$2:$L$116) -> 14828122 | C8: =COUNTIF(Detalle!$K$2:$K$116,"Expansión") -> 17
A9: Contracción MRR | B9: =SUMIF(Detalle!$K$2:$K$116,"Contracción",Detalle!$L$2:$L$116) -> 43146258 | C9: =COUNTIF(Detalle!$K$2:$K$116,"Contracción") -> 30
A10: Churned MRR | B10: =SUMIF(Detalle!$K$2:$K$116,"Churned",Detalle!$L$2:$L$116) -> 37681670 | C10: =COUNTIF(Detalle!$K$2:$K$116,"Churned") -> 4
A11: Up Sale / Ingreso no recurrente | B11: =SUMIF(Detalle!$K$2:$K$116,"Up Sale (no recurrente)",Detalle!$I$2:$I$116) -> 494843760 | C11: =COUNTIF(Detalle!$K$2:$K$116,"Up Sale (no recurrente)") -> 1
A13: Total MRR Junio (recurrente) | B13: =SUM(Detalle!H2:H116) -> 7.5986018e+08
A14: Total MRR Julio (recurrente) | B14: =SUM(Detalle!I2:I116)-SUMIF(Detalle!$K$2:$K$116,"Up Sale (no recurrente)",Detalle!$I$2:$I$116) -> 7.0310944e+08
A15: Variación neta (recurrente) | B15: =B14-B13 -> -56750746
A16: # Clientes sin actividad (Jun y Jul) | B16: =COUNTIF(Detalle!$K$2:$K$116,"Sin actividad") -> 19
A18: MRR mensual recurrente (histórico 2026)
A19: Enero | B19: =SUM(Detalle!C2:C116) -> 5.9286089e+08
A20: Febrero | B20: =SUM(Detalle!D2:D116) -> 6.9588403e+08
A21: Marzo | B21: =SUM(Detalle!E2:E116) -> 7.3407697e+08
A22: Abril | B22: =SUM(Detalle!F2:F116) -> 7.5404633e+08
A23: Mayo | B23: =SUM(Detalle!G2:G116) -> 7.7412262e+08
A24: Junio | B24: =SUM(Detalle!H2:H116) -> 7.5986018e+08
A25: Julio | B25: =SUM(Detalle!I2:I116)-SUMIF(Detalle!$K$2:$K$116,"Up Sale (no recurrente)",Detalle!$I$2:$I$116) -> 7.0310944e+08
A27: MRR promedio (Ene-Jul, recurrente) | B27: =AVERAGE(B19:B25) -> 7.1628007e+08
A29: ARR (Annual Recurring Revenue)
A30: ARR = MRR promedio Ene-Jul × 12 | B30: =B27*12 -> 8.5953608e+09
A32: Nota MRR: el MRR mensual de cada cliente = VENCIDA (Mes Anterior) + CORRIENTE (Mes en curso), pues distintos comerciales registran la factura en una u otra columna (casi nunca ambas a la vez). 'Nuevas Ventas' = $0 en junio y sin facturación previa Ene-Mayo. 'Rescatadas' = $0 en junio pero con facturación en algún mes Ene-Mayo, y volvieron a facturar en julio. Caja Costa Rica (CCSS) se reclasificó manualmente como Up Sale y se excluye de Nuevas Ventas, del Total MRR y del ARR.

Sheet Detalle
A1: Cliente | B1: Estado | C1: Enero | D1: Febrero | E1: Marzo | F1: Abril | G1: Mayo | H1: Junio | I1: Julio | J1: Tuvo histórico previo (Ene-May) | K1: Categoría | L1: Monto categoría | M1: Clasificación manual (override) | N1: Monto no recurrente (Up Sale)
A2: Preventist | B2: Activo | C2: 10471000 | D2: 14211600 | E2: 13198568 | F2: 20507241 | G2: 19480285 | H2: 20342970 | I2: 21630780 | J2: =IF(SUM(C2:G2)>0,1,0) -> 1 | K2: =IF(M2<>"",M2,IF(AND(H2=0,I2=0),"Sin actividad",IF(AND(H2=0,I2>0),IF(J2=1,"Rescatada","Nueva"),IF(AND(H2>0,I2=0),"Churned",IF(I2>H2,"Expansión",IF(I2<H2,"Contracción","Retenida")))))) -> Expansión | L2: =IF(K2="Up Sale (no recurrente)",0,IF(K2="Expansión",I2-H2,IF(K2="Contracción",H2-I2,IF(K2="Retenida",I2,IF(OR(K2="Nueva",K2="Rescatada"),I2,IF(K2="Churned",H2,0)))))) -> 1287810 | N2: =IF(K2="Up Sale (no recurrente)",I2,0) -> 0
A3: Emmely Coronado Peguero | B3: Activo | C3: 356865 | D3: 351463.8 | E3: 351463.8 | F3: 356961.45 | G3: 357540.15 | H3: 355900.5 | I3: 355900.5 | J3: =IF(SUM(C3:G3)>0,1,0) -> 1 | K3: =IF(M3<>"",M3,IF(AND(H3=0,I3=0),"Sin actividad",IF(AND(H3=0,I3>0),IF(J3=1,"Rescatada","Nueva"),IF(AND(H3>0,I3=0),"Churned",IF(I3>H3,"Expansión",IF(I3<H3,"Contracción","Retenida")))))) -> Retenida | L3: =IF(K3="Up Sale (no recurrente)",0,IF(K3="Expansión",I3-H3,IF(K3="Contracción",H3-I3,IF(K3="Retenida",I3,IF(OR(K3="Nueva",K3="Rescatada"),I3,IF(K3="Churned",H3,0)))))) -> 355900.5 | N3: =IF(K3="Up Sale (no recurrente)",I3,0) -> 0
A4: Fundacion para la Confianza | B4: Activo | C4: 203500 | D4: 200420 | E4: 200420 | F4: 200420 | G4: 203885 | H4: 202950 | I4: 202950 | J4: =IF(SUM(C4:G4)>0,1,0) -> 1 | K4: =IF(M4<>"",M4,IF(AND(H4=0,I4=0),"Sin actividad",IF(AND(H4=0,I4>0),IF(J4=1,"Rescatada","Nueva"),IF(AND(H4>0,I4=0),"Churned",IF(I4>H4,"Expansión",IF(I4<H4,"Contracción","Retenida")))))) -> Retenida | L4: =IF(K4="Up Sale (no recurrente)",0,IF(K4="Expansión",I4-H4,IF(K4="Contracción",H4-I4,IF(K4="Retenida",I4,IF(OR(K4="Nueva",K4="Rescatada"),I4,IF(K4="Churned",H4,0)))))) -> 202950 | N4: =IF(K4="Up Sale (no recurrente)",I4,0) -> 0
A5: Hospitalaria SAC (Pacifico Salud) | B5: Activo | C5: 0 | D5: 3015920.2 | E5: 4929020.2 | F5: 3015920.2 | G5: 3068061.5 | H5: 6707091.6 | I5: 3889887.3 | J5: =IF(SUM(C5:G5)>0,1,0) -> 1 | K5: =IF(M5<>"",M5,IF(AND(H5=0,I5=0),"Sin actividad",IF(AND(H5=0,I5>0),IF(J5=1,"Rescatada","Nueva"),IF(AND(H5>0,I5=0),"Churned",IF(I5>H5,"Expansión",IF(I5<H5,"Contracción","Retenida")))))) -> Contracción | L5: =IF(K5="Up Sale (no recurrente)",0,IF(K5="Expansión",I5-H5,IF(K5="Contracción",H5-I5,IF(K5="Retenida",I5,IF(OR(K5="Nueva",K5="Rescatada"),I5,IF(K5="Churned",H5,0)))))) -> 2817204.3 | N5: =IF(K5="Up Sale (no recurrente)",I5,0) -> 0
A6: Servicios Hospitalarios Brisas SA | B6: Activo | C6: 1110000 | D6: 0 | E6: 1110000 | F6: 1110300 | G6: 0 | H6: 0 | I6: 0 | J6: =IF(SUM(C6:G6)>0,1,0) -> 1 | K6: =IF(M6<>"",M6,IF(AND(H6=0,I6=0),"Sin actividad",IF(AND(H6=0,I6>0),IF(J6=1,"Rescatada","Nueva"),IF(AND(H6>0,I6=0),"Churned",IF(I6>H6,"Expansión",IF(I6<H6,"Contracción","Retenida")))))) -> Sin actividad | L6: =IF(K6="Up Sale (no recurrente)",0,IF(K6="Expansión",I6-H6,IF(K6="Contracción",H6-I6,IF(K6="Retenida",I6,IF(OR(K6="Nueva",K6="Rescatada"),I6,IF(K6="Churned",H6,0)))))) -> 0 | N6: =IF(K6="Up Sale (no recurrente)",I6,0) -> 0
A7: Caja Costa Rija (CCSS) | B7: Activo | C7: 0 | D7: 0 | E7: 0 | F7: 0 | G7: 0 | H7: 0 | I7: 494843760 | J7: =IF(SUM(C7:G7)>0,1,0) -> 0 | K7: =IF(M7<>"",M7,IF(AND(H7=0,I7=0),"Sin actividad",IF(AND(H7=0,I7>0),IF(J7=1,"Rescatada","Nueva"),IF(AND(H7>0,I7=0),"Churned",IF(I7>H7,"Expansión",IF(I7<H7,"Contracción","Retenida")))))) -> Up Sale (no recurrente) | L7: =IF(K7="Up Sale (no recurrente)",0,IF(K7="Expansión",I7-H7,IF(K7="Contracción",H7-I7,IF(K7="Retenida",I7,IF(OR(K7="Nueva",K7="Rescatada"),I7,IF(K7="Churned",H7,0)))))) -> 0 | M7: Up Sale (no recurrente) | N7: =IF(K7="Up Sale (no recurrente)",I7,0) -> 494843760
A8: Clínica Ziegler | B8: Activo | C8: 0 | D8: 0 | E8: 0 | F8: 0 | G8: 0 | H8: 0 | I8: 1749060 | J8: =IF(SUM(C8:G8)>0,1,0) -> 0 | K8: =IF(M8<>"",M8,IF(AND(H8=0,I8=0),"Sin actividad",IF(AND(H8=0,I8>0),IF(J8=1,"Rescatada","Nueva"),IF(AND(H8>0,I8=0),"Churned",IF(I8>H8,"Expansión",IF(I8<H8,"Contracción","Retenida")))))) -> Nueva | L8: =IF(K8="Up Sale (no recurrente)",0,IF(K8="Expansión",I8-H8,IF(K8="Contracción",H8-I8,IF(K8="Retenida",I8,IF(OR(K8="Nueva",K8="Rescatada"),I8,IF(K8="Churned",H8,0)))))) -> 1749060 | N8: =IF(K8="Up Sale (no recurrente)",I8,0) -> 0
A9: Dr Jaime (Ginecología) | B9: Activo | C9: 266098.14 | D9: 266098.14 | E9: 266098.14 | F9: 266098.14 | G9: 266098.14 | H9: 266098.14 | I9: 266098.14 | J9: =IF(SUM(C9:G9)>0,1,0) -> 1 | K9: =IF(M9<>"",M9,IF(AND(H9=0,I9=0),"Sin actividad",IF(AND(H9=0,I9>0),IF(J9=1,"Rescatada","Nueva"),IF(AND(H9>0,I9=0),"Churned",IF(I9>H9,"Expansión",IF(I9<H9,"Contracción","Retenida")))))) -> Retenida | L9: =IF(K9="Up Sale (no recurrente)",0,IF(K9="Expansión",I9-H9,IF(K9="Contracción",H9-I9,IF(K9="Retenida",I9,IF(OR(K9="Nueva",K9="Rescatada"),I9,IF(K9="Churned",H9,0)))))) -> 266098.14 | N9: =IF(K9="Up Sale (no recurrente)",I9,0) -> 0
A10: Oral Studio | B10: Activo | C10: 447047.62 | D10: 447047.62 | E10: 447047.62 | F10: 447047.62 | G10: 447047.62 | H10: 447047.62 | I10: 447047.62 | J10: =IF(SUM(C10:G10)>0,1,0) -> 1 | K10: =IF(M10<>"",M10,IF(AND(H10=0,I10=0),"Sin actividad",IF(AND(H10=0,I10>0),IF(J10=1,"Rescatada","Nueva"),IF(AND(H10>0,I10=0),"Churned",IF(I10>H10,"Expansión",IF(I10<H10,"Contracción","Retenida")))))) -> Retenida | L10: =IF(K10="Up Sale (no recurrente)",0,IF(K10="Expansión",I10-H10,IF(K10="Contracción",H10-I10,IF(K10="Retenida",I10,IF(OR(K10="Nueva",K10="Rescatada"),I10,IF(K10="Churned",H10,0)))))) -> 447047.62 | N10: =IF(K10="Up Sale (no recurrente)",I10,0) -> 0
A11: Clinica Guadalupe | B11: Activo | C11: 7595917 | D11: 9601552 | E11: 9601552 | F11: 7595917 | G11: 7983308.8 | H11: 7983308.8 | I11: 6654932 | J11: =IF(SUM(C11:G11)>0,1,0) -> 1 | K11: =IF(M11<>"",M11,IF(AND(H11=0,I11=0),"Sin actividad",IF(AND(H11=0,I11>0),IF(J11=1,"Rescatada","Nueva"),IF(AND(H11>0,I11=0),"Churned",IF(I11>H11,"Expansión",IF(I11<H11,"Contracción","Retenida")))))) -> Contracción | L11: =IF(K11="Up Sale (no recurrente)",0,IF(K11="Expansión",I11-H11,IF(K11="Contracción",H11-I11,IF(K11="Retenida",I11,IF(OR(K11="Nueva",K11="Rescatada"),I11,IF(K11="Churned",H11,0)))))) -> 1328376.8 | N11: =IF(K11="Up Sale (no recurrente)",I11,0) -> 0
A12: Clínica Panamericana (Zona Franca de Uraba) | B12: Activo | C12: 19150000 | D12: 19150000 | E12: 19150000 | F12: 19150000 | G12: 19150000 | H12: 19150000 | I12: 19150000 | J12: =IF(SUM(C12:G12)>0,1,0) -> 1 | K12: =IF(M12<>"",M12,IF(AND(H12=0,I12=0),"Sin actividad",IF(AND(H12=0,I12>0),IF(J12=1,"Rescatada","Nueva"),IF(AND(H12>0,I12=0),"Churned",IF(I12>H12,"Expansión",IF(I12<H12,"Contracción","Retenida")))))) -> Retenida | L12: =IF(K12="Up Sale (no recurrente)",0,IF(K12="Expansión",I12-H12,IF(K12="Contracción",H12-I12,IF(K12="Retenida",I12,IF(OR(K12="Nueva",K12="Rescatada"),I12,IF(K12="Churned",H12,0)))))) -> 19150000 | N12: =IF(K12="Up Sale (no recurrente)",I12,0) -> 0
A13: Vidamedical Bogotá - Cafam | B13: Activo | C13: 0 | D13: 29661904 | E13: 30509238 | F13: 30509238 | G13: 30509238 | H13: 30509238 | I13: 30509238 | J13: =IF(SUM(C13:G13)>0,1,0) -> 1 | K13: =IF(M13<>"",M13,IF(AND(H13=0,I13=0),"Sin actividad",IF(AND(H13=0,I13>0),IF(J13=1,"Rescatada","Nueva"),IF(AND(H13>0,I13=0),"Churned",IF(I13>H13,"Expansión",IF(I13<H13,"Contracción","Retenida")))))) -> Retenida | L13: =IF(K13="Up Sale (no recurrente)",0,IF(K13="Expansión",I13-H13,IF(K13="Contracción",H13-I13,IF(K13="Retenida",I13,IF(OR(K13="Nueva",K13="Rescatada"),I13,IF(K13="Churned",H13,0)))))) -> 30509238 | N13: =IF(K13="Up Sale (no recurrente)",I13,0) -> 0
A14: Vidamedical Cúcuta | B14: Activo | C14: 0 | D14: 5965476 | E14: 5118142 | F14: 5118142 | G14: 5118142 | H14: 5118142 | I14: 5118142 | J14: =IF(SUM(C14:G14)>0,1,0) -> 1 | K14: =IF(M14<>"",M14,IF(AND(H14=0,I14=0),"Sin actividad",IF(AND(H14=0,I14>0),IF(J14=1,"Rescatada","Nueva"),IF(AND(H14>0,I14=0),"Churned",IF(I14>H14,"Expansión",IF(I14<H14,"Contracción","Retenida")))))) -> Retenida | L14: =IF(K14="Up Sale (no recurrente)",0,IF(K14="Expansión",I14-H14,IF(K14="Contracción",H14-I14,IF(K14="Retenida",I14,IF(OR(K14="Nueva",K14="Rescatada"),I14,IF(K14="Churned",H14,0)))))) -> 5118142 | N14: =IF(K14="Up Sale (no recurrente)",I14,0) -> 0
A15: Fundación Organización Vid | B15: Activo | C15: 2338699.2 | D15: 2338699 | E15: 14099524 | F15: 14254915 | G15: 14440019 | H15: 14793897 | I15: 15149201 | J15: =IF(SUM(C15:G15)>0,1,0) -> 1 | K15: =IF(M15<>"",M15,IF(AND(H15=0,I15=0),"Sin actividad",IF(AND(H15=0,I15>0),IF(J15=1,"Rescatada","Nueva"),IF(AND(H15>0,I15=0),"Churned",IF(I15>H15,"Expansión",IF(I15<H15,"Contracción","Retenida")))))) -> Expansión | L15: =IF(K15="Up Sale (no recurrente)",0,IF(K15="Expansión",I15-H15,IF(K15="Contracción",H15-I15,IF(K15="Retenida",I15,IF(OR(K15="Nueva",K15="Rescatada"),I15,IF(K15="Churned",H15,0)))))) -> 355304 | N15: =IF(K15="Up Sale (no recurrente)",I15,0) -> 0
A16: Clinica Cardio VID | B16: Activo | C16: 0 | D16: 0 | E16: 4048044 | F16: 3892653 | G16: 3707549 | H16: 3348226 | I16: 2998368 | J16: =IF(SUM(C16:G16)>0,1,0) -> 1 | K16: =IF(M16<>"",M16,IF(AND(H16=0,I16=0),"Sin actividad",IF(AND(H16=0,I16>0),IF(J16=1,"Rescatada","Nueva"),IF(AND(H16>0,I16=0),"Churned",IF(I16>H16,"Expansión",IF(I16<H16,"Contracción","Retenida")))))) -> Contracción | L16: =IF(K16="Up Sale (no recurrente)",0,IF(K16="Expansión",I16-H16,IF(K16="Contracción",H16-I16,IF(K16="Retenida",I16,IF(OR(K16="Nueva",K16="Rescatada"),I16,IF(K16="Churned",H16,0)))))) -> 349858 | N16: =IF(K16="Up Sale (no recurrente)",I16,0) -> 0
A17: Central de Especialistas | B17: Activo | C17: 2177417 | D17: 3996370 | E17: 3899447 | F17: 3628439 | G17: 2730725 | H17: 3924364.6 | I17: 3324724.6 | J17: =IF(SUM(C17:G17)>0,1,0) -> 1 | K17: =IF(M17<>"",M17,IF(AND(H17=0,I17=0),"Sin actividad",IF(AND(H17=0,I17>0),IF(J17=1,"Rescatada","Nueva"),IF(AND(H17>0,I17=0),"Churned",IF(I17>H17,"Expansión",IF(I17<H17,"Contracción","Retenida")))))) -> Contracción | L17: =IF(K17="Up Sale (no recurrente)",0,IF(K17="Expansión",I17-H17,IF(K17="Contracción",H17-I17,IF(K17="Retenida",I17,IF(OR(K17="Nueva",K17="Rescatada"),I17,IF(K17="Churned",H17,0)))))) -> 599640 | N17: =IF(K17="Up Sale (no recurrente)",I17,0) -> 0
A18: Reencontrarse | B18: Activo | C18: 9819552 | D18: 10330169 | E18: 10320349 | F18: 10320349 | G18: 10320349 | H18: 10523660 | I18: 10320349 | J18: =IF(SUM(C18:G18)>0,1,0) -> 1 | K18: =IF(M18<>"",M18,IF(AND(H18=0,I18=0),"Sin actividad",IF(AND(H18=0,I18>0),IF(J18=1,"Rescatada","Nueva"),IF(AND(H18>0,I18=0),"Churned",IF(I18>H18,"Expansión",IF(I18<H18,"Contracción","Retenida")))))) -> Contracción | L18: =IF(K18="Up Sale (no recurrente)",0,IF(K18="Expansión",I18-H18,IF(K18="Contracción",H18-I18,IF(K18="Retenida",I18,IF(OR(K18="Nueva",K18="Rescatada"),I18,IF(K18="Churned",H18,0)))))) -> 203310.88 | N18: =IF(K18="Up Sale (no recurrente)",I18,0) -> 0
A19: San Diego | B19: Activo | C19: 688546.96 | D19: 688546.96 | E19: 688546.96 | F19: 688546.96 | G19: 688546.96 | H19: 688546.96 | I19: 688546.96 | J19: =IF(SUM(C19:G19)>0,1,0) -> 1 | K19: =IF(M19<>"",M19,IF(AND(H19=0,I19=0),"Sin actividad",IF(AND(H19=0,I19>0),IF(J19=1,"Rescatada","Nueva"),IF(AND(H19>0,I19=0),"Churned",IF(I19>H19,"Expansión",IF(I19<H19,"Contracción","Retenida")))))) -> Retenida | L19: =IF(K19="Up Sale (no recurrente)",0,IF(K19="Expansión",I19-H19,IF(K19="Contracción",H19-I19,IF(K19="Retenida",I19,IF(OR(K19="Nueva",K19="Rescatada"),I19,IF(K19="Churned",H19,0)))))) -> 688546.96 | N19: =IF(K19="Up Sale (no recurrente)",I19,0) -> 0
... A88: ESE Hospital Local de Montelibano | B88: Activo | C88: 0 | D88: 6312000 | E88: 0 | F88: 0 | G88: 0 | H88: 0 | I88: 0 | J88: =IF(SUM(C88:G88)>0,1,0) -> 1 | K88: =IF(M88<>"",M88,IF(AND(H88=0,I88=0),"Sin actividad",IF(AND(H88=0,I88>0),IF(J88=1,"Rescatada","Nueva"),IF(AND(H88>0,I88=0),"Churned",IF(I88>H88,"Expansión",IF(I88<H88,"Contracción","Retenida")))))) -> Sin actividad | L88: =IF(K88="Up Sale (no recurrente)",0,IF(K88="Expansión",I88-H88,IF(K88="Contracción",H88-I88,IF(K88="Retenida",I88,IF(OR(K88="Nueva",K88="Rescatada"),I88,IF(K88="Churned",H88,0)))))) -> 0 | N88: =IF(K88="Up Sale (no recurrente)",I88,0) -> 0
A89: DermaPau Plus SAS | C89: 2150000 | D89: 0 | E89: 10965000 | F89: 0 | G89: 0 | H89: 0 | I89: 0 | J89: =IF(SUM(C89:G89)>0,1,0) -> 1 | K89: =IF(M89<>"",M89,IF(AND(H89=0,I89=0),"Sin actividad",IF(AND(H89=0,I89>0),IF(J89=1,"Rescatada","Nueva"),IF(AND(H89>0,I89=0),"Churned",IF(I89>H89,"Expansión",IF(I89<H89,"Contracción","Retenida")))))) -> Sin actividad | L89: =IF(K89="Up Sale (no recurrente)",0,IF(K89="Expansión",I89-H89,IF(K89="Contracción",H89-I89,IF(K89="Retenida",I89,IF(OR(K89="Nueva",K89="Rescatada"),I89,IF(K89="Churned",H89,0)))))) -> 0 | N89: =IF(K89="Up Sale (no recurrente)",I89,0) -> 0
A90: ESE San Jose - (San Andres - Bucaramanga) | C90: 0 | D90: 0 | E90: 0 | F90: 0 | G90: 3585600 | H90: 1106400 | I90: 1178400 | J90: =IF(SUM(C90:G90)>0,1,0) -> 1 | K90: =IF(M90<>"",M90,IF(AND(H90=0,I90=0),"Sin actividad",IF(AND(H90=0,I90>0),IF(J90=1,"Rescatada","Nueva"),IF(AND(H90>0,I90=0),"Churned",IF(I90>H90,"Expansión",IF(I90<H90,"Contracción","Retenida")))))) -> Expansión | L90: =IF(K90="Up Sale (no recurrente)",0,IF(K90="Expansión",I90-H90,IF(K90="Contracción",H90-I90,IF(K90="Retenida",I90,IF(OR(K90="Nueva",K90="Rescatada"),I90,IF(K90="Churned",H90,0)))))) -> 72000 | N90: =IF(K90="Up Sale (no recurrente)",I90,0) -> 0
A91: Cooperativa San Esteban IPS | C91: 0 | D91: 0 | E91: 0 | F91: 0 | G91: 0 | H91: 0 | I91: 0 | J91: =IF(SUM(C91:G91)>0,1,0) -> 0 | K91: =IF(M91<>"",M91,IF(AND(H91=0,I91=0),"Sin actividad",IF(AND(H91=0,I91>0),IF(J91=1,"Rescatada","Nueva"),IF(AND(H91>0,I91=0),"Churned",IF(I91>H91,"Expansión",IF(I91<H91,"Contracción","Retenida")))))) -> Sin actividad | L91: =IF(K91="Up Sale (no recurrente)",0,IF(K91="Expansión",I91-H91,IF(K91="Contracción",H91-I91,IF(K91="Retenida",I91,IF(OR(K91="Nueva",K91="Rescatada"),I91,IF(K91="Churned",H91,0)))))) -> 0 | N91: =IF(K91="Up Sale (no recurrente)",I91,0) -> 0
A92: Neurodinamia SA | C92: 0 | D92: 0 | E92: 0 | F92: 7100000 | G92: 7100000 | H92: 8333980 | I92: 11936520 | J92: =IF(SUM(C92:G92)>0,1,0) -> 1 | K92: =IF(M92<>"",M92,IF(AND(H92=0,I92=0),"Sin actividad",IF(AND(H92=0,I92>0),IF(J92=1,"Rescatada","Nueva"),IF(AND(H92>0,I92=0),"Churned",IF(I92>H92,"Expansión",IF(I92<H92,"Contracción","Retenida")))))) -> Expansión | L92: =IF(K92="Up Sale (no recurrente)",0,IF(K92="Expansión",I92-H92,IF(K92="Contracción",H92-I92,IF(K92="Retenida",I92,IF(OR(K92="Nueva",K92="Rescatada"),I92,IF(K92="Churned",H92,0)))))) -> 3602540 | N92: =IF(K92="Up Sale (no recurrente)",I92,0) -> 0
A93: Clinica de Ojos (CLINOJOS) SA | B93: Activo | C93: 0 | D93: 0 | E93: 9468810 | F93: 13273756 | G93: 15829636 | H93: 13273756 | I93: 13273756 | J93: =IF(SUM(C93:G93)>0,1,0) -> 1 | K93: =IF(M93<>"",M93,IF(AND(H93=0,I93=0),"Sin actividad",IF(AND(H93=0,I93>0),IF(J93=1,"Rescatada","Nueva"),IF(AND(H93>0,I93=0),"Churned",IF(I93>H93,"Expansión",IF(I93<H93,"Contracción","Retenida")))))) -> Retenida | L93: =IF(K93="Up Sale (no recurrente)",0,IF(K93="Expansión",I93-H93,IF(K93="Contracción",H93-I93,IF(K93="Retenida",I93,IF(OR(K93="Nueva",K93="Rescatada"),I93,IF(K93="Churned",H93,0)))))) -> 13273756 | N93: =IF(K93="Up Sale (no recurrente)",I93,0) -> 0
A94: Centro de Ortopedia y Rehabilitacion Ortovital Integral SAS | B94: Activo | C94: 0 | D94: 0 | E94: 0 | F94: 6356250 | G94: 6356250 | H94: 7658550 | I94: 6356250 | J94: =IF(SUM(C94:G94)>0,1,0) -> 1 | K94: =IF(M94<>"",M94,IF(AND(H94=0,I94=0),"Sin actividad",IF(AND(H94=0,I94>0),IF(J94=1,"Rescatada","Nueva"),IF(AND(H94>0,I94=0),"Churned",IF(I94>H94,"Expansión",IF(I94<H94,"Contracción","Retenida")))))) -> Contracción | L94: =IF(K94="Up Sale (no recurrente)",0,IF(K94="Expansión",I94-H94,IF(K94="Contracción",H94-I94,IF(K94="Retenida",I94,IF(OR(K94="Nueva",K94="Rescatada"),I94,IF(K94="Churned",H94,0)))))) -> 1302300 | N94: =IF(K94="Up Sale (no recurrente)",I94,0) -> 0
A95: Hospital San Bernabe ESE (ASOHSVAL) | C95: 0 | D95: 0 | E95: 0 | F95: 0 | G95: 0 | H95: 5482828 | I95: 3262207 | J95: =IF(SUM(C95:G95)>0,1,0) -> 0 | K95: =IF(M95<>"",M95,IF(AND(H95=0,I95=0),"Sin actividad",IF(AND(H95=0,I95>0),IF(J95=1,"Rescatada","Nueva"),IF(AND(H95>0,I95=0),"Churned",IF(I95>H95,"Expansión",IF(I95<H95,"Contracción","Retenida")))))) -> Contracción | L95: =IF(K95="Up Sale (no recurrente)",0,IF(K95="Expansión",I95-H95,IF(K95="Contracción",H95-I95,IF(K95="Retenida",I95,IF(OR(K95="Nueva",K95="Rescatada"),I95,IF(K95="Churned",H95,0)))))) -> 2220621 | N95: =IF(K95="Up Sale (no recurrente)",I95,0) -> 0
A96: Medihel Services Colombia | B96: Activo | C96: 0 | D96: 0 | E96: 0 | F96: 0 | G96: 0 | H96: 0 | I96: 7500000 | J96: =IF(SUM(C96:G96)>0,1,0) -> 0 | K96: =IF(M96<>"",M96,IF(AND(H96=0,I96=0),"Sin actividad",IF(AND(H96=0,I96>0),IF(J96=1,"Rescatada","Nueva"),IF(AND(H96>0,I96=0),"Churned",IF(I96>H96,"Expansión",IF(I96<H96,"Contracción","Retenida")))))) -> Nueva | L96: =IF(K96="Up Sale (no recurrente)",0,IF(K96="Expansión",I96-H96,IF(K96="Contracción",H96-I96,IF(K96="Retenida",I96,IF(OR(K96="Nueva",K96="Rescatada"),I96,IF(K96="Churned",H96,0)))))) -> 7500000 | N96: =IF(K96="Up Sale (no recurrente)",I96,0) -> 0
A97: Audiocom SAS | C97: 0 | D97: 0 | E97: 0 | F97: 0 | G97: 0 | H97: 0 | I97: 0 | J97: =IF(SUM(C97:G97)>0,1,0) -> 0 | K97: =IF(M97<>"",M97,IF(AND(H97=0,I97=0),"Sin actividad",IF(AND(H97=0,I97>0),IF(J97=1,"Rescatada","Nueva"),IF(AND(H97>0,I97=0),"Churned",IF(I97>H97,"Expansión",IF(I97<H97,"Contracción","Retenida")))))) -> Sin actividad | L97: =IF(K97="Up Sale (no recurrente)",0,IF(K97="Expansión",I97-H97,IF(K97="Contracción",H97-I97,IF(K97="Retenida",I97,IF(OR(K97="Nueva",K97="Rescatada"),I97,IF(K97="Churned",H97,0)))))) -> 0 | N97: =IF(K97="Up Sale (no recurrente)",I97,0) -> 0
A98: Fundacion Liberate | B98: Rangos | C98: 0 | D98: 0 | E98: 0 | F98: 4693114 | G98: 0 | H98: 5678214 | I98: 3378214 | J98: =IF(SUM(C98:G98)>0,1,0) -> 1 | K98: =IF(M98<>"",M98,IF(AND(H98=0,I98=0),"Sin actividad",IF(AND(H98=0,I98>0),IF(J98=1,"Rescatada","Nueva"),IF(AND(H98>0,I98=0),"Churned",IF(I98>H98,"Expansión",IF(I98<H98,"Contracción","Retenida")))))) -> Contracción | L98: =IF(K98="Up Sale (no recurrente)",0,IF(K98="Expansión",I98-H98,IF(K98="Contracción",H98-I98,IF(K98="Retenida",I98,IF(OR(K98="Nueva",K98="Rescatada"),I98,IF(K98="Churned",H98,0)))))) -> 2300000 | N98: =IF(K98="Up Sale (no recurrente)",I98,0) -> 0
A99: Centro Intercultural de Atencion en Salud (CIAS) | C99: 0 | D99: 0 | E99: 0 | F99: 0 | G99: 1395000 | H99: 0 | I99: 0 | J99: =IF(SUM(C99:G99)>0,1,0) -> 1 | K99: =IF(M99<>"",M99,IF(AND(H99=0,I99=0),"Sin actividad",IF(AND(H99=0,I99>0),IF(J99=1,"Rescatada","Nueva"),IF(AND(H99>0,I99=0),"Churned",IF(I99>H99,"Expansión",IF(I99<H99,"Contracción","Retenida")))))) -> Sin actividad | L99: =IF(K99="Up Sale (no recurrente)",0,IF(K99="Expansión",I99-H99,IF(K99="Contracción",H99-I99,IF(K99="Retenida",I99,IF(OR(K99="Nueva",K99="Rescatada"),I99,IF(K99="Churned",H99,0)))))) -> 0 | N99: =IF(K99="Up Sale (no recurrente)",I99,0) -> 0
A100: Ese Hospital San Fernando (Amagá) | C100: 0 | D100: 0 | E100: 0 | F100: 0 | G100: 6698888 | H100: 3284952 | I100: 3055320 | J100: =IF(SUM(C100:G100)>0,1,0) -> 1 | K100: =IF(M100<>"",M100,IF(AND(H100=0,I100=0),"Sin actividad",IF(AND(H100=0,I100>0),IF(J100=1,"Rescatada","Nueva"),IF(AND(H100>0,I100=0),"Churned",IF(I100>H100,"Expansión",IF(I100<H100,"Contracción","Retenida")))))) -> Contracción | L100: =IF(K100="Up Sale (no recurrente)",0,IF(K100="Expansión",I100-H100,IF(K100="Contracción",H100-I100,IF(K100="Retenida",I100,IF(OR(K100="Nueva",K100="Rescatada"),I100,IF(K100="Churned",H100,0)))))) -> 229632 | N100: =IF(K100="Up Sale (no recurrente)",I100,0) -> 0
A101: Ese Hosptal la Anunciacion (Mutata) | C101: 0 | D101: 0 | E101: 0 | F101: 0 | G101: 4560072 | H101: 2181136 | I101: 2127224 | J101: =IF(SUM(C101:G101)>0,1,0) -> 1 | K101: =IF(M101<>"",M101,IF(AND(H101=0,I101=0),"Sin actividad",IF(AND(H101=0,I101>0),IF(J101=1,"Rescatada","Nueva"),IF(AND(H101>0,I101=0),"Churned",IF(I101>H101,"Expansión",IF(I101<H101,"Contracción","Retenida")))))) -> Contracción | L101: =IF(K101="Up Sale (no recurrente)",0,IF(K101="Expansión",I101-H101,IF(K101="Contracción",H101-I101,IF(K101="Retenida",I101,IF(OR(K101="Nueva",K101="Rescatada"),I101,IF(K101="Churned",H101,0)))))) -> 53912 | N101: =IF(K101="Up Sale (no recurrente)",I101,0) -> 0
A102: Ese Hospital Maria Auxiliadora (Chigorodo) | C102: 0 | D102: 0 | E102: 0 | F102: 0 | G102: 4360248 | H102: 2262648 | I102: 2060064 | J102: =IF(SUM(C102:G102)>0,1,0) -> 1 | K102: =IF(M102<>"",M102,IF(AND(H102=0,I102=0),"Sin actividad",IF(AND(H102=0,I102>0),IF(J102=1,"Rescatada","Nueva"),IF(AND(H102>0,I102=0),"Churned",IF(I102>H102,"Expansión",IF(I102<H102,"Contracción","Retenida")))))) -> Contracción | L102: =IF(K102="Up Sale (no recurrente)",0,IF(K102="Expansión",I102-H102,IF(K102="Contracción",H102-I102,IF(K102="Retenida",I102,IF(OR(K102="Nueva",K102="Rescatada"),I102,IF(K102="Churned",H102,0)))))) -> 202584 | N102: =IF(K102="Up Sale (no recurrente)",I102,0) -> 0
A103: Ese Hospital Francisco Luis Jimenez (Carepa) | C103: 0 | D103: 0 | E103: 0 | F103: 1133440 | G103: 1042728 | H103: 774456 | I103: 672520 | J103: =IF(SUM(C103:G103)>0,1,0) -> 1 | K103: =IF(M103<>"",M103,IF(AND(H103=0,I103=0),"Sin actividad",IF(AND(H103=0,I103>0),IF(J103=1,"Rescatada","Nueva"),IF(AND(H103>0,I103=0),"Churned",IF(I103>H103,"Expansión",IF(I103<H103,"Contracción","Retenida")))))) -> Contracción | L103: =IF(K103="Up Sale (no recurrente)",0,IF(K103="Expansión",I103-H103,IF(K103="Contracción",H103-I103,IF(K103="Retenida",I103,IF(OR(K103="Nueva",K103="Rescatada"),I103,IF(K103="Churned",H103,0)))))) -> 101936 | N103: =IF(K103="Up Sale (no recurrente)",I103,0) -> 0
A104: Ese Hospital San Rafael (San Luis) | C104: 0 | D104: 0 | E104: 0 | F104: 0 | G104: 916136 | H104: 0 | I104: 0 | J104: =IF(SUM(C104:G104)>0,1,0) -> 1 | K104: =IF(M104<>"",M104,IF(AND(H104=0,I104=0),"Sin actividad",IF(AND(H104=0,I104>0),IF(J104=1,"Rescatada","Nueva"),IF(AND(H104>0,I104=0),"Churned",IF(I104>H104,"Expansión",IF(I104<H104,"Contracción","Retenida")))))) -> Sin actividad | L104: =IF(K104="Up Sale (no recurrente)",0,IF(K104="Expansión",I104-H104,IF(K104="Contracción",H104-I104,IF(K104="Retenida",I104,IF(OR(K104="Nueva",K104="Rescatada"),I104,IF(K104="Churned",H104,0)))))) -> 0 | N104: =IF(K104="Up Sale (no recurrente)",I104,0) -> 0
A105: Ese San Joaquin (Nariño) | C105: 0 | D105: 0 | E105: 0 | F105: 0 | G105: 666080 | H105: 456320 | I105: 310592 | J105: =IF(SUM(C105:G105)>0,1,0) -> 1 | K105: =IF(M105<>"",M105,IF(AND(H105=0,I105=0),"Sin actividad",IF(AND(H105=0,I105>0),IF(J105=1,"Rescatada","Nueva"),IF(AND(H105>0,I105=0),"Churned",IF(I105>H105,"Expansión",IF(I105<H105,"Contracción","Retenida")))))) -> Contracción | L105: =IF(K105="Up Sale (no recurrente)",0,IF(K105="Expansión",I105-H105,IF(K105="Contracción",H105-I105,IF(K105="Retenida",I105,IF(OR(K105="Nueva",K105="Rescatada"),I105,IF(K105="Churned",H105,0)))))) -> 145728 | N105: =IF(K105="Up Sale (no recurrente)",I105,0) -> 0
A106: Hospital San Antonio de (Buritica) | C106: 0 | D106: 0 | E106: 0 | F106: 0 | G106: 464232 | H106: 329912 | I106: 154376 | J106: =IF(SUM(C106:G106)>0,1,0) -> 1 | K106: =IF(M106<>"",M106,IF(AND(H106=0,I106=0),"Sin actividad",IF(AND(H106=0,I106>0),IF(J106=1,"Rescatada","Nueva"),IF(AND(H106>0,I106=0),"Churned",IF(I106>H106,"Expansión",IF(I106<H106,"Contracción","Retenida")))))) -> Contracción | L106: =IF(K106="Up Sale (no recurrente)",0,IF(K106="Expansión",I106-H106,IF(K106="Contracción",H106-I106,IF(K106="Retenida",I106,IF(OR(K106="Nueva",K106="Rescatada"),I106,IF(K106="Churned",H106,0)))))) -> 175536 | N106: =IF(K106="Up Sale (no recurrente)",I106,0) -> 0
A107: Ese Hospital San Antonio (Betania) | C107: 0 | D107: 0 | E107: 0 | F107: 0 | G107: 670680 | H107: 430928 | I107: 412528 | J107: =IF(SUM(C107:G107)>0,1,0) -> 1 | K107: =IF(M107<>"",M107,IF(AND(H107=0,I107=0),"Sin actividad",IF(AND(H107=0,I107>0),IF(J107=1,"Rescatada","Nueva"),IF(AND(H107>0,I107=0),"Churned",IF(I107>H107,"Expansión",IF(I107<H107,"Contracción","Retenida")))))) -> Contracción | L107: =IF(K107="Up Sale (no recurrente)",0,IF(K107="Expansión",I107-H107,IF(K107="Contracción",H107-I107,IF(K107="Retenida",I107,IF(OR(K107="Nueva",K107="Rescatada"),I107,IF(K107="Churned",H107,0)))))) -> 18400 | N107: =IF(K107="Up Sale (no recurrente)",I107,0) -> 0
A108: Ese Hospital Santa Isabel (Gomez Plata) | C108: 0 | D108: 0 | E108: 0 | F108: 0 | G108: 973912 | H108: 586040 | I108: 438472 | J108: =IF(SUM(C108:G108)>0,1,0) -> 1 | K108: =IF(M108<>"",M108,IF(AND(H108=0,I108=0),"Sin actividad",IF(AND(H108=0,I108>0),IF(J108=1,"Rescatada","Nueva"),IF(AND(H108>0,I108=0),"Churned",IF(I108>H108,"Expansión",IF(I108<H108,"Contracción","Retenida")))))) -> Contracción | L108: =IF(K108="Up Sale (no recurrente)",0,IF(K108="Expansión",I108-H108,IF(K108="Contracción",H108-I108,IF(K108="Retenida",I108,IF(OR(K108="Nueva",K108="Rescatada"),I108,IF(K108="Churned",H108,0)))))) -> 147568 | N108: =IF(K108="Up Sale (no recurrente)",I108,0) -> 0
...
