Workbook
Name CostoVentasBase: Inputs!$C$40
Name DeltaModQ2: Inputs!$D$75
Name DeltaModQ3: Inputs!$D$76
Name DeltaModQ4: Inputs!$D$77
Name DeltaVtasQ2: Inputs!$E$75
Name DeltaVtasQ3: Inputs!$E$76
Name DeltaVtasQ4: Inputs!$E$77
Name GtosAdminBase: Inputs!$C$44
Name GtosNoOpBase: Inputs!$C$54
Name GtosOpInflado: Inputs!$D$55
Name GtosVentasBase: Inputs!$C$48
Name InflacionAnual: Inputs!$C$11
Name IngNoOpBase: Inputs!$C$53
Name TasaDeudaLp: Inputs!$C$28
Name TasaImpuesto: Inputs!$C$25
Name TrmLargoPlazo: Inputs!$C$6

Sheet Burn & RunW
B2: ANÁLISIS CONSOLIDADO — INGRESOS, MÁRGENES, FCF BURN Y RUNWAY
B6: INDICADORES ACUMULADOS CONSOLIDADOS — ENE-JUL 2026 (Colombia real a julio; internacional hasta junio)
B7: Indicador | C7: Valor | D7: Unidad | E7: Explicación / criterio
B8: Ingresos acumulados año | C8: =(Inputs!$N$132+SUM('Consolidado '!C6:E7)*'Consolidado '!F4+SUM('Consolidado '!H6:J7)*'Consolidado '!K4+SUM('Consolidado '!M6:O7)*'Consolidado '!P4)/1000000 -> 5292.1427 | D8: COP MM | E8: Ingresos reales consolidados: Colombia enero-julio (estados financieros) más USA, Perú y Costa Rica disponibles para abril-junio; sin doble contar Colombia.
B9: Ingresos acumulados presupuesto | C9: =(SUM('Informe Accionista'!C65:F65)*'Informe Accionista'!$M$3+SUM('Informe Accionista'!G58:I58)*'Informe Accionista'!$M$2)/1000000 -> 8516.2305 | D9: COP MM | E9: Presupuesto acumulado consolidado: enero-abril utiliza el presupuesto original anual de USD 4,555,726; mayo-julio utiliza el nuevo presupuesto consolidado anual de USD 4,067,468 (~USD 4.0MM).
B10: Quema neta acumulada año — Colombia | C10: =MAX(0,('Modelo Base'!$E$34-Inputs!$J$93)/1000000) -> 57.192074 | D10: COP MM | E10: Acumulado enero-julio 2026. Fórmula: MAX(0, Caja inicial al 31-dic-2025 − Caja final al 31-jul-2026). Equivale a sumar todas las variaciones mensuales de la caja histórica de Colombia. No utiliza CapEx estimado.
B11: Quema neta acumulada año — otros países | C11: =MAX(0,-SUM(C15:C17)) -> 341.56351 | D11: COP MM | E11: Acumulado 2026 con información disponible de abril-junio para USA, Perú y Costa Rica. Fórmula: MAX(0, −SUMA de los flujos netos bancarios mensuales). Cada flujo mensual corresponde a cobros menos pagos, convertido a COP con la TRM del mes; excluye Colombia.
B12: Quema neta acumulada año — consolidada | C12: =C10+C11 -> 398.75558 | D12: COP MM | E12: Acumulado 2026: quema neta histórica de Colombia a julio más quema neta de USA, Perú y Costa Rica disponible de abril-junio (julio internacional aún sin información bancaria).
B14: Cumplimeinto Acumulado Presupuesto | C14: =C8/C9 -> 0.62141844
B15: Flujo neto abril — otros países | C15: =SUM(_xlfn.XLOOKUP("Utilidad",'Consolidado '!$B$6:$B$17,'Consolidado '!$C$6:$E$17))*'Consolidado '!$F$4/1000000 -> -154.56619 | D15: COP MM | E15: XLOOKUP busca la fila Utilidad y suma USA, Perú y Costa Rica de abril.
B16: Flujo neto mayo — otros países | C16: =SUM(_xlfn.XLOOKUP("Utilidad",'Consolidado '!$B$6:$B$17,'Consolidado '!$H$6:$J$17))*'Consolidado '!$K$4/1000000 -> -105.79334 | D16: COP MM | E16: XLOOKUP busca la fila Utilidad y suma USA, Perú y Costa Rica de mayo.
B17: Flujo neto junio — otros países | C17: =SUM(_xlfn.XLOOKUP("Utilidad",'Consolidado '!$B$6:$B$17,'Consolidado '!$M$6:$O$17))*'Consolidado '!$P$4/1000000 -> -81.203976 | D17: COP MM | E17: XLOOKUP busca la fila Utilidad y suma USA, Perú y Costa Rica de junio.
B18: El análisis usa la caja total consolidada y el FCF burn consolidado. Colombia proviene de los estados financieros (reales hasta julio); el flujo internacional (USA, Perú y Costa Rica) está incorporado hasta junio, excluyendo Colombia del Consolidado USD para evitar doble conteo. Julio aún no incluye flujo internacional.
B19: FCF BURN Y CAMBIO DE CAJA MENSUAL — ENE-JUL 2026 (COP MM)
B20: Mes | C20: CFO Colombia | D20: CapEx Colombia | E20: Flujo caja internacional | F20: FCF / Flujo caja consolidado | G20: FCF Burn | H20: Pre-WC Burn | I20: Cambio neto caja consolidado | J20: Lectura
B21: Ene-26 | C21: ='Modelo Base'!F168/1000000 -> 254.49508 | D21: ='Modelo Base'!F171/1000000 -> -7.880549 | F21: =SUM(C21:E21) -> 246.61453 | G21: =MAX(0,-F21) -> 0 | H21: =MAX(0,-(('Informe Accionista'!C129/1000000)+D21)) -> 0 | I21: ='Modelo Base'!F179/1000000 -> 229.38317 | J21: Enero concentra el mayor FCF burn del periodo.
B22: Feb-26 | C22: ='Modelo Base'!G168/1000000 -> -267.33079 | D22: ='Modelo Base'!G171/1000000 -> -6.729228 | F22: =SUM(C22:E22) -> -274.06002 | G22: =MAX(0,-F22) -> 274.06002 | H22: =MAX(0,-(('Informe Accionista'!D129/1000000)+D22)) -> 0 | I22: ='Modelo Base'!G179/1000000 -> -268.3655 | J22: Este mes explica el burn del periodo.
B23: Mar-26 | C23: ='Modelo Base'!H168/1000000 -> 51.916596 | D23: ='Modelo Base'!H171/1000000 -> -0.985518 | F23: =SUM(C23:E23) -> 50.931078 | G23: =MAX(0,-F23) -> 0 | H23: =MAX(0,-(('Informe Accionista'!E129/1000000)+D23)) -> 23.228311 | I23: ='Modelo Base'!H179/1000000 -> 74.756784 | J23: FCF positivo; solo se ve presión en la vista pre-WC.
B24: Abr-26 | C24: ='Modelo Base'!I168/1000000 -> 89.724697 | D24: ='Modelo Base'!I171/1000000 -> -3213.6098 | E24: =(('Consolidado '!C6+'Consolidado '!C11)+('Consolidado '!D6-'Consolidado '!D15)+('Consolidado '!E6+'Consolidado '!E7+'Consolidado '!E11+'Consolidado '!E15))*'Consolidado '!F4/1000000 -> -154.56619 | F24: =SUM(C24:E24) -> -3278.4513 | G24: =MAX(0,-F24) -> 3278.4513 | H24: =MAX(0,-(('Informe Accionista'!F129/1000000)+D24)) -> 3208.7715 | I24: ='Modelo Base'!I179/1000000 -> -3773.5938 | J24: Abr: flujo histórico Colombia más caja internacional real disponible.
B25: May-26 | C25: =(Inputs!H155+(Inputs!H109-Inputs!G109)+(Inputs!H113-Inputs!G113)+(Inputs!H112-Inputs!G112)-(Inputs!H96-Inputs!G96)-(Inputs!H94-Inputs!G94)-(Inputs!H97-Inputs!G97))/1000000 -> -86.36183 | D25: =-(Inputs!H101-Inputs!G101)/1000000 -> -7.792981 | E25: =(SUM('Consolidado '!H6:J7)-SUM('Consolidado '!H9:J9,'Consolidado '!H11:J13,'Consolidado '!H15:J15))*'Consolidado '!K4/1000000 -> -105.79334 | F25: =SUM(C25:E25) -> -199.94815 | G25: =MAX(0,-F25) -> 199.94815 | H25: =MAX(0,-('Informe Accionista'!G129/1000000+D25)) -> 0 | I25: =(Inputs!H93-Inputs!G93)/1000000 -> -112.93482 | J25: May: flujo histórico Colombia más caja internacional real disponible.
B26: Jun-26 | C26: =(Inputs!I155+(Inputs!I109-Inputs!H109)+(Inputs!I113-Inputs!H113)+(Inputs!I112-Inputs!H112)-(Inputs!I96-Inputs!H96)-(Inputs!I94-Inputs!H94)-(Inputs!I97-Inputs!H97))/1000000 -> -112.21246 | D26: =-(Inputs!I101-Inputs!H101)/1000000 -> 0 | E26: =J47 -> -81.203976 | F26: =SUM(C26:E26) -> -193.41644 | G26: =MAX(0,-F26) -> 193.41644 | H26: =MAX(0,-(('Informe Accionista'!H129/1000000)+D26)) -> 0 | I26: =(Inputs!I93-Inputs!H93)/1000000+E26 -> -210.58496 | J26: Jun: Colombia más flujo bancario de USA, Perú y Costa Rica calculado solo con filas 1–16 del consolidado.
B27: Jul-26 | C27: =(Inputs!J155+(Inputs!J109-Inputs!I109)+(Inputs!J113-Inputs!I113)+(Inputs!J112-Inputs!I112)-(Inputs!J96-Inputs!I96)-(Inputs!J94-Inputs!I94)-(Inputs!J97-Inputs!I97))/1000000 -> 37.553515 | D27: =-(Inputs!J101-Inputs!I101)/1000000 -> 0 | E27: 0 | F27: =SUM(C27:E27) -> 37.553515 | G27: =MAX(0,-F27) -> 0 | I27: =(Inputs!J93-Inputs!I93)/1000000+E27 -> 58.825564 | J27: Jul: solo Colombia (estados financieros julio); flujo internacional de julio pendiente — Consolidado llega a junio.
B28: YTD Ene-Jul | C28: =SUM(C21:C27) -> -32.215191 | D28: =SUM(D21:D27) -> -3236.9981 | E28: =SUM(E21:E27) -> -341.56351 | F28: =SUM(F21:F27) -> -3610.7768 | G28: =SUM(G21:G27) -> 3945.8759 | H28: =SUM(H21:H27) -> 3231.9998 | I28: =SUM(I21:I27) -> -4002.5136 | J28: Acumulado Ene-Jun. FCF neto total incluye junio.
B29: Promedio 3M May-Jul | C29: =AVERAGE(C25:C27) -> -53.673592 | D29: =AVERAGE(D25:D27) -> -2.5976603 | E29: =AVERAGE(E25:E27) -> -62.332438 | F29: =AVERAGE(F25:F27) -> -118.60369 | G29: =AVERAGE(G25:G27) -> 131.12153 | H29: =AVERAGE(H25:H27) -> 0 | I29: =AVERAGE(I25:I27) -> -88.231404 | J29: Promedio 3M (Abr-Jun) usado para runway.
B31: Ingresos presupuesto vs ejecutado (USD MM y COP MM) — Ene a Jul 2026
B32: Mes | C32: Ppto USD MM | D32: Ejec. USD MM | E32: Gap USD MM | F32: Cumplimiento % | G32: Ppto COP MM | H32: Ejec. COP MM | I32: Gap COP MM
B33: Ene-26 | C33: 0.186 | D33: ='Informe Accionista'!C122/Inputs!$C$27/1000000 -> 0.16592079 | E33: =D33-C33 -> -0.020079214 | F33: =IF(C33=0,"N/A",D33/C33) -> 0.89204724 | G33: =C33*Inputs!$C$27 -> 686.34 | H33: ='Informe Accionista'!C122/1000000 -> 612.2477 | I33: =H33-G33 -> -74.092299
B34: Feb-26 | C34: 0.354 | D34: ='Informe Accionista'!D122/Inputs!$C$27/1000000 -> 0.20168513 | E34: =D34-C34 -> -0.15231487 | F34: =IF(C34=0,"N/A",D34/C34) -> 0.56973201 | G34: =C34*Inputs!$C$27 -> 1306.26 | H34: ='Informe Accionista'!D122/1000000 -> 744.21814 | I34: =H34-G34 -> -562.04186
B35: Mar-26 | C35: 0.396 | D35: ='Informe Accionista'!E122/Inputs!$C$27/1000000 -> 0.21329029 | E35: =D35-C35 -> -0.18270971 | F35: =IF(C35=0,"N/A",D35/C35) -> 0.53861185 | G35: =C35*Inputs!$C$27 -> 1461.24 | H35: ='Informe Accionista'!E122/1000000 -> 787.04119 | I35: =H35-G35 -> -674.19881
B36: Abr-26 | C36: 0.359 | D36: ='Informe Accionista'!F122/Inputs!$C$27/1000000 -> 0.20348717 | E36: =D36-C36 -> -0.15551283 | F36: =IF(C36=0,"N/A",D36/C36) -> 0.56681663 | G36: =C36*Inputs!$C$27 -> 1324.71 | H36: ='Informe Accionista'!F122/1000000 -> 750.86766 | I36: =H36-G36 -> -573.84234
B37: May-26 | C37: 0.403 | D37: ='Informe Accionista'!G122/Inputs!$C$27/1000000 -> 0.22398774 | E37: =D37-C37 -> -0.17901226 | F37: =IF(C37=0,"N/A",D37/C37) -> 0.55580083 | G37: =C37*Inputs!$C$27 -> 1487.07 | H37: ='Informe Accionista'!G122/1000000 -> 826.51475 | I37: =H37-G37 -> -660.55525
B38: Jun-26 | C38: ='Informe Accionista'!H65/1000000 -> 0.375559 | D38: ='Informe Accionista'!H122/Inputs!$C$27/1000000 -> 0.20364588 | E38: =D38-C38 -> -0.17191312 | F38: =IF(C38=0,"N/A",D38/C38) -> 0.54224738 | G38: =C38*Inputs!$C$27 -> 1385.8127 | H38: ='Informe Accionista'!H122/1000000 -> 751.45331 | I38: =H38-G38 -> -634.3594
B39: Jul-26 | C39: ='Informe Accionista'!I65/1000000 -> 0.388085 | D39: ='Modelo Base'!L51/Inputs!$C$27/1000000 -> 0.18425218 | E39: =D39-C39 -> -0.20383282 | F39: =IF(C39=0,"N/A",D39/C39) -> 0.47477275 | G39: =C39*Inputs!$C$27 -> 1432.0337 | H39: ='Modelo Base'!L51/1000000 -> 679.89055 | I39: =H39-G39 -> -752.1431
B40: Total Ene-Jul | C40: =SUM(C33:C39) -> 2.461644 | D40: =SUM(D33:D39) -> 1.3962692 | E40: =D40-C40 -> -1.0653748 | F40: =IF(C40=0,"N/A",D40/C40) -> 0.56721004 | G40: =SUM(G33:G39) -> 9083.4664 | H40: =SUM(H33:H39) -> 5152.2333 | I40: =H40-G40 -> -3931.2331
B42: Puente de caja Jun → Jul 2026 (COP MM) | F42: Flujo de caja internacional — Jun-26 (excluye Colombia)
B43: Concepto | C43: COP MM | D43: Comentario | F43: País | G43: Ingresos USD | H43: Egresos USD | I43: Flujo neto USD | J43: Flujo neto COP MM
B44: Caja inicial (jun-26) | C44: =Inputs!I93/1000000 -> 115.44136 | F44: USA | G44: =SUM('Consolidado '!M6:M7) -> 5664.45 | H44: =-SUM('Consolidado '!M9,'Consolidado '!M11:M13,'Consolidado '!M15) -> -27968.27 | I44: =SUM(G44:H44) -> -22303.82 | J44: =I44*$J$49/1000000 -> -78.180874
B45: (+) Utilidad neta de julio | C45: =Inputs!J155/1000000 -> 24.707052 | D45: Julio fue rentable | F45: Perú | G45: =SUM('Consolidado '!N6:N7) -> 1821.5125 | H45: =-SUM('Consolidado '!N9,'Consolidado '!N11:N13,'Consolidado '!N15) -> -11.967695 | I45: =SUM(G45:H45) -> 1809.5448 | J45: =I45*$J$49/1000000 -> 6.34294
B46: (−) Aumento de Clientes (CxC) | C46: =-(Inputs!J96-Inputs!I96)/1000000 -> 110.97319 | D46: Recuperación de cartera: cobros superaron la facturación a crédito | F46: Costa Rica | G46: =SUM('Consolidado '!O6:O7) -> 0 | H46: =-SUM('Consolidado '!O9,'Consolidado '!O11:O13,'Consolidado '!O15) -> -2671.99 | I46: =SUM(G46:H46) -> -2671.99 | J46: =I46*$J$49/1000000 -> -9.3660419
B47: (−) Aumento otros deudores/anticipos | C47: =-(Inputs!J97-Inputs!I97)/1000000 -> -31.840709 | F47: Total internacional | I47: =SUM(I44:I46) -> -23166.265 | J47: =SUM(J44:J46) -> -81.203976
...

Sheet Ppto Ene. 2026
A1: COCO TECNOLOGÍAS — P&L × 3 Escenarios 2026
C5: Inflación | H5: 0.051
C6: Tasa de Cambio | H6: 4000
B7: P&L 2026 — Monthly (Level 4) — Phase 1: Revenue lines (COP & USD)
U9: Total 2026
A10: PUC | B10: Account | E10: Currency | G10: 2026-01 | H10: 2026-02 | I10: 2026-03 | J10: 2026-04 | K10: 2026-05 | L10: 2026-06 | M10: 2026-07 | N10: 2026-08 | O10: 2026-09 | P10: 2026-10 | Q10: 2026-11 | R10: 2026-12
U11: =SUM(G12:R12) -> 1.8222904e+10
A12: 4170 | B12: Otras actividades de servicios comunitarios, sociales y personales | E12: COP | G12: 7.4492961e+08 | H12: 1.4172832e+09 | I12: 1.5849544e+09 | J12: 1.436763e+09 | K12: 1.6123205e+09 | L12: 1.5022355e+09 | M12: 1.5523381e+09 | N12: 1.5343577e+09 | O12: 1.6970537e+09 | P12: 1.6798161e+09 | Q12: 1.692867e+09 | R12: 1.7679851e+09
U13: =SUM(G14:R14) -> 4555726
A14: 4170 | B14: Otras actividades de servicios comunitarios, sociales y personales | E14: USD | G14: 186232.4 | H14: 354320.8 | I14: 396238.6 | J14: 359190.75 | K14: 403080.12 | L14: 375558.87 | M14: 388084.53 | N14: 383589.42 | O14: 424263.43 | P14: 419954.03 | Q14: 423216.76 | R14: 441996.28
F16: Ponderador Mensual
D17: Cifra 2025 | E17: Cifra 2026 | F17: =1/12 -> 0.083333333
F19: =G10 -> 2026-01 | G19: =H10 -> 2026-02 | H19: =I10 -> 2026-03 | I19: =J10 -> 2026-04 | J19: =K10 -> 2026-05 | K19: =L10 -> 2026-06 | L19: =M10 -> 2026-07 | M19: =N10 -> 2026-08 | ... Q19: =R10 -> 2026-12 | S19: =U9 -> Total 2026
A20: Moneda COP
A22: Ingresos Operacionales | F22: =G12 -> 7.4492961e+08 | G22: =H12 -> 1.4172832e+09 | H22: =I12 -> 1.5849544e+09 | I22: =J12 -> 1.436763e+09 | J22: =K12 -> 1.6123205e+09 | K22: =L12 -> 1.5022355e+09 | L22: =M12 -> 1.5523381e+09 | M22: =N12 -> 1.5343577e+09 | ... Q22: =R12 -> 1.7679851e+09 | S22: =SUM(F22:Q22) -> 1.8222904e+10
D24: %
A25: Costo de Ventas | B25: 5.0860033e+09 | C25: =B25*(1+$H$5) -> 5.3453895e+09 | F25: =$C25*$F$17 -> 4.4544912e+08 | G25: =$C25*$F$17 -> 4.4544912e+08 | H25: =$C25*$F$17 -> 4.4544912e+08 | I25: =$C25*$F$17 -> 4.4544912e+08 | J25: =$C25*$F$17 -> 4.4544912e+08 | K25: =$C25*$F$17 -> 4.4544912e+08 | L25: =$C25*$F$17 -> 4.4544912e+08 | M25: =$C25*$F$17 -> 4.4544912e+08 | ... Q25: =$C25*$F$17 -> 4.4544912e+08 | S25: =SUM(F25:Q25) -> 5.3453895e+09
A26: Mano de Obra Directa | B26: 3.096729e+09 | C26: =B26*(1+$H$5) -> 3.2546622e+09 | F26: =$C26*$F$17 -> 2.7122185e+08 | G26: =$C26*$F$17 -> 2.7122185e+08 | H26: =$C26*$F$17 -> 2.7122185e+08 | I26: =$C26*$F$17 -> 2.7122185e+08 | J26: =$C26*$F$17 -> 2.7122185e+08 | K26: =$C26*$F$17 -> 2.7122185e+08 | L26: =$C26*$F$17 -> 2.7122185e+08 | M26: =$C26*$F$17 -> 2.7122185e+08 | ... Q26: =$C26*$F$17 -> 2.7122185e+08 | S26: =SUM(F26:Q26) -> 3.2546622e+09
A27: Operacionales de Desarrollo | B27: 1.9892743e+09 | C27: =B27*(1+$H$5) -> 2.0907273e+09 | F27: =$C27*$F$17 -> 1.7422727e+08 | G27: =$C27*$F$17 -> 1.7422727e+08 | H27: =$C27*$F$17 -> 1.7422727e+08 | I27: =$C27*$F$17 -> 1.7422727e+08 | J27: =$C27*$F$17 -> 1.7422727e+08 | K27: =$C27*$F$17 -> 1.7422727e+08 | L27: =$C27*$F$17 -> 1.7422727e+08 | M27: =$C27*$F$17 -> 1.7422727e+08 | ... Q27: =$C27*$F$17 -> 1.7422727e+08 | S27: =SUM(F27:Q27) -> 2.0907273e+09
A29: Utilidad Bruta | F29: =F22-F26-F27 -> 2.9948049e+08 | G29: =G22-G26-G27 -> 9.7183409e+08 | H29: =H22-H26-H27 -> 1.1395053e+09 | I29: =I22-I26-I27 -> 9.9131388e+08 | J29: =J22-J26-J27 -> 1.1668714e+09 | K29: =K22-K26-K27 -> 1.0567864e+09 | L29: =L22-L26-L27 -> 1.106889e+09 | M29: =M22-M26-M27 -> 1.0889086e+09 | ... Q29: =Q22-Q26-Q27 -> 1.322536e+09 | S29: =SUM(F29:Q29) -> 1.2877515e+10
A32: Operacionales de Administración | B32: 1.5320319e+09 | C32: =B32*(1+$H$5) -> 1.6101656e+09 | F32: =$C32*$F$17 -> 1.3418046e+08 | G32: =$C32*$F$17 -> 1.3418046e+08 | H32: =$C32*$F$17 -> 1.3418046e+08 | I32: =$C32*$F$17 -> 1.3418046e+08 | J32: =$C32*$F$17 -> 1.3418046e+08 | K32: =$C32*$F$17 -> 1.3418046e+08 | L32: =$C32*$F$17 -> 1.3418046e+08 | M32: =$C32*$F$17 -> 1.3418046e+08 | ... Q32: =$C32*$F$17 -> 1.3418046e+08 | S32: =SUM(F32:Q32) -> 1.6101656e+09
A33: Gastos de Personal | B33: 705937048 | C33: =B33*(1+$H$5) -> 7.4193984e+08 | D33: 0.46 | F33: =$C33*$F$17 -> 61828320 | G33: =$C33*$F$17 -> 61828320 | H33: =$C33*$F$17 -> 61828320 | I33: =$C33*$F$17 -> 61828320 | J33: =$C33*$F$17 -> 61828320 | K33: =$C33*$F$17 -> 61828320 | L33: =$C33*$F$17 -> 61828320 | M33: =$C33*$F$17 -> 61828320 | ... Q33: =$C33*$F$17 -> 61828320 | S33: =SUM(F33:Q33) -> 7.4193984e+08
A34: Otros Gastos de Administración Operacionales | B34: 8.2609489e+08 | C34: =B34*(1+$H$5) -> 8.6822573e+08 | F34: =$C34*$F$17 -> 72352144 | G34: =$C34*$F$17 -> 72352144 | H34: =$C34*$F$17 -> 72352144 | I34: =$C34*$F$17 -> 72352144 | J34: =$C34*$F$17 -> 72352144 | K34: =$C34*$F$17 -> 72352144 | L34: =$C34*$F$17 -> 72352144 | M34: =$C34*$F$17 -> 72352144 | ... Q34: =$C34*$F$17 -> 72352144 | S34: =SUM(F34:Q34) -> 8.6822573e+08
S35: =SUM(F35:Q35) -> 0
S36: =SUM(F36:Q36) -> 0
A37: Operacionales de Ventas | B37: 2.4666933e+09 | C37: =B37*(1+$H$5) -> 2.5924947e+09 | F37: =$C37*$F$17 -> 2.1604123e+08 | G37: =$C37*$F$17 -> 2.1604123e+08 | H37: =$C37*$F$17 -> 2.1604123e+08 | I37: =$C37*$F$17 -> 2.1604123e+08 | J37: =$C37*$F$17 -> 2.1604123e+08 | K37: =$C37*$F$17 -> 2.1604123e+08 | L37: =$C37*$F$17 -> 2.1604123e+08 | M37: =$C37*$F$17 -> 2.1604123e+08 | ... Q37: =$C37*$F$17 -> 2.1604123e+08 | S37: =SUM(F37:Q37) -> 2.5924947e+09
A38: Gastos de Personal | B38: 1099685429 | C38: =B38*(1+$H$5) -> 1.1557694e+09 | F38: =$C38*$F$17 -> 96314115 | G38: =$C38*$F$17 -> 96314115 | H38: =$C38*$F$17 -> 96314115 | I38: =$C38*$F$17 -> 96314115 | J38: =$C38*$F$17 -> 96314115 | K38: =$C38*$F$17 -> 96314115 | L38: =$C38*$F$17 -> 96314115 | M38: =$C38*$F$17 -> 96314115 | ... Q38: =$C38*$F$17 -> 96314115 | S38: =SUM(F38:Q38) -> 1.1557694e+09
A39: Honorarios | B39: 4.6489068e+08 | C39: =B39*(1+$H$5) -> 4.8860011e+08 | F39: =$C39*$F$17 -> 40716675 | G39: =$C39*$F$17 -> 40716675 | H39: =$C39*$F$17 -> 40716675 | I39: =$C39*$F$17 -> 40716675 | J39: =$C39*$F$17 -> 40716675 | K39: =$C39*$F$17 -> 40716675 | L39: =$C39*$F$17 -> 40716675 | M39: =$C39*$F$17 -> 40716675 | ... Q39: =$C39*$F$17 -> 40716675 | S39: =SUM(F39:Q39) -> 4.8860011e+08
A40: Otros Gastos de Ventas Operacionales | B40: 9.0211724e+08 | C40: =B40*(1+$H$5) -> 9.4812522e+08 | F40: =$C40*$F$17 -> 79010435 | G40: =$C40*$F$17 -> 79010435 | H40: =$C40*$F$17 -> 79010435 | I40: =$C40*$F$17 -> 79010435 | J40: =$C40*$F$17 -> 79010435 | K40: =$C40*$F$17 -> 79010435 | L40: =$C40*$F$17 -> 79010435 | M40: =$C40*$F$17 -> 79010435 | ... Q40: =$C40*$F$17 -> 79010435 | S40: =SUM(F40:Q40) -> 9.4812522e+08
S41: =SUM(F41:Q41) -> 0
A42: Utilidad Operacional | F42: =F29-F32-F37 -> -50741202 | G42: =G29-G32-G37 -> 6.2161241e+08 | H42: =H29-H32-H37 -> 7.8928359e+08 | I42: =I29-I32-I37 -> 6.4109219e+08 | J42: =J29-J32-J37 -> 8.1664966e+08 | K42: =K29-K32-K37 -> 7.0656469e+08 | L42: =L29-L32-L37 -> 7.566673e+08 | M42: =M29-M32-M37 -> 7.3868689e+08 | ... Q42: =Q29-Q32-Q37 -> 9.7231431e+08 | S42: =SUM(F42:Q42) -> 8.6748543e+09
S43: =SUM(F43:Q43) -> 0
A44: Ingresos no Operacionales | B44: 36272911 | C44: =B44*(1+$H$5) -> 38122829 | F44: =$C44*$F$17 -> 3176902.4 | G44: =$C44*$F$17 -> 3176902.4 | H44: =$C44*$F$17 -> 3176902.4 | I44: =$C44*$F$17 -> 3176902.4 | J44: =$C44*$F$17 -> 3176902.4 | K44: =$C44*$F$17 -> 3176902.4 | L44: =$C44*$F$17 -> 3176902.4 | M44: =$C44*$F$17 -> 3176902.4 | ... Q44: =$C44*$F$17 -> 3176902.4 | S44: =SUM(F44:Q44) -> 38122829
A45: Gastos no Operacionales | B45: 92043202 | C45: =B45*(1+$H$5) -> 96737405 | F45: =$C45*$F$17 -> 8061450.4 | G45: =$C45*$F$17 -> 8061450.4 | H45: =$C45*$F$17 -> 8061450.4 | I45: =$C45*$F$17 -> 8061450.4 | J45: =$C45*$F$17 -> 8061450.4 | K45: =$C45*$F$17 -> 8061450.4 | L45: =$C45*$F$17 -> 8061450.4 | M45: =$C45*$F$17 -> 8061450.4 | ... Q45: =$C45*$F$17 -> 8061450.4 | S45: =SUM(F45:Q45) -> 96737405
A47: Utilidad Antes de Impuestos | F47: =F42+F44-F45 -> -55625750 | G47: =G42+G44-G45 -> 6.1672786e+08 | H47: =H42+H44-H45 -> 7.8439904e+08 | I47: =I42+I44-I45 -> 6.3620764e+08 | J47: =J42+J44-J45 -> 8.1176512e+08 | K47: =K42+K44-K45 -> 7.0168014e+08 | L47: =L42+L44-L45 -> 7.5178275e+08 | M47: =M42+M44-M45 -> 7.3380234e+08 | ... Q47: =Q42+Q44-Q45 -> 9.6742977e+08 | S47: =SUM(F47:Q47) -> 8.6162397e+09
A49: Impuestos | F49: =IF(F47>0,F47*35%,0) -> 0 | G49: =IF(G47>0,G47*35%,0) -> 2.1585475e+08 | H49: =IF(H47>0,H47*35%,0) -> 2.7453966e+08 | I49: =IF(I47>0,I47*35%,0) -> 2.2267268e+08 | J49: =IF(J47>0,J47*35%,0) -> 2.8411779e+08 | K49: =IF(K47>0,K47*35%,0) -> 2.4558805e+08 | L49: =IF(L47>0,L47*35%,0) -> 2.6312396e+08 | M49: =IF(M47>0,M47*35%,0) -> 2.5683082e+08 | ... Q49: =IF(Q47>0,Q47*35%,0) -> 3.3860042e+08 | S49: =SUM(F49:Q49) -> 3.0351529e+09
S50: =SUM(F50:Q50) -> 0
A51: Utilidad Neta | F51: =F47-F49 -> -55625750 | G51: =G47-G49 -> 4.0087311e+08 | H51: =H47-H49 -> 5.0985938e+08 | I51: =I47-I49 -> 4.1353497e+08 | J51: =J47-J49 -> 5.2764733e+08 | K51: =K47-K49 -> 4.5609209e+08 | L51: =L47-L49 -> 4.8865879e+08 | M51: =M47-M49 -> 4.7697152e+08 | ... Q51: =Q47-Q49 -> 6.2882935e+08 | S51: =SUM(F51:Q51) -> 5.5810868e+09
S52: =SUM(F52:Q52) -> 0
AB56: Objetivo de Ingresos | AC56: 1
...

Sheet Revenue
B3: Plan Comercial 2026 (USD) + Puente de MRR
B4: Legacy drivers (not used after target alignment)
B5: Stream | C5: Annual Target (USD) | D5: 2026-01 | E5: 2026-02 | F5: 2026-03 | G5: 2026-04 | H5: 2026-05 | I5: 2026-06 | J5: 2026-07 | K5: 2026-08 | L5: 2026-09 | M5: 2026-10 | N5: 2026-11 | O5: 2026-12 | P5: Total 2026
B6: MRR | C6: =Inputs!$H$5*(Inputs!C58/SUM(Inputs!$C$58:$C$61)) -> 1257936.3 | D6: =$C6*Inputs!D$31 -> 79848.386 | E6: =$C6*Inputs!E$31 -> 86653.102 | F6: =$C6*Inputs!F$31 -> 106779.87 | G6: =$C6*Inputs!G$31 -> 88804.185 | H6: =$C6*Inputs!H$31 -> 110006.49 | I6: =$C6*Inputs!I$31 -> 96642.16 | J6: =$C6*Inputs!J$31 -> 102662.68 | K6: =$C6*Inputs!K$31 -> 100444.21 | L6: =$C6*Inputs!N$31 -> 120090.02 | M6: =$C6*Inputs!O$31 -> 117961.4 | N6: =$C6*Inputs!P$31 -> 119498.08 | O6: =$C6*Inputs!Q$31 -> 128545.71 | P6: =SUM(D6:O6) -> 1257936.3
B7: Upsell / Cross-sell (expansion) | C7: =Inputs!$H$5*(Inputs!C59/SUM(Inputs!$C$58:$C$61)) -> 262373.56 | D7: =$C7*Inputs!D$31 -> 16654.345 | E7: =$C7*Inputs!E$31 -> 18073.636 | F7: =$C7*Inputs!F$31 -> 22271.568 | G7: =$C7*Inputs!G$31 -> 18522.297 | H7: =$C7*Inputs!H$31 -> 22944.56 | I7: =$C7*Inputs!I$31 -> 20157.1 | J7: =$C7*Inputs!J$31 -> 21412.828 | K7: =$C7*Inputs!K$31 -> 20950.111 | L7: =$C7*Inputs!N$31 -> 25047.728 | M7: =$C7*Inputs!O$31 -> 24603.752 | N7: =$C7*Inputs!P$31 -> 24924.264 | O7: =$C7*Inputs!Q$31 -> 26811.369 | P7: =SUM(D7:O7) -> 262373.56
B8: New Business LATAM | C8: =Inputs!$H$5*(Inputs!C60/SUM(Inputs!$C$58:$C$61)) -> 787120.74 | D8: =$C8*Inputs!D$31 -> 49963.04 | E8: =$C8*Inputs!E$31 -> 54220.913 | F8: =$C8*Inputs!F$31 -> 66814.709 | G8: =$C8*Inputs!G$31 -> 55566.897 | H8: =$C8*Inputs!H$31 -> 68833.685 | I8: =$C8*Inputs!I$31 -> 60471.305 | J8: =$C8*Inputs!J$31 -> 64238.489 | K8: =$C8*Inputs!K$31 -> 62850.34 | L8: =$C8*Inputs!N$31 -> 75143.191 | M8: =$C8*Inputs!O$31 -> 73811.263 | N8: =$C8*Inputs!P$31 -> 74772.798 | O8: =$C8*Inputs!Q$31 -> 80434.115 | P8: =SUM(D8:O8) -> 787120.74
B9: New Business Gobierno y Enterprise | C9: =Inputs!$H$5*(Inputs!C61/SUM(Inputs!$C$58:$C$61)) -> 728569.41 | D9: =$C9*Inputs!D$31 -> 46246.453 | E9: =$C9*Inputs!E$31 -> 50187.596 | F9: =$C9*Inputs!F$31 -> 61844.581 | G9: =$C9*Inputs!G$31 -> 51433.457 | H9: =$C9*Inputs!H$31 -> 63713.372 | I9: =$C9*Inputs!I$31 -> 55973.042 | J9: =$C9*Inputs!J$31 -> 59459.998 | K9: =$C9*Inputs!K$31 -> 58175.109 | L9: =$C9*Inputs!N$31 -> 69553.535 | M9: =$C9*Inputs!O$31 -> 68320.684 | N9: =$C9*Inputs!P$31 -> 69210.694 | O9: =$C9*Inputs!Q$31 -> 74450.885 | P9: =SUM(D9:O9) -> 728569.41
B10: One-off (Implementation) | C10: =Inputs!$C$13*Inputs!$C$19 -> 171600 | D10: =$C10*Inputs!D$31 -> 10892.43 | E10: =$C10*Inputs!E$31 -> 11820.688 | F10: =$C10*Inputs!F$31 -> 14566.258 | G10: =$C10*Inputs!G$31 -> 12114.125 | H10: =$C10*Inputs!H$31 -> 15006.415 | I10: =$C10*Inputs!I$31 -> 13183.334 | J10: =$C10*Inputs!J$31 -> 14004.617 | K10: =$C10*Inputs!K$31 -> 13701.987 | L10: =$C10*Inputs!N$31 -> 16381.949 | M10: =$C10*Inputs!O$31 -> 16091.575 | N10: =$C10*Inputs!P$31 -> 16301.199 | O10: =$C10*Inputs!Q$31 -> 17535.422 | P10: =SUM(D10:O10) -> 171600
B11: One-off (Interoperability) | C11: =Inputs!$C$13*Inputs!$C$20 -> 92400 | D11: =$C11*Inputs!D$31 -> 5865.1546 | E11: =$C11*Inputs!E$31 -> 6364.9858 | F11: =$C11*Inputs!F$31 -> 7843.3699 | G11: =$C11*Inputs!G$31 -> 6522.9906 | H11: =$C11*Inputs!H$31 -> 8080.3772 | I11: =$C11*Inputs!I$31 -> 7098.7185 | J11: =$C11*Inputs!J$31 -> 7540.9477 | K11: =$C11*Inputs!K$31 -> 7377.9931 | L11: =$C11*Inputs!N$31 -> 8821.0493 | M11: =$C11*Inputs!O$31 -> 8664.6943 | N11: =$C11*Inputs!P$31 -> 8777.5688 | O11: =$C11*Inputs!Q$31 -> 9442.1502 | P11: =SUM(D11:O11) -> 92400
B12: TOTAL | C12: =SUM(C6:C11) -> 3300000 | D12: =SUM(D6:D11) -> 209469.81 | E12: =SUM(E6:E11) -> 227320.92 | F12: =SUM(F6:F11) -> 280120.35 | G12: =SUM(G6:G11) -> 232963.95 | H12: =SUM(H6:H11) -> 288584.9 | I12: =SUM(I6:I11) -> 253525.66 | J12: =SUM(J6:J11) -> 269319.56 | ... P12: =SUM(P6:P11) -> 3300000
B15: MRR BRIDGE 2026 (USD)
B17: Metric | C17: 2026-01 | D17: 2026-02 | E17: 2026-03 | F17: 2026-04 | G17: 2026-05 | H17: 2026-06 | I17: 2026-07 | J17: 2026-08 | K17: 2026-09 | L17: 2026-10 | M17: 2026-11 | N17: 2026-12 | O17: Total/End
B18: Starting MRR (USD) | C18: =Inputs!$H$6 -> 190988.06 | D18: =C21 -> 382745.34 | E18: =D21 -> 589966.86 | F18: =E21 -> 844727.75 | G18: =F21 -> 1054831 | H18: =G21 -> 1315054.9 | I18: =H21 -> 1541723.2 | J18: =I21 -> 1781788.6 | K18: =J21 -> 2015299.4 | ... O18: =N21 -> 3139866.5
B19: New MRR (from SalesPlan) (USD) | C19: =D6+D7+D8+D9 -> 192712.22 | D19: =E6+E7+E8+E9 -> 209135.25 | E19: =F6+F7+F8+F9 -> 257710.72 | F19: =G6+G7+G8+G9 -> 214326.84 | G19: =H6+H7+H8+H9 -> 265498.11 | H19: =I6+I7+I8+I9 -> 233243.61 | I19: =J6+J7+J8+J9 -> 247774 | J19: =K6+K7+K8+K9 -> 242419.77 | ... N19: =O6+O7+O8+O9 -> 310242.08 | O19: =SUM(C19:N19) -> 3036000
B20: Churned MRR (USD) | C20: =-C18*Inputs!$C$9 -> -954.94031 | D20: =-D18*Inputs!$C$9 -> -1913.7267 | E20: =-E18*Inputs!$C$9 -> -2949.8343 | F20: =-F18*Inputs!$C$9 -> -4223.6388 | G20: =-G18*Inputs!$C$9 -> -5274.1548 | H20: =-H18*Inputs!$C$9 -> -6575.2745 | I20: =-I18*Inputs!$C$9 -> -7708.6162 | J20: =-J18*Inputs!$C$9 -> -8908.9431 | ... O20: =-O18*Inputs!$C$9 -> -15699.333
B21: Ending MRR (USD) | C21: =C18+C19+C20 -> 382745.34 | D21: =D18+D19+D20 -> 589966.86 | E21: =E18+E19+E20 -> 844727.75 | F21: =F18+F19+F20 -> 1054831 | G21: =G18+G19+G20 -> 1315054.9 | H21: =H18+H19+H20 -> 1541723.2 | I21: =I18+I19+I20 -> 1781788.6 | J21: =J18+J19+J20 -> 2015299.4 | ... N21: =N18+N19+N20 -> 3139866.5 | O21: =N21 -> 3139866.5
B23: MRR Promedio mes (USD) | C23: =AVERAGE(C18,C21) -> 286866.7 | D23: =AVERAGE(D18,D21) -> 486356.1 | E23: =AVERAGE(E18,E21) -> 717347.31 | F23: =AVERAGE(F18,F21) -> 949779.35 | G23: =AVERAGE(G18,G21) -> 1184942.9 | H23: =AVERAGE(H18,H21) -> 1428389.1 | I23: =AVERAGE(I18,I21) -> 1661755.9 | J23: =AVERAGE(J18,J21) -> 1898544 | ... O23: =AVERAGE(O18,O21) -> 3139866.5
B25: CHECKS & KPIs (sanity check rápido)
B27: Check | C27: Valor | D27: Status
B28: Target total (recurrente + one-off) (USD) | C28: =Inputs!$C$12 -> 3300000
B29: Total plan comercial (USD) | C29: =P12 -> 3300000
B30: Brecha (USD) | C30: =C29-C28 -> 0 | D30: =IF(ABS(C30)<1000,"OK","GAP") -> OK
B32: MRR final dic-2026 (USD) | C32: =N21 -> 3139866.5
B33: Target run-rate mensual (USD) | C33: =Inputs!$C$15 -> 3036000
B34: Brecha vs target (USD) | C34: =C32-C33 -> 103866.53 | D34: =IF(C34>0,"ABOVE","BELOW") -> ABOVE
B36: Devoluciones implícitas (% bruto, ref) | C36: =Inputs!C21 -> 0.112 | D36: Referencia — modelo usa revenue neto
B38: Ingresos brutos implicitos (USD) | C38: =P12/(1-Inputs!C21) -> 3716216.2
B39: Devoluciones implicitas (USD) | C39: =C38-P12 -> 416216.22
B40: Devoluciones implicitas (COP) | C40: =C39*Inputs!C6 -> 1.5358378e+09
B43: PROYECCIÓN DE INGRESOS 2026 — 3 ESCENARIOS (COP)
B44: Cifras en pesos colombianos (COP). TRM utilizada: INPUTS!B5. Distribución mensual: pesos de estacionalidad INPUTS!C30:N30.
B46: ESCENARIO CONSERVADOR (COP) | C46: Total Anual | D46: Ene | E46: Feb | F46: Mar | G46: Abr | H46: May | I46: Jun | J46: Jul | K46: Ago | L46: Sep | M46: Oct | N46: Nov | O46: Dic | P46: % del total
B47: Ingresos (COP) | C47: =Inputs!$N$7*Inputs!$C$6 -> 8856000000 | D47: =C47*Inputs!D$31 -> 5.6214079e+08 | E47: =C47*Inputs!E$31 -> 6.1004669e+08 | F47: =C47*Inputs!F$31 -> 7.5174116e+08 | G47: =C47*Inputs!G$31 -> 6.2519053e+08 | H47: =C47*Inputs!H$31 -> 7.7445693e+08 | I47: =C47*Inputs!I$31 -> 6.8037068e+08 | J47: =C47*Inputs!J$31 -> 7.2275577e+08 | K47: =C47*Inputs!K$31 -> 7.0713752e+08 | L47: =C47*Inputs!N$31 -> 8.4544602e+08 | M47: =C47*Inputs!O$31 -> 8.3046032e+08 | N47: =C47*Inputs!P$31 -> 8.4127868e+08 | O47: =C47*Inputs!Q$31 -> 9.0497491e+08 | P47: =SUM(D47:O47)/C47 -> 1
B48: Check suma meses | C48: =SUM(D47:O47) -> 8856000000 | D48: =IF(ABS(C47-C48)<1,"OK","ERROR") -> OK
B51: ESCENARIO BASE (COP) | C51: Total Anual | D51: Ene | E51: Feb | F51: Mar | G51: Abr | H51: May | I51: Jun | J51: Jul | K51: Ago | L51: Sep | M51: Oct | N51: Nov | O51: Dic | P51: % del total
B52: Ingresos (COP) | C52: =Inputs!$N$8*Inputs!$C$6 -> 12177000000 | D52: =C52*Inputs!D$31 -> 7.7294359e+08 | E52: =C52*Inputs!E$31 -> 8.388142e+08 | F52: =C52*Inputs!F$31 -> 1.0336441e+09 | G52: =C52*Inputs!G$31 -> 8.5963698e+08 | H52: =C52*Inputs!H$31 -> 1.0648783e+09 | I52: =C52*Inputs!I$31 -> 9.3550969e+08 | J52: =C52*Inputs!J$31 -> 9.9378918e+08 | K52: =C52*Inputs!K$31 -> 9.7231409e+08 | L52: =C52*Inputs!N$31 -> 1.1624883e+09 | M52: =C52*Inputs!O$31 -> 1.1418829e+09 | N52: =C52*Inputs!P$31 -> 1.1567582e+09 | O52: =C52*Inputs!Q$31 -> 1.2443405e+09 | P52: =SUM(D52:O52)/C52 -> 1
B53: Check suma meses | C53: =SUM(D52:O52) -> 12177000000 | D53: =IF(ABS(C52-C53)<1,"OK","ERROR") -> OK
B56: ESCENARIO OPTIMISTA (COP) | C56: Total Anual | D56: Ene | E56: Feb | F56: Mar | G56: Abr | H56: May | I56: Jun | J56: Jul | K56: Ago | L56: Sep | M56: Oct | N56: Nov | O56: Dic | P56: % del total
B57: Ingresos (COP) | C57: =Inputs!$N$9*Inputs!$C$6 -> 16605000000 | D57: =C57*Inputs!D$31 -> 1.054014e+09 | E57: =C57*Inputs!E$31 -> 1.1438375e+09 | F57: =C57*Inputs!F$31 -> 1.4095147e+09 | G57: =C57*Inputs!G$31 -> 1.1722322e+09 | H57: =C57*Inputs!H$31 -> 1.4521067e+09 | I57: =C57*Inputs!I$31 -> 1.275695e+09 | J57: =C57*Inputs!J$31 -> 1.3551671e+09 | K57: =C57*Inputs!K$31 -> 1.3258828e+09 | L57: =C57*Inputs!N$31 -> 1.5852113e+09 | M57: =C57*Inputs!O$31 -> 1.5571131e+09 | N57: =C57*Inputs!P$31 -> 1.5773975e+09 | O57: =C57*Inputs!Q$31 -> 1.696828e+09 | P57: =SUM(D57:O57)/C57 -> 1
B58: Check suma meses | C58: =SUM(D57:O57) -> 1.6605e+10 | D58: =IF(ABS(C57-C58)<1,"OK","ERROR") -> OK
...

Sheet Inputs
B2: INPUTS — CocoTech 2026 Budget Model (All Assumptions Consolidated) | Q2: temp
E4: Calculado | K4: Escenarios target 2026 (USD)
E5: ARR target (USD) = Total - One-off | H5: =C15 -> 3036000 | K5: Escenario | N5: Total target (USD) | O5: One-off (USD) | P5: Recurrente implícito (USD) | Q5: Run-rate mensual (USD)
B6: FX rate (COP per USD) | C6: 3690 | D6: TrmLargoPlazo | E6: Calculado / Referencia | H6: =(C7*(1+C11))/C6 -> 190988.06
B7: MRR Dec-2025 (COP) | C7: 670548000 | D7: MrrDic25 | E7: Referencia: Ene-2026 neto real (COP) | H7: 612247701 | K7: Conservador | N7: 2400000 | O7: =N7*$C$14 -> 192000 | P7: =N7-O7 -> 2208000 | Q7: =P7/12 -> 184000
B8: Customers Dec-2025 (count) | C8: 90 | D8: ClientesDic25 | K8: Base | N8: 3300000 | O8: =N8*$C$14 -> 264000 | P8: =N8-O8 -> 3036000 | Q8: =P8/12 -> 253000
B9: Monthly churn rate (revenue) | C9: 0.005 | D9: ChurnMensual | K9: Optimista | N9: 4500000 | O9: =N9*$C$14 -> 360000 | P9: =N9-O9 -> 4140000 | Q9: =P9/12 -> 345000
B10: Monthly churn rate (revenue) | C10: 0.005 | D10: ChurnMensual
B11: Annual price increase applied in Jan | C11: 0.051 | D11: InflacionAnual | K11: Escenario activo | N11: Base
B12: 2026 Total target (ARR + One-off) (USD) | C12: =INDEX($N$7:$N$9,MATCH($N$11,$K$7:$K$9,0)) -> 3300000 | D12: TargetTotal26
B13: Otros ingresos / One-off anual (USD) | C13: =C12*C14 -> 264000 | D13: OtrosIngresos | K13: Ingreso Meta 2026 por Hoja | N13: Total (USD) | O13: One-off (USD) | P13: Recurrente (USD) | Q13: Run-rate mensual
B14: Procentaje de Otros Ingresos | C14: 0.08 | D14: PctOtrosIng | K14: Conservador | N14: =N7 -> 2400000 | O14: =O7 -> 192000 | P14: =P7 -> 2208000 | Q14: =Q7 -> 184000
B15: Target recurrente anual (USD) | C15: =C12-C13 -> 3036000 | D15: TargetRecurrente | K15: Base | N15: =N8 -> 3300000 | O15: =O8 -> 264000 | P15: =P8 -> 3036000 | Q15: =Q8 -> 253000
B16: Check: Total = Recurrente + One-off | C16: =IF(ABS(C12-C15-C13)<1,"OK","ERROR") -> OK | D16: CheckTotal | K16: Optimista | N16: =N9 -> 4500000 | O16: =O9 -> 360000 | P16: =P9 -> 4140000 | Q16: =Q9 -> 345000
B17: Check: Target anual = Ingresos proyectados | C17: =IF(ABS(C12-SUM(D36:Q36))<100,"OK","ERROR") -> ERROR | D17: CheckIngresos
B18: NRR target | C18: 1.09 | D18: NrrTarget
B19: One-off split: % Implementation | C19: 0.65 | D19: PctImplement
B20: One-off split: % Interoperability | C20: =1-C19 -> 0.35 | D20: PctInterop
B21: Devoluciones (% de ingresos brutos) | C21: 0.112 | D21: PctDevoluciones
B22: FX & Tax Assumptions
B23: FX Low scenario (COP/USD) | C23: 3600 | D23: TrmBajo
B24: FX High scenario (COP/USD) | C24: 4400 | D24: TrmAlto
B25: Tax rate (statutory) | C25: 0.35 | D25: TasaImpuesto
B26: Caja Subsidiaria (USD) | C26: 325080 | D26: CajaSubsidiaria
B27: TRM Subsidiaria (COP/USD) | C27: 3690 | D27: TrmSubsidiaria
B28: Tasa de interés deuda LP (anual) | C28: 0.1 | D28: TasaDeudaLp
B29: Tasa de interés deuda CP (anual) | C29: 0.12 | D29: TasaDeudaCp | E29: Feb | F29: Mar | G29: Abr | H29: May | I29: Jun | J29: Jul | K29: Ago | N29: Sep | O29: Oct | P29: Nov | Q29: Dic | R29: TOTAL
B30: 2025 Monthly Revenue (COP) | C30: COP | D30: 483452000 | E30: 524652000 | F30: 646512000 | G30: 537676000 | H30: 666048000 | I30: 585132000 | J30: 621584000 | K30: 608152000 | N30: 727100000 | O30: 714212000 | P30: 723516000 | Q30: 778296000 | R30: 7616332000
B31: Weights (sum to 1.0) | D31: =D30/SUM($D$30:$Q$30) -> 0.063475699 | E31: =E30/SUM($D$30:$Q$30) -> 0.068885127 | F31: =F30/SUM($D$30:$Q$30) -> 0.084884955 | G31: =G30/SUM($D$30:$Q$30) -> 0.070595137 | H31: =H30/SUM($D$30:$Q$30) -> 0.087449969 | I31: =I30/SUM($D$30:$Q$30) -> 0.076825958 | J31: =J30/SUM($D$30:$Q$30) -> 0.081611989 | K31: =K30/SUM($D$30:$Q$30) -> 0.07984841 | N31: =N30/SUM($D$30:$Q$30) -> 0.095465901 | O31: =O30/SUM($D$30:$Q$30) -> 0.093773748 | P31: =P30/SUM($D$30:$Q$30) -> 0.094995334 | Q31: =Q30/SUM($D$30:$Q$30) -> 0.10218777 | R31: =SUM(D31:Q31) -> 1
B32: Index | C32: x | D32: 0.76170839 | E32: 0.82662153 | F32: 1.0186195 | G32: 0.84718762 | H32: 1.0493891 | I32: 0.92190076 | J32: 0.97934386 | K32: 0.95818092 | N32: 1.1459108 | O32: 1.1251173 | P32: 1.1397767 | Q32: 1.226505 | R32: 12
B33: Check: sum weights = 1 | C33: =SUM(D31:Q31) -> 1 | R33: 1
C34: 0 | R34: 0
B35: MRR PLAN (USD) — Base | D35: Ene | E35: Feb | F35: Mar | G35: Abr | H35: May | I35: Jun | J35: Jul | K35: Ago | N35: Sep | O35: Oct | P35: Nov | Q35: Dic | R35: TOTAL
B36: USD | C36: USD | D36: 176186.49 | E36: 175305.55 | F36: 175643.79 | G36: 230718.12 | H36: 264031.05 | I36: 275673.04 | J36: 274294.68 | K36: 285467.08 | N36: 284039.74 | O36: 282619.54 | P36: 281206.45 | Q36: 279800.41 | R36: 2984986
B37: Check: Total Plan USD | C37: Calc | D37: 2984986 | R37: 2984986
B38: COSTOS BASE 2025 (COP) — Ajustados por inflación en P&L
B39: Cuenta | C39: Base 2025 (COP) | D39: 2026 = Base×(1+Infl.) (COP)
B40: Costo de Ventas | C40: =C135 -> 3795959000 | D40: =C40*(1+$C$11) -> 3.9895529e+09 | E40: CostoVentasBase
C41: 3795959000 | D41: 3989552909
B42: Otros costos directos / desarrollo | C42: 0 | D42: 0
...

Sheet Modelo Base
B2: Coco Tecnologías — Modelo Financiero 3 Estados | E2: Dic-25 | F2: Ene-26 | G2: Feb-26 | H2: Mar-26 | I2: Abr-26 | J2: May-26 | K2: Jun-26 | L2: Jul-26 | M2: Ago-26 | N2: Sep-26 | O2: Oct-26 | P2: Nov-26 | Q2: Dic-26
B4: SUPUESTOS Y DRIVERS (COP)
B5: Cifras en pesos colombianos. Fuente: INPUTS + EEFF reales Feb/Mar-26
B6: Tasa de Cambio (COP/USD) | C6: TRM | E6: =TrmLargoPlazo -> 3690 | F6: 3690 | G6: 3690 | H6: 3690 | I6: 3690 | J6: 3690 | K6: 3690 | L6: 3690 | M6: 3690 | N6: 3690 | O6: 3690 | P6: 3690 | Q6: 3690
B7: Tasa de Impuestos | C7: % Estatutario | E7: =TasaImpuesto -> 0.35 | F7: =TasaImpuesto -> 0.35 | G7: =TasaImpuesto -> 0.35 | H7: =TasaImpuesto -> 0.35 | I7: =TasaImpuesto -> 0.35 | J7: =TasaImpuesto -> 0.35 | K7: =TasaImpuesto -> 0.35 | L7: =TasaImpuesto -> 0.35 | ... Q7: =TasaImpuesto -> 0.35
B9: Drivers del Estado de Resultados | S9: Total COP | T9: Total USD
B10: Ingresos Mensuales (COP) | C10: fuente: P&L | F10: =Inputs!$D$132 -> 612247701 | G10: =Inputs!$E$132 -> 744218137 | H10: =Inputs!$F$132 -> 787041187 | I10: =Inputs!$G$132 -> 750867662 | J10: =Inputs!$H$132 -> 826514746 | K10: =Inputs!$I$132 -> 751453314 | L10: =Inputs!$J$132 -> 679890552 | M10: {=INDEX(Revenue!K:K,$E$18)} -> 9.7231409e+08 | N10: {=INDEX(Revenue!L:L,$E$18)} -> 1.1624883e+09 | O10: {=INDEX(Revenue!M:M,$E$18)} -> 1.1418829e+09 | P10: {=INDEX(Revenue!N:N,$E$18)} -> 1.1567582e+09 | Q10: {=INDEX(Revenue!O:O,$E$18)} -> 1.2443405e+09 | S10: =SUM(F10:Q10) -> 1.0830017e+10 | T10: =S10/TrmLargoPlazo -> 2934964
B11: Costo de Ventas Mensual (COP) | C11: fuente: P&L | F11: =Inputs!$D$135 -> 238535794 | G11: =Inputs!$E$135 -> 343308791 | H11: =Inputs!$F$135 -> 455639201 | I11: =Inputs!$G$135 -> 379273594 | J11: =Inputs!H135 -> 355470523 | K11: =Inputs!I135 -> 348477606 | L11: =Inputs!J135 -> 321917838 | M11: =CostoVentasBase*(1+InflacionAnual)*(1/12)+DeltaModQ3 -> 3.5252106e+08 | N11: =CostoVentasBase*(1+InflacionAnual)*(1/12)+DeltaModQ3 -> 3.5252106e+08 | O11: =CostoVentasBase*(1+InflacionAnual)*(1/12)+DeltaModQ3 -> 3.5252106e+08 | P11: =CostoVentasBase*(1+InflacionAnual)*(1/12)+DeltaModQ4 -> 3.6255022e+08 | Q11: =CostoVentasBase*(1+InflacionAnual)*(1/12)+DeltaModQ4 -> 3.6255022e+08 | S11: =SUM(F11:Q11) -> 4.225287e+09 | T11: =S11/TrmLargoPlazo -> 1145064.2
B12: Gastos Administrativos (COP) | F12: =Inputs!$D$139 -> 98722435 | G12: =Inputs!$E$139 -> 105633472 | H12: =Inputs!$F$139 -> 141811865 | I12: =Inputs!$G$139 -> 114280887 | J12: =Inputs!H139 -> 116808824 | K12: =Inputs!I139 -> 112288693 | L12: =Inputs!J139 -> 107932742 | M12: =GtosAdminBase*(1+InflacionAnual)*(1/12) -> 1.3539998e+08 | N12: =GtosAdminBase*(1+InflacionAnual)*(1/12) -> 1.3539998e+08 | O12: =GtosAdminBase*(1+InflacionAnual)*(1/12) -> 1.3539998e+08 | P12: =GtosAdminBase*(1+InflacionAnual)*(1/12) -> 1.3539998e+08 | Q12: =GtosAdminBase*(1+InflacionAnual)*(1/12) -> 1.3539998e+08 | S12: =SUM(F12:Q12) -> 1.4744788e+09 | T12: =S12/TrmLargoPlazo -> 399587.76
B13: Gastos de Ventas (COP) | F13: =Inputs!$D$142 -> 131600259 | G13: =Inputs!$E$142 -> 173632204 | H13: =Inputs!$F$142 -> 139615776 | I13: =Inputs!$G$142 -> 130090415 | J13: =Inputs!H142 -> 120233213 | K13: =Inputs!I142 -> 146803460 | L13: =Inputs!J142 -> 117761236 | M13: =GtosVentasBase*(1+InflacionAnual)*(1/12)+DeltaVtasQ3 -> 2.3088303e+08 | N13: =GtosVentasBase*(1+InflacionAnual)*(1/12)+DeltaVtasQ3 -> 2.3088303e+08 | O13: =GtosVentasBase*(1+InflacionAnual)*(1/12)+DeltaVtasQ3 -> 2.3088303e+08 | P13: =GtosVentasBase*(1+InflacionAnual)*(1/12)+DeltaVtasQ4 -> 2.3766442e+08 | Q13: =GtosVentasBase*(1+InflacionAnual)*(1/12)+DeltaVtasQ4 -> 2.3766442e+08 | S13: =SUM(F13:Q13) -> 2.1277145e+09 | T13: =S13/TrmLargoPlazo -> 576616.39
B14: Gastos Operativos/Proyectos (COP) | F14: =Inputs!$D$141 -> 73409852 | G14: =Inputs!$E$141 -> 75509638 | H14: =Inputs!$F$141 -> 72217138 | I14: =Inputs!$G$141 -> 122384514 | J14: =Inputs!H141 -> 120992711 | K14: =Inputs!I141 -> 108908060 | L14: =Inputs!J141 -> 102936374 | M14: =GtosOpInflado*(1/12) -> 1.1302524e+08 | N14: =GtosOpInflado*(1/12) -> 1.1302524e+08 | O14: =GtosOpInflado*(1/12) -> 1.1302524e+08 | P14: =GtosOpInflado*(1/12) -> 1.1302524e+08 | Q14: =GtosOpInflado*(1/12) -> 1.1302524e+08 | S14: =SUM(F14:Q14) -> 1.2414845e+09 | T14: =S14/TrmLargoPlazo -> 336445.66
B15: Ingresos No Operacionales (COP) | F15: =Inputs!$D$146 -> 597687 | G15: =Inputs!$E$146 -> 13488976 | H15: =Inputs!$F$146 -> -10197660 | I15: =Inputs!$G$146 -> 906545 | J15: =Inputs!H146 -> 1366339 | K15: =Inputs!I146 -> 3920249 | L15: =Inputs!J146 -> 718311 | M15: =IngNoOpBase*(1+InflacionAnual)*(1/12) -> 11706739 | N15: =IngNoOpBase*(1+InflacionAnual)*(1/12) -> 11706739 | O15: =IngNoOpBase*(1+InflacionAnual)*(1/12) -> 11706739 | P15: =IngNoOpBase*(1+InflacionAnual)*(1/12) -> 11706739 | Q15: =IngNoOpBase*(1+InflacionAnual)*(1/12) -> 11706739 | S15: =SUM(F15:Q15) -> 69334140 | T15: =S15/TrmLargoPlazo -> 18789.74
B16: Gastos No Operacionales (COP) | F16: =Inputs!$D$150 -> 7091551 | G16: =Inputs!$E$150 -> 5574093 | H16: =Inputs!$F$150 -> 5497554 | I16: =Inputs!$G$150 -> 5038594 | J16: =Inputs!$H$150 -> 6000846 | K16: =Inputs!$I$150 -> 5552094 | L16: =Inputs!$J$150 -> 5353621 | M16: =GtosNoOpBase*(1+InflacionAnual)*(1/12) -> 8061432.8 | N16: =GtosNoOpBase*(1+InflacionAnual)*(1/12) -> 8061432.8 | O16: =GtosNoOpBase*(1+InflacionAnual)*(1/12) -> 8061432.8 | P16: =GtosNoOpBase*(1+InflacionAnual)*(1/12) -> 8061432.8 | Q16: =GtosNoOpBase*(1+InflacionAnual)*(1/12) -> 8061432.8 | S16: =SUM(F16:Q16) -> 80415517 | T16: =S16/TrmLargoPlazo -> 21792.823
B18: Escenario | C18: Base | D18: fila fuente en Revenue → | E18: =IF(C18="Conservador",47,IF(C18="Optimista",57,52)) -> 52 | F18: =IF($C$18="Optimista",1,IF($C$18="Conservador",2,3)) -> 3
B19: Moneda EEFF | C19: USD | D19: ← conmuta moneda e idioma del bloque EEFF (filas 281-301)
B20: 3 Escenarios de Ingresos | F20: =F2 -> Ene-26 | G20: =G2 -> Feb-26 | H20: =H2 -> Mar-26 | I20: =I2 -> Abr-26 | J20: =J2 -> May-26 | K20: =K2 -> Jun-26 | L20: =L2 -> Jul-26 | M20: =M2 -> Ago-26 | ... Q20: =Q2 -> Dic-26 | S20: Total COP | T20: Total USD
B21: ='Consol. Pptos'!B40 -> Proyección mensual COP — Ppto Metas | E21: Optimista | F21: =F10 -> 612247701 | G21: =G10 -> 744218137 | H21: =H10 -> 787041187 | I21: =I10 -> 750867662 | J21: ='Consol. Pptos'!H63 -> 1013200000 | K21: ='Consol. Pptos'!I63 -> 1.1866154e+09 | L21: ='Consol. Pptos'!J63 -> 1.3600307e+09 | M21: ='Consol. Pptos'!K63 -> 1.5334461e+09 | N21: ='Consol. Pptos'!L63 -> 1.7068614e+09 | O21: ='Consol. Pptos'!M63 -> 1.8802768e+09 | P21: ='Consol. Pptos'!N63 -> 2.0536921e+09 | Q21: ='Consol. Pptos'!O63 -> 2227107500 | S21: =SUM(F21:Q21) -> 15855604687 | T21: =S21/TrmLargoPlazo -> 4296911.8
B22: ='Consol. Pptos'!B108 -> Proyección mensual COP — Ppto Intnl | E22: Conservador | F22: =F10 -> 612247701 | G22: =G10 -> 744218137 | H22: =H10 -> 787041187 | I22: =I10 -> 750867662 | J22: ='Consol. Pptos'!H122 -> 1.2184027e+09 | K22: ='Consol. Pptos'!I122 -> 7.5947894e+08 | L22: ='Consol. Pptos'!J122 -> 8.0343646e+08 | M22: ='Consol. Pptos'!K122 -> 1.2436402e+09 | N22: ='Consol. Pptos'!L122 -> 1.2490402e+09 | O22: ='Consol. Pptos'!M122 -> 1.3504209e+09 | P22: ='Consol. Pptos'!N122 -> 1.3558209e+09 | Q22: ='Consol. Pptos'!O122 -> 1.3612209e+09 | S22: =SUM(F22:Q22) -> 1.2235836e+10 | T22: =S22/TrmLargoPlazo -> 3315944.7
B23: ='Consol. Pptos'!B177 -> Proyección mensual COP — Ppto Consolidado | E23: Base | F23: =F10 -> 612247701 | G23: =G10 -> 744218137 | H23: =H10 -> 787041187 | I23: =I10 -> 750867662 | J23: =Inputs!H132 -> 826514746 | K23: =Inputs!I132 -> 751453314 | L23: ='Consol. Pptos'!J202 -> 1.0474069e+09 | M23: ='Consol. Pptos'!K202 -> 1.5736261e+09 | N23: ='Consol. Pptos'!L202 -> 1.6650414e+09 | O23: ='Consol. Pptos'!M202 -> 1.7564568e+09 | P23: ='Consol. Pptos'!N202 -> 1.8478721e+09 | Q23: ='Consol. Pptos'!O202 -> 1939287500 | S23: =SUM(F23:Q23) -> 1.4302034e+10 | T23: =S23/TrmLargoPlazo -> 3875889.9
B26: Drivers del Balance General | R26: Préstamo Intercompany - Coco Delaware
B27: DSO (Días de Cobro) | C27: Días | E27: 84 | R27: Prestamista | S27: Nombre | T27: Coco Delaware
B28: DPO (Días de Pago) | C28: Días | E28: 52 | R28: Fondos USA disponibles | S28: USD | T28: 338508
B29: Vida Útil PPE (meses) | C29: Meses | E29: 60 | R29: Cupo máximo Coco Delaware | S29: COP | T29: =$T$28*$E$6 -> 1249094520
B30: CapEx mensual proyectado (COP) | C30: COP | E30: 7360092 | R30: Tasa interés intercompany | S30: % anual | T30: 0
B31: Impuestos x Pagar (% de Impuestos) | C31: % | E31: 1 | R31: Inicio de mecánica | S31: Mes | T31: May-26
B32: Caja mínima operativa (COP) | C32: COP | E32: =E34 -> 231459000
B33: Saldos Iniciales (Dic-25, COP)
B34: Efectivo | E34: 231459000 | F34: =Inputs!D93 -> 425594626 | G34: =Inputs!E93 -> 120301539 | H34: =Inputs!F93 -> 269488711 | I34: =Inputs!G93 -> 357757161 | J34: =Inputs!H93 -> 244822345 | K34: =Inputs!I93 -> 115441362 | L34: =Inputs!J93 -> 174266926
B35: CxC Clientes | E35: 1833296000 | F35: =Inputs!D96 -> 1590540829 | G35: =Inputs!E96 -> 1797557189 | H35: =Inputs!F96 -> 1690589814 | I35: =Inputs!G96 -> 1612589704 | J35: =Inputs!H96 -> 1675346692 | K35: =Inputs!I96 -> 1799431102 | L35: =Inputs!J96 -> 1688457915
B36: Inversiones | E36: 92028000 | F36: =Inputs!D94 -> 92548595 | G36: =Inputs!E94 -> 93008823 | H36: =Inputs!F94 -> 93705293 | I36: =Inputs!G94 -> 94574157 | J36: =Inputs!H94 -> 175907394 | K36: =Inputs!I94 -> 77569331 | L36: =Inputs!J94 -> 78270032
B37: Otros Deudores | E37: 3301925000 | F37: =Inputs!D97 -> 3331745751 | G37: =Inputs!E97 -> 3359507781 | H37: =Inputs!F97 -> 3397894998 | I37: =Inputs!G97 -> 3433020955 | J37: =Inputs!H97 -> 3468917579 | K37: =Inputs!I97 -> 3497856336 | L37: =Inputs!J97 -> 3529697045
B38: PPE (neto) | E38: 209212000 | F38: =Inputs!D101 -> 216571954 | G38: =Inputs!E101 -> 222840954 | H38: =Inputs!F101 -> 223130002 | I38: =Inputs!G101 -> 218182533 | J38: =Inputs!H101 -> 225975514 | K38: =Inputs!I101 -> 225975514 | L38: =Inputs!J101 -> 225975514
B39: Intangibles | E39: 410000000 | F39: =Inputs!D102 -> 410000000 | G39: =Inputs!E102 -> 410000000 | H39: =Inputs!F102 -> 410000000 | I39: =Inputs!G102 -> 410000000 | J39: =Inputs!H102 -> 410000000 | K39: =Inputs!I102 -> 410000000 | L39: =Inputs!J102 -> 410000000
B40: CxP Proveedores | E40: 544703000 | F40: =Inputs!D109 -> 502128241 | G40: =Inputs!E109 -> 493782297 | H40: =Inputs!F109 -> 571037565 | I40: =Inputs!G109 -> 563841763 | J40: =Inputs!H109 -> 502311050 | K40: =Inputs!I109 -> 483390906 | L40: =Inputs!J109 -> 403760304
B41: CxP Socios/Terceros | E41: 2654919000 | F41: =Inputs!D116 -> 2645015181 | G41: =Inputs!E116 -> 2622128056 | H41: =Inputs!F116 -> 2643128881 | I41: =Inputs!G116 -> 2648455481 | J41: =Inputs!H116 -> 2642649181 | K41: =Inputs!I116 -> 2641566481 | L41: =Inputs!J116 -> 2641787281
B42: Impuestos x Pagar | E42: 40077000 | F42: =Inputs!D112 -> 14350080 | G42: =Inputs!E112 -> 1791700 | H42: =Inputs!F112 -> 25570584 | I42: =Inputs!G112 -> 24496645 | J42: =Inputs!H112 -> 22513416 | K42: =Inputs!I112 -> 23325495 | L42: =Inputs!J112 -> 19229474
B43: Obligaciones Laborales | E43: 333178000 | F43: =Inputs!D113 -> 344307623 | G43: =Inputs!E113 -> 241683051 | H43: =Inputs!F113 -> 236353731 | I43: =Inputs!G113 -> 271532869 | J43: =Inputs!H113 -> 320296862 | K43: =Inputs!I113 -> 247533920 | L43: =Inputs!J113 -> 265675229
B44: Obligaciones Financieras | E44: 80111000 | F44: =Inputs!D108 -> 72783461 | G44: =Inputs!E108 -> 101365099 | H44: =Inputs!F108 -> 104189980 | I44: =Inputs!G108 -> 112563470 | J44: =Inputs!H108 -> 99589767 | K44: =Inputs!I108 -> 83503947 | L44: =Inputs!J108 -> 104555195
B45: Capital Social + Superávit | E45: 1210339000 | F45: =Inputs!D121 -> 1210339000 | G45: =Inputs!E121 -> 1210339000 | H45: =Inputs!F121 -> 1210339000 | I45: =Inputs!G121 -> 1210339000 | J45: =Inputs!H121 -> 1210339000 | K45: =Inputs!I121 -> 1210339000 | L45: =Inputs!J121 -> 1210339000
B46: Utilidades Acumuladas | E46: 1214593000 | F46: =Inputs!D122 -> 1278078168 | G46: =Inputs!E122 -> 1332127083 | H46: =Inputs!F122 -> 1294189077 | I46: =Inputs!G122 -> 1294895280 | J46: =Inputs!H122 -> 1403270248 | K46: =Inputs!I122 -> 1436613897 | L46: =Inputs!J122 -> 1461320949
...

Sheet Consol. Pptos
B1: COCO Tecnologías — Consolidado Total de Presupuestos 2026
B2: Apila las 4 hojas fuente: Ppto Metas · Ppto Intnl · Ppto Consolidado · Datos Intnl. Valores linkeados a las hojas originales. | H2: Óptica | I2: Total COP | J2: Total USD
H3: Ppto Metas | I3: 16192037025 | J3: 4272305.3
B4: ▸ Salta a: | C4: 1. Ppto Metas | D4: 2. Ppto Intnl | E4: 3. Ppto Consolidado | F4: 4. Datos Intnl | H4: Ppto Intnl | I4: 1.2299661e+10 | J4: 3245293.1
H5: Ppto Consolidado | I5: 15238222885 | J5: 4020639.3
B7: 1. PPTO METAS — Escenario objetivo (incluye Enterprise CR 1M USD)
B9: Variables principales
B10: TRM | C10: =Inputs!$C$6 -> 3690 | D10: COP/USD
B11: MRR base abril asumido | C11: 800000000 | D11: COP
B12: Ingreso real enero | C12: 612247701 | D12: COP
B13: Ingreso real febrero | C13: 744218137 | D13: COP
B14: Ingreso real marzo | C14: 787041187 | D14: COP
B16: Metas 2026 (inputs USD) | C16: USD
B17: Ingreso acumulado (referencia) | C17: 2100000
B18: Churn (-) | C18: 315000
B19: Contracción (-) | C19: 42000
B20: One-off (imp. + interop.) | C20: 63000
B21: Logos nuevos (MRR) | C21: =SUM(C22:C26) -> 374000
B22: Siesa | C22: 50000
B23: Indigo | C23: 50000
B24: Weli | C24: 50000
B25: Menudeo | C25: 200000
B26: Clientes > 3mil citas | C26: 24000
B27: Innovación | C27: =SUM(C28:C31) -> 507000
B28: Campañas + bot 2.0 | C28: 300000
B29: COCO Pay | C29: 105000
B30: Cirugías | C30: 60000
B31: ChargeBee | C31: 42000
B32: Up/Cross Selling (NRR) | C32: =SUM(C33:C35) -> 220000
B33: Comfama | C33: 36000
B34: Maple | C34: 84000
B35: Otros | C35: 100000
B36: Enterprise (MRR) CR | C36: 1000000
B37: TOTAL | C37: =C17-C18-C19+C20+C21+C27+C32+C36 -> 3907000
B40: Proyección mensual COP — Ppto Metas
B41: Categoría | C41: Rubro | D41: Ene-26 | E41: 46079 | F41: 46107 | G41: Abr-26 | H41: 46168 | I41: 46199 | J41: 46229 | K41: Ago-26 | L41: 46291 | M41: 46321 | N41: 46352 | O41: Dic-26 | P41: Total 2026
B42: Actual | C42: Ingresos reales reportados | D42: =$C$12 -> 612247701 | E42: =$C$13 -> 744218137 | F42: =$C$14 -> 787041187 | G42: 0 | H42: 0 | I42: 0 | J42: 0 | K42: 0 | L42: 0 | M42: 0 | N42: 0 | O42: 0 | P42: =SUM(D42:O42) -> 2143507025
B43: Base recurrente | C43: MRR base (800M plano Abr-Dic) | D43: 0 | E43: 0 | F43: 0 | G43: =$C$11 -> 800000000 | H43: =$C$11 -> 800000000 | I43: =$C$11 -> 800000000 | J43: =$C$11 -> 800000000 | K43: =$C$11 -> 800000000 | L43: =$C$11 -> 800000000 | M43: =$C$11 -> 800000000 | N43: =$C$11 -> 800000000 | O43: =$C$11 -> 800000000 | P43: =SUM(D43:O43) -> 7200000000
B44: Logos nuevos (MRR) | C44: Subtotal logos nuevos | D44: =SUM(D45:D49) -> 0 | E44: =SUM(E45:E49) -> 0 | F44: =SUM(F45:F49) -> 0 | G44: =SUM(G45:G49) -> 30668000 | H44: =SUM(H45:H49) -> 61336000 | I44: =SUM(I45:I49) -> 92004000 | J44: =SUM(J45:J49) -> 122672000 | K44: =SUM(K45:K49) -> 153340000 | ... O44: =SUM(O45:O49) -> 276012000 | P44: =SUM(D44:O44) -> 1380060000
B45: Logos nuevos | C45: Siesa | D45: 0 | E45: 0 | F45: 0 | G45: =$C$22*$C$10*1/45 -> 4100000 | H45: =$C$22*$C$10*2/45 -> 8200000 | I45: =$C$22*$C$10*3/45 -> 12300000 | J45: =$C$22*$C$10*4/45 -> 16400000 | K45: =$C$22*$C$10*5/45 -> 20500000 | L45: =$C$22*$C$10*6/45 -> 24600000 | M45: =$C$22*$C$10*7/45 -> 28700000 | N45: =$C$22*$C$10*8/45 -> 32800000 | O45: =$C$22*$C$10*9/45 -> 36900000 | P45: =SUM(D45:O45) -> 184500000
...

Sheet Informe Accionista
B2: COCO Tecnologías — Informe de Resultados Ene-Jul 2026 | L2: TRM Real / Ajustado: | M2: 3690
B3: Todas las cifras en USD. Presupuesto original Enero valorado a TRM 4,000 COP/USD (versión entregada en su momento). Real y presupuesto ajustado valorados a TRM 3,690 COP/USD. | L3: TRM Ppto Original Enero: | M3: 4000
B5: 1. RESUMEN EJECUTIVO — Acumulado Ene-Jul 2026 (USD) | L5: TRM: 3,690
C7: Ppto Ene-Jul | D7: Real | E7: Diferencia | F7: % Cumpl.
B8: Ingresos | C8: =SUM(C65:I65) -> 2462707 | D8: =SUM('Modelo Base'!F51:L51)/$M$2 -> 1396269.2 | E8: =D8-C8 -> -1066437.8 | F8: =IF(C8=0,0,D8/C8) -> 0.56696521
B9: Utilidad bruta | C9: =SUM(C65:I65)-SUM(C66:I66) -> 1683173 | D9: =SUM('Modelo Base'!F53:L53)/$M$2 -> 734311.64 | E9: =D9-C9 -> -948861.36 | F9: =IF(C9=0,0,D9/C9) -> 0.43626629
B10: EBITDA | C10: =C9-SUM(C68:I68)-SUM(C69:I69) -> 1070288 | D10: =SUM('Modelo Base'!F59:L59)/$M$2 -> 74806.554 | E10: =D10-C10 -> -995481.45 | F10: =IF(C10=0,0,D10/ABS(C10)) -> 0.069893855
B11: Utilidad neta | C11: =C10+SUM(C71:I71)-SUM(C72:I72)-SUM(C73:I73) -> 685267 | D11: =SUM('Modelo Base'!F70:L70)/$M$2 -> 66864.032 | E11: =D11-C11 -> -618402.97 | F11: =IF(C11=0,0,D11/ABS(C11)) -> 0.097573693
B12: Margen EBITDA | C12: =IF(C8=0,0,C10/C8) -> 0.43459819 | D12: =IF(D8=0,0,D10/D8) -> 0.053576026 | E12: =D12-C12 -> -0.38102216
B13: Margen neto | C13: =IF(C8=0,0,C11/C8) -> 0.27825762 | D13: =IF(D8=0,0,D11/D8) -> 0.047887637 | E13: =D13-C13 -> -0.23036999
B16: 2. CUMPLIMIENTO ACUMULADO vs PRESUPUESTO ORIGINAL ENERO (USD) | L16: TRM: 3,690
B17: Línea | C17: Ene | D17: Ene-Feb | E17: Ene-Mar | F17: Ene-Abr | G17: Ene-May | H17: Ene-Jun | I17: YTD (Ene-Jul)
B18: Ingresos | C18: =IF(C65=0,0,C30/C65) -> 0.89093596 | D18: =IF(SUM(C65:D65)=0,0,SUM(C30:D30)/SUM(C65:D65)) -> 0.68005527 | E18: =IF(SUM(C65:E65)=0,0,SUM(C30:E30)/SUM(C65:E65)) -> 0.62009092 | F18: =IF(SUM(C65:F65)=0,0,SUM(C30:F30)/SUM(C65:F65)) -> 0.60524203 | G18: =IF(SUM(C65:G65)=0,0,SUM(C30:G30)/SUM(C65:G65)) -> 0.5934866 | H18: =IF(SUM(C65:H65)=0,0,SUM(C30:H30)/SUM(C65:H65)) -> 0.58421101 | I18: =IF(SUM(C65:I65)=0,0,SUM(C30:I30)/SUM(C65:I65)) -> 0.56696521
B19: Utilidad bruta | C19: =IF(C65-C66=0,0,C32/(C65-C66)) -> 1.3527039 | D19: =IF(SUM(C65:D65)-SUM(C66:D66)=0,0,SUM(C32:D32)/(SUM(C65:D65)-SUM(C66:D66))) -> 0.66049498 | E19: =IF(SUM(C65:E65)-SUM(C66:E66)=0,0,SUM(C32:E32)/(SUM(C65:E65)-SUM(C66:E66))) -> 0.49731593 | F19: =IF(SUM(C65:F65)-SUM(C66:F66)=0,0,SUM(C32:F32)/(SUM(C65:F65)-SUM(C66:F66))) -> 0.47080754 | G19: =IF(SUM(C67:G67)=0,0,SUM(C32:G32)/ABS(SUM(C67:G67))) -> 0.46232538 | H19: =IF(SUM(C67:H67)=0,0,SUM(C32:H32)/ABS(SUM(C67:H67))) -> 0.45312671 | I19: =IF(SUM(C67:I67)=0,0,SUM(C32:I32)/ABS(SUM(C67:I67))) -> 0.43626629
B20: EBITDA | C20: =IF((C65-C66-C68-C69)=0,0,C37/ABS(C65-C66-C68-C69)) -> 1.4950411 | D20: =IF((SUM(C65:D65)-SUM(C66:D66)-SUM(C68:D68)-SUM(C69:D69))=0,0,SUM(C37:D37)/ABS(SUM(C65:D65)-SUM(C66:D66)-SUM(C68:D68)-SUM(C69:D69))) -> 0.22048252 | E20: =IF((SUM(C65:E65)-SUM(C66:E66)-SUM(C68:E68)-SUM(C69:E69))=0,0,SUM(C37:E37)/ABS(SUM(C65:E65)-SUM(C66:E66)-SUM(C68:E68)-SUM(C69:E69))) -> 0.074812117 | F20: =IF((SUM(C65:F65)-SUM(C66:F66)-SUM(C68:F68)-SUM(C69:F69))=0,0,SUM(C37:F37)/ABS(SUM(C65:F65)-SUM(C66:F66)-SUM(C68:F68)-SUM(C69:F69))) -> 0.053467049 | G20: =IF(SUM(C70:G70)=0,0,SUM(C37:G37)/ABS(SUM(C70:G70))) -> 0.081445042 | H20: =IF(SUM(C70:H70)=0,0,SUM(C37:H37)/ABS(SUM(C70:H70))) -> 0.075874676 | I20: =IF(SUM(C70:I70)=0,0,SUM(C37:I37)/ABS(SUM(C70:I70))) -> 0.069893855
B21: Utilidad neta | C21: =IF(C74=0,0,C41/ABS(C74)) -> 1.2372172 | D21: =IF(SUM(C74:D74)=0,0,SUM(C41:D41)/ABS(SUM(C74:D74))) -> 0.36903067 | E21: =IF(SUM(C74:E74)=0,0,SUM(C41:E41)/ABS(SUM(C74:E74))) -> 0.10090253 | F21: =IF(SUM(C74:F74)=0,0,SUM(C41:F41)/ABS(SUM(C74:F74))) -> 0.068615052 | G21: =IF(SUM(C74:G74)=0,0,SUM(C41:G41)/ABS(SUM(C74:G74))) -> 0.11386051 | H21: =IF(SUM(C74:H74)=0,0,SUM(C41:H41)/ABS(SUM(C74:H74))) -> 0.1068518 | I21: =IF(SUM(C74:I74)=0,0,SUM(C41:I41)/ABS(SUM(C74:I74))) -> 0.097573693
B25: 3. P&L MENSUAL 2026 — REAL ENE-JUL + PROYECCIÓN AGO-DIC (USD) | L25: TRM: 3,690
B26: Real Ene-Abr + proyección May-Dic actualizada del Modelo Base, valorado en USD a TRM 3,690.
B28: Línea | C28: Ene | D28: Feb | E28: Mar | F28: Abr | G28: May | H28: Jun | I28: Jul | J28: Ago | K28: Sep | L28: Oct | M28: Nov | N28: Dic | O28: Total 2026 | P28: YTD real Ene-Jul
B29: (Verde: real · Amarillo: proyectado)
B30: Ingresos | C30: ='Modelo Base'!F51/$M$2 -> 165920.79 | D30: ='Modelo Base'!G51/$M$2 -> 201685.13 | E30: ='Modelo Base'!H51/$M$2 -> 213290.29 | F30: ='Modelo Base'!I51/$M$2 -> 203487.17 | G30: ='Modelo Base'!J51/$M$2 -> 223987.74 | H30: ='Modelo Base'!K51/$M$2 -> 203645.88 | I30: ='Modelo Base'!L51/$M$2 -> 184252.18 | J30: ='Modelo Base'!M51/$M$2 -> 426456.93 | ... N30: ='Modelo Base'!Q51/$M$2 -> 525552.17 | O30: =SUM(C30:N30) -> 3776291.9 | P30: =SUM(C30:I30) -> 1396269.2
B31: Costo de ventas | C31: ='Modelo Base'!F52/$M$2 -> 64643.847 | D31: ='Modelo Base'!G52/$M$2 -> 93037.613 | E31: ='Modelo Base'!H52/$M$2 -> 123479.46 | F31: ='Modelo Base'!I52/$M$2 -> 102784.17 | G31: ='Modelo Base'!J52/$M$2 -> 96333.475 | H31: ='Modelo Base'!K52/$M$2 -> 94438.376 | I31: ='Modelo Base'!L52/$M$2 -> 87240.607 | J31: ='Modelo Base'!M52/$M$2 -> 95534.163 | ... N31: ='Modelo Base'!Q52/$M$2 -> 98252.092 | O31: =SUM(C31:N31) -> 1145064.2 | P31: =SUM(C31:I31) -> 661957.55
B32: Utilidad bruta | C32: ='Modelo Base'!F53/$M$2 -> 101276.94 | D32: ='Modelo Base'!G53/$M$2 -> 108647.52 | E32: ='Modelo Base'!H53/$M$2 -> 89810.836 | F32: ='Modelo Base'!I53/$M$2 -> 100703 | G32: ='Modelo Base'!J53/$M$2 -> 127654.26 | H32: ='Modelo Base'!K53/$M$2 -> 109207.51 | I32: ='Modelo Base'!L53/$M$2 -> 97011.576 | J32: ='Modelo Base'!M53/$M$2 -> 330922.77 | ... N32: ='Modelo Base'!Q53/$M$2 -> 427300.08 | O32: =SUM(C32:N32) -> 2631227.7 | P32: =SUM(C32:I32) -> 734311.64
B33: Margen bruto | C33: =IF(C30=0,0,C32/C30) -> 0.61039332 | D33: =IF(D30=0,0,D32/D30) -> 0.5386987 | E33: =IF(E30=0,0,E32/E30) -> 0.42107324 | F33: =IF(F30=0,0,F32/F30) -> 0.49488623 | G33: =IF(G30=0,0,G32/G30) -> 0.5699163 | H33: =IF(H30=0,0,H32/H30) -> 0.5362618 | I33: =IF(I30=0,0,I32/I30) -> 0.52651521 | J33: =IF(J30=0,0,J32/J30) -> 0.77598169 | ... P33: =IF(P30=0,0,P32/P30) -> 0.52590979
B34: Gastos admin | C34: ='Modelo Base'!F56/$M$2 -> 26754.047 | D34: ='Modelo Base'!G56/$M$2 -> 28626.957 | E34: ='Modelo Base'!H56/$M$2 -> 38431.4 | F34: ='Modelo Base'!I56/$M$2 -> 30970.43 | G34: ='Modelo Base'!J56/$M$2 -> 31655.508 | H34: ='Modelo Base'!K56/$M$2 -> 30430.54 | I34: ='Modelo Base'!L56/$M$2 -> 29250.066 | J34: ='Modelo Base'!M56/$M$2 -> 36693.761 | ... N34: ='Modelo Base'!Q56/$M$2 -> 36693.761 | O34: =SUM(C34:N34) -> 399587.76 | P34: =SUM(C34:I34) -> 216118.95
B35: Gastos ventas | C35: ='Modelo Base'!F57/$M$2 -> 35664.027 | D35: ='Modelo Base'!G57/$M$2 -> 47054.798 | E35: ='Modelo Base'!H57/$M$2 -> 37836.254 | F35: ='Modelo Base'!I57/$M$2 -> 35254.855 | G35: ='Modelo Base'!J57/$M$2 -> 32583.527 | H35: ='Modelo Base'!K57/$M$2 -> 39784.136 | I35: ='Modelo Base'!L57/$M$2 -> 31913.614 | J35: ='Modelo Base'!M57/$M$2 -> 62569.927 | ... N35: ='Modelo Base'!Q57/$M$2 -> 64407.701 | O35: =SUM(C35:N35) -> 576616.39 | P35: =SUM(C35:I35) -> 260091.21
B36: Gastos op/proyectos | C36: ='Modelo Base'!F58/$M$2 -> 19894.269 | D36: ='Modelo Base'!G58/$M$2 -> 20463.317 | E36: ='Modelo Base'!H58/$M$2 -> 19571.04 | F36: ='Modelo Base'!I58/$M$2 -> 33166.535 | G36: ='Modelo Base'!J58/$M$2 -> 32789.353 | H36: ='Modelo Base'!K58/$M$2 -> 29514.379 | I36: ='Modelo Base'!L58/$M$2 -> 27896.036 | J36: ='Modelo Base'!M58/$M$2 -> 30630.147 | ... N36: ='Modelo Base'!Q58/$M$2 -> 30630.147 | O36: =SUM(C36:N36) -> 336445.66 | P36: =SUM(C36:I36) -> 183294.93
B37: EBITDA | C37: ='Modelo Base'!F59/$M$2 -> 18964.596 | D37: ='Modelo Base'!G59/$M$2 -> 12502.448 | E37: ='Modelo Base'!H59/$M$2 -> -6027.8572 | F37: ='Modelo Base'!I59/$M$2 -> 1311.1794 | G37: ='Modelo Base'!J59/$M$2 -> 30625.874 | H37: ='Modelo Base'!K59/$M$2 -> 9478.4539 | I37: ='Modelo Base'!L59/$M$2 -> 7951.8596 | J37: ='Modelo Base'!M59/$M$2 -> 201028.93 | ... N37: ='Modelo Base'!Q59/$M$2 -> 295568.47 | O37: =SUM(C37:N37) -> 1318577.9 | P37: =SUM(C37:I37) -> 74806.554
B38: Margen EBITDA | C38: =IF(C30=0,0,C37/C30) -> 0.1142991 | D38: =IF(D30=0,0,D37/D30) -> 0.061989932 | E38: =IF(E30=0,0,E37/E30) -> -0.028261282 | F38: =IF(F30=0,0,F37/F30) -> 0.0064435482 | G38: =IF(G30=0,0,G37/G30) -> 0.13673014 | H38: =IF(H30=0,0,H37/H30) -> 0.046543803 | I38: =IF(I30=0,0,I37/I30) -> 0.043157479 | J38: =IF(J30=0,0,J37/J30) -> 0.47139328 | ... P38: =IF(P30=0,0,P37/P30) -> 0.053576026
