Workbook

Sheet Diccionario
A1: Diccionario de indicadores — Dashboard Ejecutivo COCO Tecnologías
A2: Catálogo único de variables. 'Origen=COCO' viene de tu archivo; 'Origen=Claude' son inputs base que las fórmulas requieren y conviene validar.
A3: ID | B3: Categoría | C3: Código indicador | D3: Nombre visible | E3: Tipo | F3: Fórmula / regla de cálculo | G3: Unidad | H3: Responsable carga | I3: Fuente sugerida | J3: Frecuencia | K3: Desglose (segmento / detalle) | L3: Origen | M3: Comentario | N3: periodicidad
A4: 1 | B4: Control | C4: periodo | D4: Periodo | E4: Dimensión | F4: Mes de reporte en formato AAAA-MM | G4: AAAA-MM | H4: Cada área | I4: Plantilla | J4: Mensual | L4: COCO | M4: Debe existir en todas las filas | N4: Mensual
A5: 2 | B5: Control | C5: pais | D5: País | E5: Dimensión | F5: País donde se genera la métrica | G5: Texto | H5: Cada área | I5: Plantilla | J5: Mensual | K5: Colombia / México / EE.UU. / Otros | L5: COCO | N5: Mensual
A6: 3 | B6: Control | C6: compania | D6: Compañía | E6: Dimensión | F6: Entidad legal o unidad de negocio | G6: Texto | H6: Finanzas | I6: Contabilidad | J6: Mensual | K6: Coco Colombia / Coco LLC / Coco Global | L6: COCO | N6: Mensual
A7: 4 | B7: Control | C7: moneda | D7: Moneda | E7: Dimensión | F7: Moneda original del dato reportado | G7: COP/USD | H7: Cada área | I7: Plantilla | J7: Mensual | K7: COP / USD | L7: COCO | M7: No mezclar monedas sin identificar | N7: Mensual
A8: 5 | B8: Control | C8: escenario | D8: Escenario | E8: Dimensión | F8: Tipo de dato reportado | G8: Texto | H8: Finanzas | I8: Plantilla | J8: Mensual | K8: Real / Budget / Forecast | L8: COCO | M8: Permite comparar real vs ppto vs forecast | N8: Mensual
A9: 7 | B9: Finanzas | C9: ingresos_one_off | D9: Ingresos one-off | E9: Input | F9: Facturación no recurrente | G9: COP/USD | H9: Ventas | I9: Facturación / contab. | J9: Mensual | K9: detalle: Implementación / Interoperabilidad / Integración / Proyectos | L9: COCO | M9: Separar de ingresos recurrentes | N9: Mensual
A10: 10 | B10: Finanzas | C10: margen_bruto | D10: Margen bruto | E10: KPI | F10: ingresos_totales - costo_directo | G10: COP/USD | H10: Finanzas | I10: Contabilidad | J10: Mensual | L10: COCO | M10: Indicador clave de escalabilidad | N10: Mensual
A11: 11 | B11: Finanzas | C11: margen_bruto_pct | D11: Margen bruto % | E11: KPI | F11: margen_bruto / ingresos_totales | G11: % | H11: Finanzas | I11: Contabilidad | J11: Mensual | L11: COCO | M11: Meta a definir con CEO | N11: Mensual
A12: 12 | B12: Finanzas | C12: gastos_totales | D12: Gastos operativos totales | E12: Input/KPI | F12: Σ gastos por área | G12: COP/USD | H12: Finanzas | I12: Contabilidad | J12: Mensual | L12: COCO | M12: Opex. Puede cargarse agregado o por área. Distinto de 'egresos_totales' | N12: Mensual
A13: 15 | B13: Finanzas | C13: egresos_totales | D13: Egresos totales | E13: Input/KPI | F13: Σ de todas las salidas del periodo (costos + gastos + financieros) | G13: COP/USD | H13: Finanzas | I13: Contabilidad | J13: Mensual | L13: COCO | M13: P&L: Ingresos - Egresos = Utilidad neta | N13: Mensual
A14: 17 | B14: Finanzas | C14: utilidad_neta | D14: Utilidad neta | E14: KPI | F14: ingresos_totales - egresos_totales | G14: COP/USD | H14: Finanzas | I14: Contabilidad | J14: Mensual | L14: COCO | M14: Resultado del P&L del periodo | N14: Mensual
A15: 13 | B15: Finanzas | C15: ebitda | D15: EBITDA | E15: KPI | F15: margen_bruto - gastos_totales | G15: COP/USD | H15: Finanzas | I15: Contabilidad | J15: Mensual | L15: COCO | M15: Métrica central del comité | N15: Mensual
A16: 14 | B16: Finanzas | C16: margen_ebitda | D16: Margen EBITDA | E16: KPI | F16: ebitda / ingresos_totales | G16: % | H16: Finanzas | I16: Contabilidad | J16: Mensual | L16: COCO | M16: Comparar contra presupuesto | N16: Mensual
A17: 16 | B17: Finanzas | C17: cobros_periodo | D17: Cobros del periodo | E17: Input | F17: Dinero efectivamente recibido de clientes | G17: COP/USD | H17: Tesorería | I17: Bancos / cartera | J17: Mensual | L17: COCO | M17: Distinto a facturación | N17: Mensual
A18: 18 | B18: Finanzas | C18: burn_rate_neto | D18: Burn rate neto | E18: KPI | F18: pagos_periodo - cobros_periodo | G18: COP/USD | H18: Finanzas | I18: Tesorería | J18: Mensual | L18: COCO | M18: Negativo = consume caja | N18: Mensual
A19: 19 | B19: Finanzas | C19: runway_meses | D19: Runway | E19: KPI | F19: caja_disponible / burn_rate_neto | G19: Meses | H19: Finanzas | I19: Tesorería | J19: Mensual | L19: COCO | M19: Solo si burn_rate_neto > 0 | N19: Mensual
A20: 21 | B20: Finanzas | C20: ppto_vs_real_ingresos | D20: Ingresos real vs presupuesto | E20: KPI | F20: (ingresos_totales Real / ingresos_totales Budget) - 1 | G20: % | H20: Finanzas | I20: Presupuesto | J20: Mensual | L20: COCO | M20: Se deriva del campo 'escenario' | N20: Mensual
A21: 22 | B21: Finanzas | C21: ppto_vs_real_gastos | D21: Gastos real vs presupuesto | E21: KPI | F21: (gastos_totales Real / gastos_totales Budget) - 1 | G21: % | H21: Finanzas | I21: Presupuesto | J21: Mensual | L21: COCO | M21: Se deriva del campo 'escenario' | N21: Mensual
... A26: 36 | B26: Ventas | C26: pipeline_ponderado | D26: Pipeline ponderado | E26: KPI | F26: Σ (valor_oportunidad * prob_cierre) | G26: COP/USD | H26: Ventas | I26: CRM | J26: Semanal/mensual | L26: COCO | M26: Más útil que pipeline bruto | N26: Mensual
A27: 37 | B27: Ventas | C27: ventas_cerradas | D27: Ventas cerradas | E27: Input | F27: Valor contratos ganados en el periodo | G27: COP/USD | H27: Ventas | I27: CRM / contratos | J27: Mensual | K27: detalle: Recurrente / One-off | L27: COCO | M27: Separar recurrente vs one-off | N27: Mensual
A28: 41 | B28: Ventas | C28: ticket_promedio | D28: Ticket promedio | E28: KPI | F28: ventas_cerradas / deals_ganados | G28: COP/USD | H28: Ventas | I28: CRM / contratos | J28: Mensual | L28: COCO | M28: Medir también por país | N28: Mensual
A29: 42 | B29: Ventas | C29: forecast_comercial | D29: Forecast comercial | E29: Input/KPI | F29: Σ (oport. con cierre esperado * prob_cierre) | G29: COP/USD | H29: Ventas | I29: CRM | J29: Semanal/mensual | L29: COCO | M29: Anticipa ingresos | N29: Mensual
A30: 43 | B30: Marketing | C30: gasto_marketing_total | D30: Gasto marketing total | E30: Input | F30: Gasto total de marketing (pauta total) | G30: COP/USD | H30: Marketing | I30: Marketing | J30: Mensual | L30: COCO | M30: Necesario para CAC. Revisar = pauta total | N30: Mensual
A31: 44 | B31: Marketing | C31: leads_generados | D31: Leads generados | E31: Input | F31: Nº de leads nuevos | G31: Número | H31: Marketing | I31: CRM / formularios | J31: Mensual | K31: detalle: por canal (opcional) | L31: COCO | M31: Separar por canal si es posible | N31: Mensual
A32: 49 | B32: Marketing | C32: cac_fully_loaded | D32: CAC fully loaded | E32: KPI | F32: (gasto_ventas_comercial + gasto_marketing_total) / clientes_nuevos | G32: COP/USD | H32: Comercial/Mktg | I32: Contab. / CRM | J32: Trimestral | L32: COCO | M32: Incluye ventas + mktg. Revisión trimestral (Andrés) | N32: Trimestral
A33: 50 | B33: Marketing | C33: ltv | D33: LTV | E33: KPI | F33: (arpa * margen_bruto_pct) / churn_ingresos_pct | G33: COP/USD | H33: Comercial/Mktg | I33: Facturación / CRM | J33: Trimestral | K33: detalle: Mercadeo (s/ingreso, churn clientes) | Financiero TTM (margen 51%, churn ingresos) | L33: COCO | M33: Vista Financiera: hoja Calc_LTV_Fin, margen editable, churn TTM | N33: Trimestral
A34: 51 | B34: Marketing | C34: ltv_cac | D34: LTV / CAC | E34: KPI | F34: ltv / cac_fully_loaded | G34: Veces | H34: Comercial/Mktg | I34: Dashboard | J34: Trimestral | K34: detalle: Mercadeo | Financiero | L34: COCO | M34: Eficiencia comercial. Difiere según vista del LTV | N34: Trimestral
A35: 52 | B35: Marketing | C35: cac_payback_meses | D35: Payback CAC | E35: KPI | F35: cac_fully_loaded / (arpa * margen_bruto_pct) | G35: Meses | H35: Comercial/Mktg | I35: Dashboard | J35: Trimestral | K35: detalle: Mercadeo (s/margen) | Financiero (c/margen) | L35: COCO | M35: Dos vistas. Revisión trimestral (Andrés) | N35: Trimestral
A36: 53 | B36: Customer Success | C36: clientes_inicio | D36: Clientes iniciales | E36: Input | F36: Clientes activos al inicio del periodo | G36: Número | H36: Comercial | I36: CRM / facturación | J36: Mensual | L36: COCO | M36: Base para churn | N36: Mensual
A37: 54 | B37: Customer Success | C37: clientes_nuevos | D37: Clientes nuevos | E37: Input | F37: Clientes ganados en el periodo | G37: Número | H37: Comercial | I37: CRM | J37: Mensual | L37: COCO | M37: Reconcilia con ventas | N37: Mensual
A38: 56 | B38: Customer Success | C38: clientes_final | D38: Clientes finales | E38: KPI | F38: clientes_inicio + clientes_nuevos - clientes_perdidos | G38: Número | H38: Comercial | I38: CRM | J38: Mensual | L38: COCO | M38: Base al cierre | N38: Mensual
A39: 57 | B39: Customer Success | C39: churn_clientes_pct | D39: Churn de clientes | E39: KPI | F39: clientes_perdidos / clientes_inicio | G39: % | H39: Comercial | I39: CRM | J39: Mensual | L39: COCO | M39: Complementa churn de ingresos | N39: Mensual
A40: 58 | B40: Customer Success | C40: clientes_en_riesgo | D40: Clientes en riesgo | E40: Input | F40: Clientes con prob. de churn según CS | G40: Número | H40: Comercial | I40: CRM / health score | J40: Mensual | L40: COCO | M40: Métrica accionable | N40: Mensual
A41: 59 | B41: Customer Success | C41: clientes_riesgo_pct | D41: % clientes en riesgo | E41: KPI | F41: clientes_en_riesgo / clientes_final | G41: % | H41: Comercial | I41: CRM | J41: Mensual | L41: COCO | M41: Alerta temprana | N41: Mensual
A42: 60 | B42: Customer Success | C42: nps | D42: NPS | E42: Input | F42: Resultado de encuesta de recomendación | G42: % | H42: CS | I42: Encuestas | J42: Mensual/trim. | K42: detalle: Promotores / Pasivos / Detractores | L42: COCO | M42: S8. Histórico completo lo envía CS | N42: Mensual
A43: 67 | B43: Internacional | C43: ingresos_internacionales | D43: Ingresos internacionales | E43: KPI | F43: Σ ingresos_totales donde país≠Colombia | G43: COP/USD | H43: Finanzas | I43: Facturación | J43: Mensual | K43: segmento: por país | L43: COCO | M43: Clave para ronda | N43: Mensual
A44: 68 | B44: Internacional | C44: mrr_internacional | D44: MRR internacional | E44: KPI | F44: Σ mrr_final donde país≠Colombia | G44: COP/USD | H44: Finanzas/Intl | I44: Facturación / CRM | J44: Mensual | K44: segmento: por país | L44: COCO | N44: Mensual
...

Sheet BD_Indicadores
A1: BD_Indicadores — tabla de hechos (formato largo). 1 fila = 1 indicador en 1 periodo y dimensiones.
A2: AAAA-MM | B2: lista | C2: lista | D2: lista | E2: lista | F2: lista (Diccionario) | G2: p.ej. Medianos | H2: p.ej. AWS / Comercial | I2: número | J2: COP/USD/%/… | K2: opcional | L2: lista (Diccionario)
A3: periodo | B3: pais | C3: compania | D3: moneda | E3: escenario | F3: codigo_indicador | G3: segmento | H3: detalle | I3: valor | J3: unidad | K3: comentario | L3: area | M3: area_responsable | N3: periodicidad
A4: 2024-01 | B4: Colombia | C4: Coco Colombia | D4: COP | E4: Real | F4: ingresos_totales | I4: 430000000 | J4: COP | L4: =IFERROR(INDEX(Diccionario!$B:$B,MATCH(F4,Diccionario!$C:$C,0)),"") | M4: =IFERROR(INDEX(Diccionario!$H:$H,MATCH(F4,Diccionario!$C:$C,0)),"") | N4: =IFERROR(INDEX(Diccionario!$N:$N,MATCH(F4,Diccionario!$C:$C,0)),"")
A5: 2024-01 | B5: Colombia | C5: Coco Colombia | D5: COP | E5: Real | F5: egresos_totales | I5: 547000000 | J5: COP | L5: =IFERROR(INDEX(Diccionario!$B:$B,MATCH(F5,Diccionario!$C:$C,0)),"") | M5: =IFERROR(INDEX(Diccionario!$H:$H,MATCH(F5,Diccionario!$C:$C,0)),"") | N5: =IFERROR(INDEX(Diccionario!$N:$N,MATCH(F5,Diccionario!$C:$C,0)),"")
A6: 2024-01 | B6: Colombia | C6: Coco Colombia | D6: COP | E6: Real | F6: utilidad_neta | I6: -117000000 | J6: COP | K6: Derivado: ingresos - egresos | L6: =IFERROR(INDEX(Diccionario!$B:$B,MATCH(F6,Diccionario!$C:$C,0)),"") | M6: =IFERROR(INDEX(Diccionario!$H:$H,MATCH(F6,Diccionario!$C:$C,0)),"") | N6: =IFERROR(INDEX(Diccionario!$N:$N,MATCH(F6,Diccionario!$C:$C,0)),"")
A7: 2024-02 | B7: Colombia | C7: Coco Colombia | D7: COP | E7: Real | F7: ingresos_totales | I7: 692000000 | J7: COP | L7: =IFERROR(INDEX(Diccionario!$B:$B,MATCH(F7,Diccionario!$C:$C,0)),"") | M7: =IFERROR(INDEX(Diccionario!$H:$H,MATCH(F7,Diccionario!$C:$C,0)),"") | N7: =IFERROR(INDEX(Diccionario!$N:$N,MATCH(F7,Diccionario!$C:$C,0)),"")
A8: 2024-02 | B8: Colombia | C8: Coco Colombia | D8: COP | E8: Real | F8: egresos_totales | I8: 515000000 | J8: COP | L8: =IFERROR(INDEX(Diccionario!$B:$B,MATCH(F8,Diccionario!$C:$C,0)),"") | M8: =IFERROR(INDEX(Diccionario!$H:$H,MATCH(F8,Diccionario!$C:$C,0)),"") | N8: =IFERROR(INDEX(Diccionario!$N:$N,MATCH(F8,Diccionario!$C:$C,0)),"")
A9: 2024-02 | B9: Colombia | C9: Coco Colombia | D9: COP | E9: Real | F9: utilidad_neta | I9: 177000000 | J9: COP | K9: Derivado: ingresos - egresos | L9: =IFERROR(INDEX(Diccionario!$B:$B,MATCH(F9,Diccionario!$C:$C,0)),"") | M9: =IFERROR(INDEX(Diccionario!$H:$H,MATCH(F9,Diccionario!$C:$C,0)),"") | N9: =IFERROR(INDEX(Diccionario!$N:$N,MATCH(F9,Diccionario!$C:$C,0)),"")
A10: 2024-03 | B10: Colombia | C10: Coco Colombia | D10: COP | E10: Real | F10: ingresos_totales | I10: 582000000 | J10: COP | L10: =IFERROR(INDEX(Diccionario!$B:$B,MATCH(F10,Diccionario!$C:$C,0)),"") | M10: =IFERROR(INDEX(Diccionario!$H:$H,MATCH(F10,Diccionario!$C:$C,0)),"") | N10: =IFERROR(INDEX(Diccionario!$N:$N,MATCH(F10,Diccionario!$C:$C,0)),"")
A11: 2024-03 | B11: Colombia | C11: Coco Colombia | D11: COP | E11: Real | F11: egresos_totales | I11: 571000000 | J11: COP | L11: =IFERROR(INDEX(Diccionario!$B:$B,MATCH(F11,Diccionario!$C:$C,0)),"") | M11: =IFERROR(INDEX(Diccionario!$H:$H,MATCH(F11,Diccionario!$C:$C,0)),"") | N11: =IFERROR(INDEX(Diccionario!$N:$N,MATCH(F11,Diccionario!$C:$C,0)),"")
A12: 2024-03 | B12: Colombia | C12: Coco Colombia | D12: COP | E12: Real | F12: utilidad_neta | I12: 11000000 | J12: COP | K12: Derivado: ingresos - egresos | L12: =IFERROR(INDEX(Diccionario!$B:$B,MATCH(F12,Diccionario!$C:$C,0)),"") | M12: =IFERROR(INDEX(Diccionario!$H:$H,MATCH(F12,Diccionario!$C:$C,0)),"") | N12: =IFERROR(INDEX(Diccionario!$N:$N,MATCH(F12,Diccionario!$C:$C,0)),"")
A13: 2024-04 | B13: Colombia | C13: Coco Colombia | D13: COP | E13: Real | F13: ingresos_totales | I13: 578000000 | J13: COP | L13: =IFERROR(INDEX(Diccionario!$B:$B,MATCH(F13,Diccionario!$C:$C,0)),"") | M13: =IFERROR(INDEX(Diccionario!$H:$H,MATCH(F13,Diccionario!$C:$C,0)),"") | N13: =IFERROR(INDEX(Diccionario!$N:$N,MATCH(F13,Diccionario!$C:$C,0)),"")
A14: 2024-04 | B14: Colombia | C14: Coco Colombia | D14: COP | E14: Real | F14: egresos_totales | I14: 573000000 | J14: COP | L14: =IFERROR(INDEX(Diccionario!$B:$B,MATCH(F14,Diccionario!$C:$C,0)),"") | M14: =IFERROR(INDEX(Diccionario!$H:$H,MATCH(F14,Diccionario!$C:$C,0)),"") | N14: =IFERROR(INDEX(Diccionario!$N:$N,MATCH(F14,Diccionario!$C:$C,0)),"")
A15: 2024-04 | B15: Colombia | C15: Coco Colombia | D15: COP | E15: Real | F15: utilidad_neta | I15: 5000000 | J15: COP | K15: Derivado: ingresos - egresos | L15: =IFERROR(INDEX(Diccionario!$B:$B,MATCH(F15,Diccionario!$C:$C,0)),"") | M15: =IFERROR(INDEX(Diccionario!$H:$H,MATCH(F15,Diccionario!$C:$C,0)),"") | N15: =IFERROR(INDEX(Diccionario!$N:$N,MATCH(F15,Diccionario!$C:$C,0)),"")
A16: 2024-05 | B16: Colombia | C16: Coco Colombia | D16: COP | E16: Real | F16: ingresos_totales | I16: 679000000 | J16: COP | L16: =IFERROR(INDEX(Diccionario!$B:$B,MATCH(F16,Diccionario!$C:$C,0)),"") | M16: =IFERROR(INDEX(Diccionario!$H:$H,MATCH(F16,Diccionario!$C:$C,0)),"") | N16: =IFERROR(INDEX(Diccionario!$N:$N,MATCH(F16,Diccionario!$C:$C,0)),"")
A17: 2024-05 | B17: Colombia | C17: Coco Colombia | D17: COP | E17: Real | F17: egresos_totales | I17: 574000000 | J17: COP | L17: =IFERROR(INDEX(Diccionario!$B:$B,MATCH(F17,Diccionario!$C:$C,0)),"") | M17: =IFERROR(INDEX(Diccionario!$H:$H,MATCH(F17,Diccionario!$C:$C,0)),"") | N17: =IFERROR(INDEX(Diccionario!$N:$N,MATCH(F17,Diccionario!$C:$C,0)),"")
A18: 2024-05 | B18: Colombia | C18: Coco Colombia | D18: COP | E18: Real | F18: utilidad_neta | I18: 105000000 | J18: COP | K18: Derivado: ingresos - egresos | L18: =IFERROR(INDEX(Diccionario!$B:$B,MATCH(F18,Diccionario!$C:$C,0)),"") | M18: =IFERROR(INDEX(Diccionario!$H:$H,MATCH(F18,Diccionario!$C:$C,0)),"") | N18: =IFERROR(INDEX(Diccionario!$N:$N,MATCH(F18,Diccionario!$C:$C,0)),"")
A19: 2024-06 | B19: Colombia | C19: Coco Colombia | D19: COP | E19: Real | F19: ingresos_totales | I19: 684000000 | J19: COP | L19: =IFERROR(INDEX(Diccionario!$B:$B,MATCH(F19,Diccionario!$C:$C,0)),"") | M19: =IFERROR(INDEX(Diccionario!$H:$H,MATCH(F19,Diccionario!$C:$C,0)),"") | N19: =IFERROR(INDEX(Diccionario!$N:$N,MATCH(F19,Diccionario!$C:$C,0)),"")
A20: 2024-06 | B20: Colombia | C20: Coco Colombia | D20: COP | E20: Real | F20: egresos_totales | I20: 611000000 | J20: COP | L20: =IFERROR(INDEX(Diccionario!$B:$B,MATCH(F20,Diccionario!$C:$C,0)),"") | M20: =IFERROR(INDEX(Diccionario!$H:$H,MATCH(F20,Diccionario!$C:$C,0)),"") | N20: =IFERROR(INDEX(Diccionario!$N:$N,MATCH(F20,Diccionario!$C:$C,0)),"")
A21: 2024-06 | B21: Colombia | C21: Coco Colombia | D21: COP | E21: Real | F21: utilidad_neta | I21: 73000000 | J21: COP | K21: Derivado: ingresos - egresos | L21: =IFERROR(INDEX(Diccionario!$B:$B,MATCH(F21,Diccionario!$C:$C,0)),"") | M21: =IFERROR(INDEX(Diccionario!$H:$H,MATCH(F21,Diccionario!$C:$C,0)),"") | N21: =IFERROR(INDEX(Diccionario!$N:$N,MATCH(F21,Diccionario!$C:$C,0)),"")
A22: 2024-07 | B22: Colombia | C22: Coco Colombia | D22: COP | E22: Real | F22: ingresos_totales | I22: 642000000 | J22: COP | L22: =IFERROR(INDEX(Diccionario!$B:$B,MATCH(F22,Diccionario!$C:$C,0)),"") | M22: =IFERROR(INDEX(Diccionario!$H:$H,MATCH(F22,Diccionario!$C:$C,0)),"") | N22: =IFERROR(INDEX(Diccionario!$N:$N,MATCH(F22,Diccionario!$C:$C,0)),"")
A23: 2024-07 | B23: Colombia | C23: Coco Colombia | D23: COP | E23: Real | F23: egresos_totales | I23: 555000000 | J23: COP | L23: =IFERROR(INDEX(Diccionario!$B:$B,MATCH(F23,Diccionario!$C:$C,0)),"") | M23: =IFERROR(INDEX(Diccionario!$H:$H,MATCH(F23,Diccionario!$C:$C,0)),"") | N23: =IFERROR(INDEX(Diccionario!$N:$N,MATCH(F23,Diccionario!$C:$C,0)),"")
A24: 2024-07 | B24: Colombia | C24: Coco Colombia | D24: COP | E24: Real | F24: utilidad_neta | I24: 87000000 | J24: COP | K24: Derivado: ingresos - egresos | L24: =IFERROR(INDEX(Diccionario!$B:$B,MATCH(F24,Diccionario!$C:$C,0)),"") | M24: =IFERROR(INDEX(Diccionario!$H:$H,MATCH(F24,Diccionario!$C:$C,0)),"") | N24: =IFERROR(INDEX(Diccionario!$N:$N,MATCH(F24,Diccionario!$C:$C,0)),"")
A25: 2024-08 | B25: Colombia | C25: Coco Colombia | D25: COP | E25: Real | F25: ingresos_totales | I25: 675000000 | J25: COP | L25: =IFERROR(INDEX(Diccionario!$B:$B,MATCH(F25,Diccionario!$C:$C,0)),"") | M25: =IFERROR(INDEX(Diccionario!$H:$H,MATCH(F25,Diccionario!$C:$C,0)),"") | N25: =IFERROR(INDEX(Diccionario!$N:$N,MATCH(F25,Diccionario!$C:$C,0)),"")
A26: 2024-08 | B26: Colombia | C26: Coco Colombia | D26: COP | E26: Real | F26: egresos_totales | I26: 638000000 | J26: COP | L26: =IFERROR(INDEX(Diccionario!$B:$B,MATCH(F26,Diccionario!$C:$C,0)),"") | M26: =IFERROR(INDEX(Diccionario!$H:$H,MATCH(F26,Diccionario!$C:$C,0)),"") | N26: =IFERROR(INDEX(Diccionario!$N:$N,MATCH(F26,Diccionario!$C:$C,0)),"")
A27: 2024-08 | B27: Colombia | C27: Coco Colombia | D27: COP | E27: Real | F27: utilidad_neta | I27: 37000000 | J27: COP | K27: Derivado: ingresos - egresos | L27: =IFERROR(INDEX(Diccionario!$B:$B,MATCH(F27,Diccionario!$C:$C,0)),"") | M27: =IFERROR(INDEX(Diccionario!$H:$H,MATCH(F27,Diccionario!$C:$C,0)),"") | N27: =IFERROR(INDEX(Diccionario!$N:$N,MATCH(F27,Diccionario!$C:$C,0)),"")
A28: 2024-09 | B28: Colombia | C28: Coco Colombia | D28: COP | E28: Real | F28: ingresos_totales | I28: 663000000 | J28: COP | L28: =IFERROR(INDEX(Diccionario!$B:$B,MATCH(F28,Diccionario!$C:$C,0)),"") | M28: =IFERROR(INDEX(Diccionario!$H:$H,MATCH(F28,Diccionario!$C:$C,0)),"") | N28: =IFERROR(INDEX(Diccionario!$N:$N,MATCH(F28,Diccionario!$C:$C,0)),"")
A29: 2024-09 | B29: Colombia | C29: Coco Colombia | D29: COP | E29: Real | F29: egresos_totales | I29: 679000000 | J29: COP | L29: =IFERROR(INDEX(Diccionario!$B:$B,MATCH(F29,Diccionario!$C:$C,0)),"") | M29: =IFERROR(INDEX(Diccionario!$H:$H,MATCH(F29,Diccionario!$C:$C,0)),"") | N29: =IFERROR(INDEX(Diccionario!$N:$N,MATCH(F29,Diccionario!$C:$C,0)),"")
A30: 2024-09 | B30: Colombia | C30: Coco Colombia | D30: COP | E30: Real | F30: utilidad_neta | I30: -16000000 | J30: COP | K30: Derivado: ingresos - egresos | L30: =IFERROR(INDEX(Diccionario!$B:$B,MATCH(F30,Diccionario!$C:$C,0)),"") | M30: =IFERROR(INDEX(Diccionario!$H:$H,MATCH(F30,Diccionario!$C:$C,0)),"") | N30: =IFERROR(INDEX(Diccionario!$N:$N,MATCH(F30,Diccionario!$C:$C,0)),"")
A31: 2024-10 | B31: Colombia | C31: Coco Colombia | D31: COP | E31: Real | F31: ingresos_totales | I31: 672000000 | J31: COP | L31: =IFERROR(INDEX(Diccionario!$B:$B,MATCH(F31,Diccionario!$C:$C,0)),"") | M31: =IFERROR(INDEX(Diccionario!$H:$H,MATCH(F31,Diccionario!$C:$C,0)),"") | N31: =IFERROR(INDEX(Diccionario!$N:$N,MATCH(F31,Diccionario!$C:$C,0)),"")
A32: 2024-10 | B32: Colombia | C32: Coco Colombia | D32: COP | E32: Real | F32: egresos_totales | I32: 716000000 | J32: COP | L32: =IFERROR(INDEX(Diccionario!$B:$B,MATCH(F32,Diccionario!$C:$C,0)),"") | M32: =IFERROR(INDEX(Diccionario!$H:$H,MATCH(F32,Diccionario!$C:$C,0)),"") | N32: =IFERROR(INDEX(Diccionario!$N:$N,MATCH(F32,Diccionario!$C:$C,0)),"")
A33: 2024-10 | B33: Colombia | C33: Coco Colombia | D33: COP | E33: Real | F33: utilidad_neta | I33: -44000000 | J33: COP | K33: Derivado: ingresos - egresos | L33: =IFERROR(INDEX(Diccionario!$B:$B,MATCH(F33,Diccionario!$C:$C,0)),"") | M33: =IFERROR(INDEX(Diccionario!$H:$H,MATCH(F33,Diccionario!$C:$C,0)),"") | N33: =IFERROR(INDEX(Diccionario!$N:$N,MATCH(F33,Diccionario!$C:$C,0)),"")
A34: 2024-11 | B34: Colombia | C34: Coco Colombia | D34: COP | E34: Real | F34: ingresos_totales | I34: 761000000 | J34: COP | L34: =IFERROR(INDEX(Diccionario!$B:$B,MATCH(F34,Diccionario!$C:$C,0)),"") | M34: =IFERROR(INDEX(Diccionario!$H:$H,MATCH(F34,Diccionario!$C:$C,0)),"") | N34: =IFERROR(INDEX(Diccionario!$N:$N,MATCH(F34,Diccionario!$C:$C,0)),"")
A35: 2024-11 | B35: Colombia | C35: Coco Colombia | D35: COP | E35: Real | F35: egresos_totales | I35: 740000000 | J35: COP | L35: =IFERROR(INDEX(Diccionario!$B:$B,MATCH(F35,Diccionario!$C:$C,0)),"") | M35: =IFERROR(INDEX(Diccionario!$H:$H,MATCH(F35,Diccionario!$C:$C,0)),"") | N35: =IFERROR(INDEX(Diccionario!$N:$N,MATCH(F35,Diccionario!$C:$C,0)),"")
A36: 2024-11 | B36: Colombia | C36: Coco Colombia | D36: COP | E36: Real | F36: utilidad_neta | I36: 21000000 | J36: COP | K36: Derivado: ingresos - egresos | L36: =IFERROR(INDEX(Diccionario!$B:$B,MATCH(F36,Diccionario!$C:$C,0)),"") | M36: =IFERROR(INDEX(Diccionario!$H:$H,MATCH(F36,Diccionario!$C:$C,0)),"") | N36: =IFERROR(INDEX(Diccionario!$N:$N,MATCH(F36,Diccionario!$C:$C,0)),"")
A37: 2024-12 | B37: Colombia | C37: Coco Colombia | D37: COP | E37: Real | F37: ingresos_totales | I37: 1279000000 | J37: COP | L37: =IFERROR(INDEX(Diccionario!$B:$B,MATCH(F37,Diccionario!$C:$C,0)),"") | M37: =IFERROR(INDEX(Diccionario!$H:$H,MATCH(F37,Diccionario!$C:$C,0)),"") | N37: =IFERROR(INDEX(Diccionario!$N:$N,MATCH(F37,Diccionario!$C:$C,0)),"")
A38: 2024-12 | B38: Colombia | C38: Coco Colombia | D38: COP | E38: Real | F38: egresos_totales | I38: 810000000 | J38: COP | L38: =IFERROR(INDEX(Diccionario!$B:$B,MATCH(F38,Diccionario!$C:$C,0)),"") | M38: =IFERROR(INDEX(Diccionario!$H:$H,MATCH(F38,Diccionario!$C:$C,0)),"") | N38: =IFERROR(INDEX(Diccionario!$N:$N,MATCH(F38,Diccionario!$C:$C,0)),"")
A39: 2024-12 | B39: Colombia | C39: Coco Colombia | D39: COP | E39: Real | F39: utilidad_neta | I39: 469000000 | J39: COP | K39: Derivado: ingresos - egresos | L39: =IFERROR(INDEX(Diccionario!$B:$B,MATCH(F39,Diccionario!$C:$C,0)),"") | M39: =IFERROR(INDEX(Diccionario!$H:$H,MATCH(F39,Diccionario!$C:$C,0)),"") | N39: =IFERROR(INDEX(Diccionario!$N:$N,MATCH(F39,Diccionario!$C:$C,0)),"")
A40: 2025-01 | B40: Colombia | C40: Coco Colombia | D40: COP | E40: Real | F40: ingresos_totales | I40: 504000000 | J40: COP | L40: =IFERROR(INDEX(Diccionario!$B:$B,MATCH(F40,Diccionario!$C:$C,0)),"") | M40: =IFERROR(INDEX(Diccionario!$H:$H,MATCH(F40,Diccionario!$C:$C,0)),"") | N40: =IFERROR(INDEX(Diccionario!$N:$N,MATCH(F40,Diccionario!$C:$C,0)),"")
...

Sheet TRM
A1: TRM mensual (COP por USD) — derivada de ingresos COP / ingresos USD
A2: El dashboard convierte a USD dividiendo el valor COP entre la TRM del periodo. Editable.
A3: periodo | B3: trm_cop_usd | C3: fuente | D3: trm_promedio_mercado
A4: 2024-01 | B4: 4420 | C4: Ingresos COP/USD | D4: 3915.2
A5: 2024-02 | B5: 4420 | C5: Ingresos COP/USD | D5: 3931.44
A6: 2024-03 | B6: 4420 | C6: Ingresos COP/USD | D6: 3899.34
A7: 2024-04 | B7: 4420 | C7: Ingresos COP/USD | D7: 3867.98
A8: 2024-05 | B8: 4420 | C8: Ingresos COP/USD | D8: 3869.1
A9: 2024-06 | B9: 4420 | C9: Ingresos COP/USD | D9: 4042.8
A10: 2024-07 | B10: 4420 | C10: Ingresos COP/USD | D10: 4036.92
A11: 2024-08 | B11: 4420 | C11: Ingresos COP/USD | D11: 4065.55
A12: 2024-09 | B12: 4420 | C12: Ingresos COP/USD | D12: 4182.51
A13: 2024-10 | B13: 4420 | C13: Ingresos COP/USD | D13: 4249.47
A14: 2024-11 | B14: 4420 | C14: Ingresos COP/USD | D14: 4408.65
A15: 2024-12 | B15: 4420 | C15: Ingresos COP/USD | D15: 4385.15
... A33: 2026-06 | B33: 4170 | C33: Ingresos COP/USD | D33: 3571.44
A34: 2023-07 | C34: TRM promedio mensual (mercado) | D34: 4069.23
A35: 2023-08 | C35: TRM promedio mensual (mercado) | D35: 4070.73
A36: 2023-09 | C36: TRM promedio mensual (mercado) | D36: 4004.52
A37: 2023-10 | C37: TRM promedio mensual (mercado) | D37: 4222.43
A38: 2023-11 | C38: TRM promedio mensual (mercado) | D38: 4038.8
A39: 2023-12 | C39: TRM promedio mensual (mercado) | D39: 3948.21
A40: 2026-07 | B40: 3505.2683 | C40: Base previa/impl?cita para convertir Colombia julio

Sheet TRM_Peru
A1: Tasa de cambio Perú — promedio mensual 2026 (S/ por US$)
A2: Fuente: BCRP (promedio del periodo). Julio = promedio del mes hasta la fecha (días hábiles 1–9 jul, provisional).
A4: periodo | B4: par | C4: tc_pen_usd | D4: factor_usd_pen | E4: fuente
A5: 2026-01 | B5: PEN/USD | C5: 3.357 | D5: 0.297885 | E5: BCRP promedio mensual
A6: 2026-02 | B6: PEN/USD | C6: 3.357 | D6: 0.297885 | E6: BCRP promedio mensual
A7: 2026-03 | B7: PEN/USD | C7: 3.447 | D7: 0.290107 | E7: BCRP promedio mensual
A8: 2026-04 | B8: PEN/USD | C8: 3.443 | D8: 0.290444 | E8: BCRP promedio mensual
A9: 2026-05 | B9: PEN/USD | C9: 3.435 | D9: 0.291121 | E9: BCRP promedio mensual
A10: 2026-06 | B10: PEN/USD | C10: 3.405 | D10: 0.293686 | E10: BCRP promedio mensual
A11: 2026-07* | B11: PEN/USD | C11: 3.405 | D11: 0.293686 | E11: Promedio hasta 9-jul (provisional)

Sheet Calc_LTV_Fin
A1: LTV financiero (margen bruto + churn de ingresos TTM)
A2: Cambia solo la celda amarilla (margen bruto) y LTV / payback / LTV:CAC se recalculan. Ventana TTM jun-2025 a may-2026.
A4: Margen bruto (EDITABLE) | B4: 0.51 | C4: Source: Contabilidad, may-2026
A5: ARPA mensual prom. (TTM) | B5: 8307111 | C5: Prom. ARPU mercadeo TTM
A6: Churn de ingresos mensual (TTM) | B6: 0.0102 | C6: Σchurned / Σmrr_inicio (MRR bridge)
A7: Churn de clientes mensual (TTM) | B7: 0.0117 | C7: Account Churn mercadeo (comparativo)
A8: CAC prom. trimestral (TTM) | B8: 64935810 | C8: Prom. CAC mercadeo en la ventana
A10: RESULTADOS
A11: LTV financiero (COP) | B11: =B5*B4/B6
A12: Payback financiero (meses) | B12: =B8/(B5*B4)
A13: LTV:CAC financiero (veces) | B13: =B11/B8

Sheet Analisis_Churn
A1: Análisis de Churn — Informe Contabilidad mayo 2026
A2: Valor de churn en USD. Definición de la cifra (MRR perdido vs. valor de contrato) a confirmar. Total churn = 40.131 USD.
A4: 1. Churn por razón de retiro
A5: Razón | B5: Valor USD | C5: % del total
A6: Cambio de gerente | B6: 3689 | C6: 0.0919
A7: Interoperabilidad | B7: 1381 | C7: 0.0344
A8: No agrega valor | B8: 18462 | C8: 0.46
A9: Piloto no exitoso | B9: 558 | C9: 0.0139
A10: Presupuesto | B10: 16040 | C10: 0.3997
A11: Total | B11: 40131 | C11: 1
A13: 2. Churn por factor
A14: Factor | B14: Valor USD | C14: % del total
A15: Externo | B15: 19436 | C15: 0.4843
A16: Interno | B16: 20694 | C16: 0.5157
A17: Total | B17: 40131 | C17: 1
A19: 3. Churn por tamaño de cliente
A20: Tamaño | B20: Valor USD | C20: Comparativo 'Enero'
A21: Grande | B21: 28116 | C21: 0
A22: Mediano | B22: 8720 | C22: 14164
A23: Pequeño | B23: 3294 | C23: 1731
A24: Total | B24: 40131 | C24: 15895
A26: 4. Notas y hallazgos (CS)
A27: • Salud Total representa el 40% del churn.
A28: • No gastar esfuerzo comercial en clientes con < 3.000 citas mensuales o consultorios particulares.
A29: • El churn de B2C debe medirse aparte del agendamiento.
A30: • Producto: estabilización del bot en Q1.
A31: • Campañas y mejoras para Q3.

Sheet Analisis_Reconciliacion
A1: Facturación Contable vs Ejecutada — mayo 2026 (S2)
A3: Concepto | B3: Contable (COP) | C3: Ejecutada (COP) | D3: Contable (USD) | E3: Ejecutada (USD)
A4: Ingresos operativos | B4: 826514745 | C4: 812464793 | D4: 223987.74 | E4: 220180.16
A5: Otros ingresos | B5: 1366337 | C5: 1366337 | D5: 370.28103 | E5: 370.28103
A6: Egresos | B6: 713505270 | C6: 713505270 | D6: 193361.86 | E6: 193361.86
A7: Financieros | B7: 6000847 | C7: 6000847 | D7: 1626.2458 | E7: 1626.2458
A8: Utilidad | B8: 108374965 | C8: 94325013 | D8: 29369.909 | E8: 25562.334

Sheet CATALOGOS
A1: area | B1: codigo_indicador | D1: paises | E1: escenarios | F1: monedas | G1: companias
A2: Finanzas | B2: ingresos_totales | D2: Colombia | E2: Real | F2: COP | G2: Coco Colombia
A3: Finanzas | B3: ingresos_recurrentes | D3: EE.UU. | E3: Presupuesto | F3: USD | G3: Coco LLC
A4: Finanzas | B4: ingresos_no_recurrentes | D4: Perú | E4: Modelo | G4: Coco Perú
A5: Finanzas | B5: costo_proveedor_ventas_pct | D5: Costa Rica | G5: Coco Costa Rica
A6: Finanzas | B6: ebitda | D6: Consolidado | G6: Coco Consolidado
A7: Finanzas | B7: utilidad_neta | D7: Otros
A8: Finanzas | B8: egresos_totales
A9: Finanzas | B9: burn_rate_neto
A10: Finanzas | B10: runway_meses
A11: Ingresos_MRR | B11: mrr_final
A12: Ingresos_MRR | B12: arr
A13: Ingresos_MRR | B13: arpa
A14: Ingresos_MRR | B14: retained_mrr
A15: Ingresos_MRR | B15: new_mrr
A16: Ingresos_MRR | B16: expansion_mrr
A17: Ingresos_MRR | B17: reactivacion_mrr
A18: Ingresos_MRR | B18: contraction_mrr
A19: Ingresos_MRR | B19: churned_mrr
... A66: Internacional | B66: clientes_internacionales

Sheet LOG
A1: timestamp | B1: usuario | C1: accion | D1: area | E1: hoja | F1: filas_afectadas | G1: detalle
A2: 2026-08-12T14:53:01 | B2: Codex | C2: actualizacion_bd_local | D2: Finanzas | E2: BD_MAESTRA_COCO | F2: 84 | G2: EEFF julio 2026: soporte contable, P&G Colombia mensual, bloque internacional y candidatos intercompa??a.
A3: 2026-08-12T14:55:03 | B3: Codex | C3: correccion_actualizacion_bd_local | D3: Finanzas | E3: BD_MAESTRA_COCO | F3: 84 | G3: Correcci?n: julio Colombia derivado solo con filas COP locales, excluyendo conversiones USD.
C4: Actualizaci?n final julio 2026 | G4: Base maestra actualizada con Colombia, EE.UU., Per? y Costa Rica julio; consolidado USD recalculado; CR julio agregado desde Julio 2026 CR.xlsx.
A5: 2026-08-12T17:09 | B5: Codex | C5: organizacion_base_datos | D5: Finanzas/BI | E5: BD_MAESTRA_COCO | F5: 1261 | G5: Se agregan capas BD_PYG_OFICIAL, BD_GASTOS_HOMOLOGADOS, MAP_DASHBOARD_GASTOS, BD_GASTOS_DASHBOARD_BRIDGE y DB_CHECKS_ORGANIZACION.
A6: 2026-08-12T17:11 | B6: Codex | C6: ajuste_organizacion_base | D6: Finanzas/BI | E6: BD_MAESTRA_COCO | F6: 129 | G6: Se agrega BD_GASTOS_RESUMEN_MENSUAL y se corrigen checks normalizados de cobertura julio.

Sheet Pipeline_Comercial
A1: cliente | B1: comercial | C1: tipo | D1: prob | E1: mes | F1: mrr_cop | G1: impl_cop | H1: citas | I1: valor_cop | J1: ponderado_cop

Sheet MAP_DASHBOARD_GASTOS
A1: codigo_comun | B1: rubro_comun | C1: categoria_comun | D1: indicador_dashboard | E1: detalle_dashboard | F1: area_dashboard | G1: usar_en_grafica | H1: criterio | I1: estado_mapeo
A2: PL-O-010 | B2: Gastos de personal | C2: Gastos de administraci?n | D2: gasto_admin | E2: Personal | F2: Administracion | G2: SI | H2: Administracion: personal, n?mina y beneficios | I2: Aprobado
A3: PL-O-020 | B3: Honorarios y servicios profesionales | C3: Gastos de administraci?n | D3: gasto_admin | E3: Honorarios | F3: Administracion | G3: SI | H3: Servicios profesionales administrativos | I3: Aprobado
A4: PL-O-030 | B4: Impuestos y contribuciones | C4: Gastos de administraci?n | D4: gasto_admin | E4: Diversos | F4: Administracion | G4: SI | H4: Impuestos administrativos no financieros | I4: Aprobado
A5: PL-O-040 | B5: Arrendamientos | C5: Gastos de administraci?n | D5: gasto_admin | E5: Arrendamiento | F5: Administracion | G5: SI | H5: Arrendamientos administrativos | I5: Aprobado
A6: PL-O-050 | B6: Seguros | C6: Gastos de administraci?n | D6: gasto_admin | E6: Seguros | F6: Administracion | G6: SI | H6: P?lizas y seguros | I6: Aprobado
A7: PL-O-060 | B7: Tecnolog?a y procesamiento de datos | C7: Gastos de administraci?n | D7: gasto_admin | E7: Servicios | F7: Administracion | G7: SI | H7: Servicios tecnol?gicos administrativos | I7: Aprobado
A8: PL-O-070 | B8: Telecomunicaciones | C8: Gastos de administraci?n | D8: gasto_admin | E8: Servicios | F8: Administracion | G8: SI | H8: Telecomunicaciones y conectividad | I8: Aprobado
A9: PL-O-080 | B9: Correo y mensajer?a | C9: Gastos de administraci?n | D9: gasto_admin | E9: Servicios | F9: Administracion | G9: SI | H9: Mensajer?a y correo | I9: Aprobado
A10: PL-O-090 | B10: Viajes y representaci?n | C10: Gastos de administraci?n | D10: gasto_admin | E10: Viajes | F10: Administracion | G10: SI | H10: Viajes y representaci?n | I10: Aprobado
A11: PL-O-100 | B11: Otros servicios administrativos | C11: Gastos de administraci?n | D11: gasto_admin | E11: Servicios | F11: Administracion | G11: SI | H11: Servicios administrativos no clasificados | I11: Revisar
A12: PL-O-110 | B12: Suministros y oficina | C12: Gastos de administraci?n | D12: gasto_admin | E12: Diversos | F12: Administracion | G12: SI | H12: Suministros/oficina | I12: Aprobado
... A21: PL-F-010 | B21: Gastos financieros | C21: Gastos financieros | D21: gasto_area | E21: Financieros | F21: Financieros | G21: SI | H21: Costos financieros separados | I21: Aprobado

Sheet BD_GASTOS_HOMOLOGADOS
A1: periodo | B1: pais | C1: entidad | D1: moneda | E1: codigo_comun | F1: categoria | G1: rubro_comun | H1: subrubro | I1: tercero_detalle | J1: saldo_inicial | K1: debitos | L1: creditos | M1: saldo_final_fuente | N1: saldo_presentacion_ytd | O1: movimiento_mes | P1: fuente_archivo | Q1: referencia | R1: confianza | S1: revisar | T1: fundamento
A2: 2026-04 | B2: Costa Rica | C2: CR | D2: USD | E2: PL-O-010 | F2: Gastos de administración | G2: Gastos de personal | H2: Sueldos | I2: NARANJO BUSTOS MARIAM | J2: 3600 | K2: 1200 | L2: 0 | M2: 4800 | N2: 4800 | O2: 1200 | P2: Abril 2026 CR.xlsx | Q2: Fila 28 | R2: Alta | S2: NO | T2: Remuneración laboral
A3: 2026-04 | B3: Costa Rica | C3: CR | D3: USD | E3: PL-O-090 | F3: Gastos de administración | G3: Viajes y representación | H3: Viáticos | J3: 900 | K3: 300 | L3: 0 | M3: 1200 | N3: 1200 | O3: 300 | P3: Abril 2026 CR.xlsx | Q3: Fila 30 | R3: Alta | S3: NO | T3: Viáticos administrativos
A4: 2026-04 | B4: Costa Rica | C4: CR | D4: USD | E4: PL-O-010 | F4: Gastos de administración | G4: Gastos de personal | H4: Prestaciones sociales | I4: NARANJO BUSTOS MARIAM | J4: 1212.37 | K4: 400 | L4: 0 | M4: 1612.37 | N4: 1612.37 | O4: 400 | P4: Abril 2026 CR.xlsx | Q4: Fila 32 | R4: Alta | S4: NO | T4: Prestaciones laborales
A5: 2026-04 | B5: Costa Rica | C5: CR | D5: USD | E5: PL-O-020 | F5: Gastos de administración | G5: Honorarios y servicios profesionales | H5: Asesoría jurídica | I5: MUÑOZ CHACON FRANCISCO JAVIER | J5: 270.35 | K5: 0 | L5: 0 | M5: 270.35 | N5: 270.35 | O5: 0 | P5: Abril 2026 CR.xlsx | Q5: Fila 35 | R5: Alta | S5: NO | T5: Servicio profesional jurídico
A6: 2026-04 | B6: Costa Rica | C6: CR | D6: USD | E6: PL-O-030 | F6: Gastos de administración | G6: Impuestos y contribuciones | H6: Industria, comercio y otros | I6: MINISTERIO DE HACIENDA | J6: 252.73 | K6: 0 | L6: 0 | M6: 252.73 | N6: 252.73 | O6: 0 | P6: Abril 2026 CR.xlsx | Q6: Fila 38 | R6: Alta | S6: NO | T6: Impuestos no asociados a renta
A7: 2026-04 | B7: Costa Rica | C7: CR | D7: USD | E7: PL-O-030 | F7: Gastos de administración | G7: Impuestos y contribuciones | H7: Industria, comercio y otros | I7: MINISTERIO DE HACIENDA | J7: 26.55 | K7: 115.64 | L7: 0 | M7: 142.19 | N7: 142.19 | O7: 115.64 | P7: Abril 2026 CR.xlsx | Q7: Fila 39 | R7: Alta | S7: NO | T7: Impuestos no asociados a renta
A8: 2026-04 | B8: Costa Rica | C8: CR | D8: USD | E8: PL-O-030 | F8: Gastos de administración | G8: Impuestos y contribuciones | H8: Contribuciones y afiliaciones | I8: MINISTERIO DE SALUD | J8: 64.79 | K8: 0 | L8: 0 | M8: 64.79 | N8: 64.79 | O8: 0 | P8: Abril 2026 CR.xlsx | Q8: Fila 42 | R8: Alta | S8: NO | T8: Contribuciones
A9: 2026-04 | B9: Costa Rica | C9: CR | D9: USD | E9: PL-O-050 | F9: Gastos de administración | G9: Seguros | H9: Otros seguros | I9: RADIOGRAFICA COSTARRICENSE SA | J9: 0 | K9: 9205.72 | L9: 0 | M9: 9205.72 | N9: 9205.72 | O9: 9205.72 | P9: Abril 2026 CR.xlsx | Q9: Fila 45 | R9: Media | S9: SI | T9: Cuenta fuente de seguros con descripción genérica
A10: 2026-04 | B10: Costa Rica | C10: CR | D10: USD | E10: PL-O-050 | F10: Gastos de administración | G10: Seguros | H10: Otros seguros | I10: SEGUROS INS | J10: 70.81 | K10: 0 | L10: 0 | M10: 70.81 | N10: 70.81 | O10: 0 | P10: Abril 2026 CR.xlsx | Q10: Fila 46 | R10: Media | S10: SI | T10: Cuenta fuente de seguros con descripción genérica
A11: 2026-04 | B11: Costa Rica | C11: CR | D11: USD | E11: PL-O-060 | F11: Gastos de administración | G11: Tecnología y procesamiento de datos | H11: Plataformas y software | I11: CAJA COSTARRICENSE DE SEGURO SOCIAL | J11: 0 | K11: 57.71 | L11: 0 | M11: 57.71 | N11: 57.71 | O11: 57.71 | P11: Abril 2026 CR.xlsx | Q11: Fila 49 | R11: Alta | S11: SI | T11: Revisar proveedores de telecomunicaciones registrados aquí
A12: 2026-04 | B12: Costa Rica | C12: CR | D12: USD | E12: PL-O-110 | F12: Gastos de administración | G12: Suministros y oficina | H12: Útiles, papelería y fotocopias | I12: FERRETERIA EPA S.A. | J12: 39.61 | K12: 0 | L12: 0 | M12: 39.61 | N12: 39.61 | O12: 0 | P12: Abril 2026 CR.xlsx | Q12: Fila 52 | R12: Alta | S12: NO | T12: Suministros de oficina
A13: 2026-04 | B13: Costa Rica | C13: CR | D13: USD | E13: PL-O-110 | F13: Gastos de administración | G13: Suministros y oficina | H13: Útiles, papelería y fotocopias | I13: ISTORE SAN PEDRO | J13: 74.31 | K13: 0 | L13: 0 | M13: 74.31 | N13: 74.31 | O13: 0 | P13: Abril 2026 CR.xlsx | Q13: Fila 53 | R13: Alta | S13: NO | T13: Suministros de oficina
A14: 2026-04 | B14: Costa Rica | C14: CR | D14: USD | E14: PL-O-110 | F14: Gastos de administración | G14: Suministros y oficina | H14: Útiles, papelería y fotocopias | I14: MUNDO TECNOLOGIA | J14: 15 | K14: 0 | L14: 0 | M14: 15 | N14: 15 | O14: 0 | P14: Abril 2026 CR.xlsx | Q14: Fila 54 | R14: Alta | S14: NO | T14: Suministros de oficina
A15: 2026-04 | B15: Costa Rica | C15: CR | D15: USD | E15: PL-O-110 | F15: Gastos de administración | G15: Suministros y oficina | H15: Útiles, papelería y fotocopias | I15: REGISTRO NACIONAL REPUBLICA DE COSTA RICA | J15: 7 | K15: 0 | L15: 0 | M15: 7 | N15: 7 | O15: 0 | P15: Abril 2026 CR.xlsx | Q15: Fila 55 | R15: Alta | S15: NO | T15: Suministros de oficina
... A100: 2026-01 | B100: Costa Rica | C100: CR | D100: USD | E100: PL-O-010 | F100: Gastos de administración | G100: Gastos de personal | H100: Sueldos | I100: NARANJO BUSTOS MARIAM | J100: 0 | K100: 1200 | L100: 0 | M100: 1200 | N100: 1200 | O100: 1200 | P100: Enero 2026 CR.xlsx | Q100: Fila 28 | R100: Alta | S100: NO | T100: Remuneración laboral
A101: 2026-01 | B101: Costa Rica | C101: CR | D101: USD | E101: PL-O-090 | F101: Gastos de administración | G101: Viajes y representación | H101: Viáticos | J101: 0 | K101: 300 | L101: 0 | M101: 300 | N101: 300 | O101: 300 | P101: Enero 2026 CR.xlsx | Q101: Fila 30 | R101: Alta | S101: NO | T101: Viáticos administrativos
A102: 2026-01 | B102: Costa Rica | C102: CR | D102: USD | E102: PL-O-010 | F102: Gastos de administración | G102: Gastos de personal | H102: Prestaciones sociales | I102: NARANJO BUSTOS MARIAM | J102: 0 | K102: 400 | L102: 0 | M102: 400 | N102: 400 | O102: 400 | P102: Enero 2026 CR.xlsx | Q102: Fila 32 | R102: Alta | S102: NO | T102: Prestaciones laborales
A103: 2026-01 | B103: Costa Rica | C103: CR | D103: USD | E103: PL-O-030 | F103: Gastos de administración | G103: Impuestos y contribuciones | H103: Industria, comercio y otros | I103: MINISTERIO DE HACIENDA | J103: 0 | K103: 240.73 | L103: 0 | M103: 240.73 | N103: 240.73 | O103: 240.73 | P103: Enero 2026 CR.xlsx | Q103: Fila 35 | R103: Alta | S103: NO | T103: Impuestos no asociados a renta
A104: 2026-01 | B104: Costa Rica | C104: CR | D104: USD | E104: PL-O-110 | F104: Gastos de administración | G104: Suministros y oficina | H104: Útiles, papelería y fotocopias | I104: MUNDO TECNOLOGIA | J104: 0 | K104: 15 | L104: 0 | M104: 15 | N104: 15 | O104: 15 | P104: Enero 2026 CR.xlsx | Q104: Fila 38 | R104: Alta | S104: NO | T104: Suministros de oficina
A105: 2026-01 | B105: Costa Rica | C105: CR | D105: USD | E105: PL-O-110 | F105: Gastos de administración | G105: Suministros y oficina | H105: Útiles, papelería y fotocopias | I105: REGISTRO NACIONAL REPUBLICA DE COSTA RICA | J105: 0 | K105: 7 | L105: 0 | M105: 7 | N105: 7 | O105: 7 | P105: Enero 2026 CR.xlsx | Q105: Fila 39 | R105: Alta | S105: NO | T105: Suministros de oficina
A106: 2026-01 | B106: Costa Rica | C106: CR | D106: USD | E106: PL-F-010 | F106: Gastos financieros | G106: Gastos financieros | H106: Gastos bancarios | I106: BAC CREDOMATIC | J106: 0 | K106: 20 | L106: 0 | M106: 20 | N106: 20 | O106: 20 | P106: Enero 2026 CR.xlsx | Q106: Fila 43 | R106: Alta | S106: NO | T106: Costo financiero bancario
A107: 2026-01 | B107: Peru | C107: PERU | D107: PEN | E107: PL-S-010 | F107: Gastos de ventas | G107: Honorarios comerciales y técnicos | H107: Otros honorarios | I107: HONORARIOS OTROS CONCEPTOS | J107: 0 | K107: 2127 | L107: 0 | M107: 2127 | N107: 2127 | O107: 2127 | P107: Enero 2026 PERU.xlsx | Q107: Fila 34 | R107: Media | S107: SI | T107: Cuenta genérica de honorarios de ventas
A108: 2026-01 | B108: Peru | C108: PERU | D108: PEN | E108: PL-F-010 | F108: Gastos financieros | G108: Gastos financieros | H108: Gastos bancarios | I108: GASTOS BANCARIOS | J108: 0 | K108: 11.06 | L108: 0 | M108: 11.06 | N108: 11.06 | O108: 11.06 | P108: Enero 2026 PERU.xlsx | Q108: Fila 37 | R108: Alta | S108: NO | T108: Costo financiero bancario
A109: 2026-01 | B109: Peru | C109: PERU | D109: PEN | E109: PL-F-010 | F109: Gastos financieros | G109: Gastos financieros | H109: Gastos bancarios | I109: IVA | J109: 0 | K109: 1.65 | L109: 0 | M109: 1.65 | N109: 1.65 | O109: 1.65 | P109: Enero 2026 PERU.xlsx | Q109: Fila 38 | R109: Alta | S109: NO | T109: Costo financiero bancario
A110: 2026-01 | B110: Peru | C110: PERU | D110: PEN | E110: PL-F-010 | F110: Gastos financieros | G110: Gastos financieros | H110: Gastos bancarios | I110: CUOTA MANEJO | J110: 0 | K110: 80 | L110: 0 | M110: 80 | N110: 80 | O110: 80 | P110: Enero 2026 PERU.xlsx | Q110: Fila 39 | R110: Alta | S110: NO | T110: Costo financiero bancario
A111: 2026-01 | B111: Estados Unidos | C111: USA | D111: USD | E111: PL-R-010 | F111: Ingresos operacionales | G111: Ingresos por servicios | H111: Software y agendamiento | I111: PRESTADORA DE SERVICIOS DE SALUD PREVENTIS SA | J111: 0 | K111: 0 | L111: 2830.35 | M111: -2830.35 | N111: 2830.35 | O111: 2830.35 | P111: Enero 2026 USA.xlsx | Q111: Fila 63 | R111: Alta | S111: NO | T111: Ingreso operacional principal
A112: 2026-01 | B112: Estados Unidos | C112: USA | D112: USD | E112: PL-R-010 | F112: Ingresos operacionales | G112: Ingresos por servicios | H112: Software y agendamiento | I112: SERVICIOS HOSPITALARIOS BRISAS SA | J112: 0 | K112: 0 | L112: 300 | M112: -300 | N112: 300 | O112: 300 | P112: Enero 2026 USA.xlsx | Q112: Fila 64 | R112: Alta | S112: NO | T112: Ingreso operacional principal
A113: 2026-01 | B113: Estados Unidos | C113: USA | D113: USD | E113: PL-R-010 | F113: Ingresos operacionales | G113: Ingresos por servicios | H113: Software y agendamiento | I113: ACOSTA BORBON ALEJANDRO | J113: 0 | K113: 0 | L113: 217 | M113: -217 | N113: 217 | O113: 217 | P113: Enero 2026 USA.xlsx | Q113: Fila 65 | R113: Alta | S113: NO | T113: Ingreso operacional principal
... A133: 2026-02 | B133: Costa Rica | C133: CR | D133: USD | E133: PL-O-010 | F133: Gastos de administración | G133: Gastos de personal | H133: Sueldos | I133: NARANJO BUSTOS MARIAM | J133: 2400 | K133: 1200 | L133: 0 | M133: 3600 | N133: 3600 | O133: 1200 | P133: Febrero 2026 CR.xlsx | Q133: Fila 28 | R133: Alta | S133: NO | T133: Remuneración laboral
A134: 2026-02 | B134: Costa Rica | C134: CR | D134: USD | E134: PL-O-090 | F134: Gastos de administración | G134: Viajes y representación | H134: Viáticos | J134: 600 | K134: 300 | L134: 0 | M134: 900 | N134: 900 | O134: 300 | P134: Febrero 2026 CR.xlsx | Q134: Fila 30 | R134: Alta | S134: NO | T134: Viáticos administrativos
A135: 2026-02 | B135: Costa Rica | C135: CR | D135: USD | E135: PL-O-010 | F135: Gastos de administración | G135: Gastos de personal | H135: Prestaciones sociales | I135: NARANJO BUSTOS MARIAM | J135: 812.37 | K135: 400 | L135: 0 | M135: 1212.37 | N135: 1212.37 | O135: 400 | P135: Febrero 2026 CR.xlsx | Q135: Fila 32 | R135: Alta | S135: NO | T135: Prestaciones laborales
A136: 2026-02 | B136: Costa Rica | C136: CR | D136: USD | E136: PL-O-020 | F136: Gastos de administración | G136: Honorarios y servicios profesionales | H136: Asesoría jurídica | I136: MUÑOZ CHACON FRANCISCO JAVIER | J136: 222.59 | K136: 47.76 | L136: 0 | M136: 270.35 | N136: 270.35 | O136: 47.76 | P136: Febrero 2026 CR.xlsx | Q136: Fila 35 | R136: Alta | S136: NO | T136: Servicio profesional jurídico
A137: 2026-02 | B137: Costa Rica | C137: CR | D137: USD | E137: PL-O-030 | F137: Gastos de administración | G137: Impuestos y contribuciones | H137: Industria, comercio y otros | I137: MINISTERIO DE HACIENDA | J137: 240.73 | K137: 12 | L137: 0 | M137: 252.73 | N137: 252.73 | O137: 12 | P137: Febrero 2026 CR.xlsx | Q137: Fila 38 | R137: Alta | S137: NO | T137: Impuestos no asociados a renta
A138: 2026-02 | B138: Costa Rica | C138: CR | D138: USD | E138: PL-O-030 | F138: Gastos de administración | G138: Impuestos y contribuciones | H138: Industria, comercio y otros | I138: MINISTERIO DE HACIENDA | J138: 0 | K138: 26.55 | L138: 0 | M138: 26.55 | N138: 26.55 | O138: 26.55 | P138: Febrero 2026 CR.xlsx | Q138: Fila 39 | R138: Alta | S138: NO | T138: Impuestos no asociados a renta
A139: 2026-02 | B139: Costa Rica | C139: CR | D139: USD | E139: PL-O-030 | F139: Gastos de administración | G139: Impuestos y contribuciones | H139: Contribuciones y afiliaciones | I139: MINISTERIO DE SALUD | J139: 0 | K139: 64.79 | L139: 0 | M139: 64.79 | N139: 64.79 | O139: 64.79 | P139: Febrero 2026 CR.xlsx | Q139: Fila 42 | R139: Alta | S139: NO | T139: Contribuciones
A140: 2026-02 | B140: Costa Rica | C140: CR | D140: USD | E140: PL-O-050 | F140: Gastos de administración | G140: Seguros | H140: Otros seguros | I140: SEGUROS INS | J140: 0 | K140: 70.81 | L140: 0 | M140: 70.81 | N140: 70.81 | O140: 70.81 | P140: Febrero 2026 CR.xlsx | Q140: Fila 45 | R140: Media | S140: SI | T140: Cuenta fuente de seguros con descripción genérica
A141: 2026-02 | B141: Costa Rica | C141: CR | D141: USD | E141: PL-O-110 | F141: Gastos de administración | G141: Suministros y oficina | H141: Útiles, papelería y fotocopias | I141: FERRETERIA EPA S.A. | J141: 0 | K141: 39.61 | L141: 0 | M141: 39.61 | N141: 39.61 | O141: 39.61 | P141: Febrero 2026 CR.xlsx | Q141: Fila 48 | R141: Alta | S141: NO | T141: Suministros de oficina
A142: 2026-02 | B142: Costa Rica | C142: CR | D142: USD | E142: PL-O-110 | F142: Gastos de administración | G142: Suministros y oficina | H142: Útiles, papelería y fotocopias | I142: ISTORE SAN PEDRO | J142: 0 | K142: 74.31 | L142: 0 | M142: 74.31 | N142: 74.31 | O142: 74.31 | P142: Febrero 2026 CR.xlsx | Q142: Fila 49 | R142: Alta | S142: NO | T142: Suministros de oficina
A143: 2026-02 | B143: Costa Rica | C143: CR | D143: USD | E143: PL-O-110 | F143: Gastos de administración | G143: Suministros y oficina | H143: Útiles, papelería y fotocopias | I143: MUNDO TECNOLOGIA | J143: 15 | K143: 0 | L143: 0 | M143: 15 | N143: 15 | O143: 0 | P143: Febrero 2026 CR.xlsx | Q143: Fila 50 | R143: Alta | S143: NO | T143: Suministros de oficina
...

Sheet BD_GASTOS_DASHBOARD_BRIDGE
A1: periodo | B1: pais | C1: entidad | D1: moneda | E1: codigo_comun | F1: rubro_comun | G1: indicador_dashboard | H1: detalle_dashboard | I1: area_dashboard | J1: valor_mes | K1: valor_ytd | L1: fuente | M1: calidad_mapeo | N1: nota
A2: 2026-04 | B2: Costa Rica | C2: CR | D2: USD | E2: PL-O-010 | F2: Gastos de personal | G2: gasto_admin | H2: Personal | I2: Administracion | J2: 1200 | K2: 4800 | L2: Abril 2026 CR.xlsx | M2: Aprobado | N2: Puente para redise?ar vistas de Costos & Gastos; no reemplaza P&G oficial.
A3: 2026-04 | B3: Costa Rica | C3: CR | D3: USD | E3: PL-O-090 | F3: Viajes y representación | G3: gasto_admin | H3: Viajes | I3: Administracion | J3: 300 | K3: 1200 | L3: Abril 2026 CR.xlsx | M3: Aprobado | N3: Puente para redise?ar vistas de Costos & Gastos; no reemplaza P&G oficial.
A4: 2026-04 | B4: Costa Rica | C4: CR | D4: USD | E4: PL-O-010 | F4: Gastos de personal | G4: gasto_admin | H4: Personal | I4: Administracion | J4: 400 | K4: 1612.37 | L4: Abril 2026 CR.xlsx | M4: Aprobado | N4: Puente para redise?ar vistas de Costos & Gastos; no reemplaza P&G oficial.
A5: 2026-04 | B5: Costa Rica | C5: CR | D5: USD | E5: PL-O-020 | F5: Honorarios y servicios profesionales | G5: gasto_admin | H5: Honorarios | I5: Administracion | J5: 0 | K5: 270.35 | L5: Abril 2026 CR.xlsx | M5: Aprobado | N5: Puente para redise?ar vistas de Costos & Gastos; no reemplaza P&G oficial.
A6: 2026-04 | B6: Costa Rica | C6: CR | D6: USD | E6: PL-O-030 | F6: Impuestos y contribuciones | G6: gasto_admin | H6: Diversos | I6: Administracion | J6: 0 | K6: 252.73 | L6: Abril 2026 CR.xlsx | M6: Aprobado | N6: Puente para redise?ar vistas de Costos & Gastos; no reemplaza P&G oficial.
A7: 2026-04 | B7: Costa Rica | C7: CR | D7: USD | E7: PL-O-030 | F7: Impuestos y contribuciones | G7: gasto_admin | H7: Diversos | I7: Administracion | J7: 115.64 | K7: 142.19 | L7: Abril 2026 CR.xlsx | M7: Aprobado | N7: Puente para redise?ar vistas de Costos & Gastos; no reemplaza P&G oficial.
A8: 2026-04 | B8: Costa Rica | C8: CR | D8: USD | E8: PL-O-030 | F8: Impuestos y contribuciones | G8: gasto_admin | H8: Diversos | I8: Administracion | J8: 0 | K8: 64.79 | L8: Abril 2026 CR.xlsx | M8: Aprobado | N8: Puente para redise?ar vistas de Costos & Gastos; no reemplaza P&G oficial.
A9: 2026-04 | B9: Costa Rica | C9: CR | D9: USD | E9: PL-O-050 | F9: Seguros | G9: gasto_admin | H9: Seguros | I9: Administracion | J9: 9205.72 | K9: 9205.72 | L9: Abril 2026 CR.xlsx | M9: Aprobado | N9: Puente para redise?ar vistas de Costos & Gastos; no reemplaza P&G oficial.
A10: 2026-04 | B10: Costa Rica | C10: CR | D10: USD | E10: PL-O-050 | F10: Seguros | G10: gasto_admin | H10: Seguros | I10: Administracion | J10: 0 | K10: 70.81 | L10: Abril 2026 CR.xlsx | M10: Aprobado | N10: Puente para redise?ar vistas de Costos & Gastos; no reemplaza P&G oficial.
A11: 2026-04 | B11: Costa Rica | C11: CR | D11: USD | E11: PL-O-060 | F11: Tecnología y procesamiento de datos | G11: gasto_admin | H11: Servicios | I11: Administracion | J11: 57.71 | K11: 57.71 | L11: Abril 2026 CR.xlsx | M11: Aprobado | N11: Puente para redise?ar vistas de Costos & Gastos; no reemplaza P&G oficial.
A12: 2026-04 | B12: Costa Rica | C12: CR | D12: USD | E12: PL-O-110 | F12: Suministros y oficina | G12: gasto_admin | H12: Diversos | I12: Administracion | J12: 0 | K12: 39.61 | L12: Abril 2026 CR.xlsx | M12: Aprobado | N12: Puente para redise?ar vistas de Costos & Gastos; no reemplaza P&G oficial.
A13: 2026-04 | B13: Costa Rica | C13: CR | D13: USD | E13: PL-O-110 | F13: Suministros y oficina | G13: gasto_admin | H13: Diversos | I13: Administracion | J13: 0 | K13: 74.31 | L13: Abril 2026 CR.xlsx | M13: Aprobado | N13: Puente para redise?ar vistas de Costos & Gastos; no reemplaza P&G oficial.
... A588: 2026-07 | B588: Costa Rica | C588: CR | D588: USD | E588: PL-F-010 | F588: Gastos financieros | G588: gasto_area | H588: Financieros | I588: Financieros | J588: 0 | K588: 6 | L588: Julio 2026 CR.xlsx | M588: Aprobado | N588: Puente para redise?ar vistas de Costos & Gastos; no reemplaza P&G oficial.

Sheet BD_GASTOS_RESUMEN_MENSUAL
A1: periodo | B1: pais | C1: entidad | D1: moneda | E1: indicador_dashboard | F1: detalle_dashboard | G1: area_dashboard | H1: valor_mes | I1: valor_ytd | J1: filas_fuente | K1: nota
A2: 2026-01 | B2: Costa Rica | C2: CR | D2: USD | E2: gasto_admin | F2: Diversos | G2: Administracion | H2: 262.73 | I2: 262.73 | J2: 3 | K2: Agregado desde BD_GASTOS_DASHBOARD_BRIDGE
A3: 2026-01 | B3: Costa Rica | C3: CR | D3: USD | E3: gasto_admin | F3: Personal | G3: Administracion | H3: 1600 | I3: 1600 | J3: 2 | K3: Agregado desde BD_GASTOS_DASHBOARD_BRIDGE
A4: 2026-01 | B4: Costa Rica | C4: CR | D4: USD | E4: gasto_admin | F4: Viajes | G4: Administracion | H4: 300 | I4: 300 | J4: 1 | K4: Agregado desde BD_GASTOS_DASHBOARD_BRIDGE
A5: 2026-01 | B5: Costa Rica | C5: CR | D5: USD | E5: gasto_area | F5: Financieros | G5: Financieros | H5: 20 | I5: 20 | J5: 1 | K5: Agregado desde BD_GASTOS_DASHBOARD_BRIDGE
A6: 2026-01 | B6: Estados Unidos | C6: USA | D6: USD | E6: gasto_admin | F6: Diversos | G6: Administracion | H6: 506.5 | I6: 506.5 | J6: 4 | K6: Agregado desde BD_GASTOS_DASHBOARD_BRIDGE
A7: 2026-01 | B7: Estados Unidos | C7: USA | D7: USD | E7: gasto_admin | F7: Honorarios | G7: Administracion | H7: 1500 | I7: 1500 | J7: 1 | K7: Agregado desde BD_GASTOS_DASHBOARD_BRIDGE
A8: 2026-01 | B8: Estados Unidos | C8: USA | D8: USD | E8: gasto_admin | F8: Personal | G8: Administracion | H8: 3550.43 | I8: 3550.43 | J8: 3 | K8: Agregado desde BD_GASTOS_DASHBOARD_BRIDGE
A9: 2026-01 | B9: Estados Unidos | C9: USA | D9: USD | E9: gasto_admin | F9: Servicios | G9: Administracion | H9: 281.34 | I9: 281.34 | J9: 4 | K9: Agregado desde BD_GASTOS_DASHBOARD_BRIDGE
A10: 2026-01 | B10: Estados Unidos | C10: USA | D10: USD | E10: gasto_area | F10: Financieros | G10: Financieros | H10: 75.9 | I10: 75.9 | J10: 2 | K10: Agregado desde BD_GASTOS_DASHBOARD_BRIDGE
A11: 2026-01 | B11: Estados Unidos | C11: USA | D11: USD | E11: gasto_comercial | F11: Servicios | G11: Comercial | H11: 648 | I11: 648 | J11: 1 | K11: Agregado desde BD_GASTOS_DASHBOARD_BRIDGE
A12: 2026-01 | B12: Peru | C12: PERU | D12: PEN | E12: gasto_area | F12: Financieros | G12: Financieros | H12: 92.71 | I12: 92.71 | J12: 3 | K12: Agregado desde BD_GASTOS_DASHBOARD_BRIDGE
A13: 2026-01 | B13: Peru | C13: PERU | D13: PEN | E13: gasto_comercial | F13: Honorarios | G13: Comercial | H13: 2127 | I13: 2127 | J13: 1 | K13: Agregado desde BD_GASTOS_DASHBOARD_BRIDGE
... A130: 2026-07 | B130: Peru | C130: PERU | D130: PEN | E130: gasto_comercial | F130: Viajes | G130: Comercial | H130: 7143.79 | I130: 14188.48 | J130: 24 | K130: Agregado desde BD_GASTOS_DASHBOARD_BRIDGE
