Workbook

Sheet Diccionario
A1: Diccionario de indicadores — Dashboard Ejecutivo COCO Tecnologías
A2: Catálogo único de variables. 'Origen=COCO' viene de tu archivo; 'Origen=Claude' son inputs base que las fórmulas requieren y conviene validar.
A3: ID | B3: Categoría | C3: Código indicador | D3: Nombre visible | E3: Tipo | F3: Fórmula / regla de cálculo | G3: Unidad | H3: Responsable carga | I3: Fuente sugerida | J3: Frecuencia | K3: Desglose (segmento / detalle) | L3: Origen | M3: Comentario | N3: periodicidad
A4: 1 | B4: Control | C4: periodo | D4: Periodo | E4: Dimensión | F4: Mes de reporte en formato AAAA-MM | G4: AAAA-MM | H4: Cada área | I4: Plantilla | J4: Mensual | L4: COCO | M4: Debe existir en todas las filas | N4: Mensual
A5: 2 | B5: Control | C5: pais | D5: País | E5: Dimensión | F5: País donde se genera la métrica | G5: Texto | H5: Cada área | I5: Plantilla | J5: Mensual | K5: Colombia / México / EE.UU. / Otros | L5: COCO | N5: Mensual
A6: 3 | B6: Control | C6: compania | D6: Compañía | E6: Dimensión | F6: Entidad legal o unidad de negocio | G6: Texto | H6: Finanzas | I6: Contabilidad | J6: Mensual | K6: Coco Colombia / Coco LLC / Coco Global | L6: COCO | N6: Mensual
A7: 4 | B7: Control | C7: moneda | D7: Moneda | E7: Dimensión | F7: Moneda original del dato reportado | G7: COP/USD | H7: Cada área | I7: Plantilla | J7: Mensual | K7: COP / USD | L7: COCO | M7: No mezclar monedas sin identificar | N7: Mensual
A8: 5 | B8: Control | C8: escenario | D8: Escenario | E8: Dimensión | F8: Tipo de dato reportado | G8: Texto | H8: Finanzas | I8: Plantilla | J8: Mensual | K8: Real / Budget / Forecast | L8: COCO | M8: Permite comparar real vs ppto vs forecast | N8: Mensual
A9: 7 | B9: Finanzas | C9: ingresos_one_off | D9: Ingresos one-off | E9: Input | F9: Facturación no recurrente | G9: COP/USD | H9: Ventas | I9: Facturación / contab. | J9: Mensual | K9: detalle: Implementación / Interoperabilidad / Integración / Proyectos | L9: COCO | M9: Separar de ingresos recurrentes | N9: Mensual
A10: 10 | B10: Finanzas | C10: margen_bruto | D10: Margen bruto | E10: KPI | F10: ingresos_totales - costo_directo | G10: COP/USD | H10: Finanzas | I10: Contabilidad | J10: Mensual | L10: COCO | M10: Indicador clave de escalabilidad | N10: Mensual
A11: 11 | B11: Finanzas | C11: margen_bruto_pct | D11: Margen bruto % | E11: KPI | F11: margen_bruto / ingresos_totales | G11: % | H11: Finanzas | I11: Contabilidad | J11: Mensual | L11: COCO | M11: Meta a definir con CEO | N11: Mensual
A12: 12 | B12: Finanzas | C12: gastos_totales | D12: Gastos operativos totales | E12: Input/KPI | F12: Σ gastos por área | G12: COP/USD | H12: Finanzas | I12: Contabilidad | J12: Mensual | L12: COCO | M12: Opex. Puede cargarse agregado o por área. Distinto de 'egresos_totales' | N12: Mensual
A13: 15 | B13: Finanzas | C13: egresos_totales | D13: Egresos totales | E13: Input/KPI | F13: Σ de todas las salidas del periodo (costos + gastos + financieros) | G13: COP/USD | H13: Finanzas | I13: Contabilidad | J13: Mensual | L13: COCO | M13: P&L: Ingresos - Egresos = Utilidad neta | N13: Mensual
A14: 17 | B14: Finanzas | C14: utilidad_neta | D14: Utilidad neta | E14: KPI | F14: ingresos_totales - egresos_totales | G14: COP/USD | H14: Finanzas | I14: Contabilidad | J14: Mensual | L14: COCO | M14: Resultado del P&L del periodo | N14: Mensual
A15: 13 | B15: Finanzas | C15: ebitda | D15: EBITDA | E15: KPI | F15: margen_bruto - gastos_totales | G15: COP/USD | H15: Finanzas | I15: Contabilidad | J15: Mensual | L15: COCO | M15: Métrica central del comité | N15: Mensual
A16: 14 | B16: Finanzas | C16: margen_ebitda | D16: Margen EBITDA | E16: KPI | F16: ebitda / ingresos_totales | G16: % | H16: Finanzas | I16: Contabilidad | J16: Mensual | L16: COCO | M16: Comparar contra presupuesto | N16: Mensual
A17: 16 | B17: Finanzas | C17: cobros_periodo | D17: Cobros del periodo | E17: Input | F17: Dinero efectivamente recibido de clientes | G17: COP/USD | H17: Tesorería | I17: Bancos / cartera | J17: Mensual | L17: COCO | M17: Distinto a facturación | N17: Mensual
A18: 18 | B18: Finanzas | C18: burn_rate_neto | D18: Burn rate neto | E18: KPI | F18: pagos_periodo - cobros_periodo | G18: COP/USD | H18: Finanzas | I18: Tesorería | J18: Mensual | L18: COCO | M18: Negativo = consume caja | N18: Mensual
A19: 19 | B19: Finanzas | C19: runway_meses | D19: Runway | E19: KPI | F19: caja_disponible / burn_rate_neto | G19: Meses | H19: Finanzas | I19: Tesorería | J19: Mensual | L19: COCO | M19: Solo si burn_rate_neto > 0 | N19: Mensual
A20: 21 | B20: Finanzas | C20: ppto_vs_real_ingresos | D20: Ingresos real vs presupuesto | E20: KPI | F20: (ingresos_totales Real / ingresos_totales Budget) - 1 | G20: % | H20: Finanzas | I20: Presupuesto | J20: Mensual | L20: COCO | M20: Se deriva del campo 'escenario' | N20: Mensual
A21: 22 | B21: Finanzas | C21: ppto_vs_real_gastos | D21: Gastos real vs presupuesto | E21: KPI | F21: (gastos_totales Real / gastos_totales Budget) - 1 | G21: % | H21: Finanzas | I21: Presupuesto | J21: Mensual | L21: COCO | M21: Se deriva del campo 'escenario' | N21: Mensual
... A26: 36 | B26: Ventas | C26: pipeline_ponderado | D26: Pipeline ponderado | E26: KPI | F26: Σ (valor_oportunidad * prob_cierre) | G26: COP/USD | H26: Ventas | I26: CRM | J26: Semanal/mensual | L26: COCO | M26: Más útil que pipeline bruto | N26: Mensual
A27: 37 | B27: Ventas | C27: ventas_cerradas | D27: Ventas cerradas | E27: Input | F27: Valor contratos ganados en el periodo | G27: COP/USD | H27: Ventas | I27: CRM / contratos | J27: Mensual | K27: detalle: Recurrente / One-off | L27: COCO | M27: Separar recurrente vs one-off | N27: Mensual
A28: 41 | B28: Ventas | C28: ticket_promedio | D28: Ticket promedio | E28: KPI | F28: ventas_cerradas / deals_ganados | G28: COP/USD | H28: Ventas | I28: CRM / contratos | J28: Mensual | L28: COCO | M28: Medir también por país | N28: Mensual
A29: 42 | B29: Ventas | C29: forecast_comercial | D29: Forecast comercial | E29: Input/KPI | F29: Σ (oport. con cierre esperado * prob_cierre) | G29: COP/USD | H29: Ventas | I29: CRM | J29: Semanal/mensual | L29: COCO | M29: Anticipa ingresos | N29: Mensual
A30: 43 | B30: Marketing | C30: gasto_marketing_total | D30: Gasto marketing total | E30: Input | F30: Gasto total de marketing (pauta total) | G30: COP/USD | H30: Marketing | I30: Marketing | J30: Mensual | L30: COCO | M30: Necesario para CAC. Revisar = pauta total | N30: Mensual
A31: 44 | B31: Marketing | C31: leads_generados | D31: Leads generados | E31: Input | F31: Nº de leads nuevos | G31: Número | H31: Marketing | I31: CRM / formularios | J31: Mensual | K31: detalle: por canal (opcional) | L31: COCO | M31: Separar por canal si es posible | N31: Mensual
A32: 49 | B32: Marketing | C32: cac_fully_loaded | D32: CAC fully loaded | E32: KPI | F32: (gasto_ventas_comercial + gasto_marketing_total) / clientes_nuevos | G32: COP/USD | H32: Comercial/Mktg | I32: Contab. / CRM | J32: Trimestral | L32: COCO | M32: Incluye ventas + mktg. Revisión trimestral (Andrés) | N32: Trimestral
A33: 50 | B33: Marketing | C33: ltv | D33: LTV | E33: KPI | F33: (arpa * margen_bruto_pct) / churn_ingresos_pct | G33: COP/USD | H33: Comercial/Mktg | I33: Facturación / CRM | J33: Trimestral | K33: detalle: Mercadeo (s/ingreso, churn clientes) | Financiero TTM (margen 51%, churn ingresos) | L33: COCO | M33: Vista Financiera: hoja Calc_LTV_Fin, margen editable, churn TTM | N33: Trimestral
A34: 51 | B34: Marketing | C34: ltv_cac | D34: LTV / CAC | E34: KPI | F34: ltv / cac_fully_loaded | G34: Veces | H34: Comercial/Mktg | I34: Dashboard | J34: Trimestral | K34: detalle: Mercadeo | Financiero | L34: COCO | M34: Eficiencia comercial. Difiere según vista del LTV | N34: Trimestral
A35: 52 | B35: Marketing | C35: cac_payback_meses | D35: Payback CAC | E35: KPI | F35: cac_fully_loaded / (arpa * margen_bruto_pct) | G35: Meses | H35: Comercial/Mktg | I35: Dashboard | J35: Trimestral | K35: detalle: Mercadeo (s/margen) | Financiero (c/margen) | L35: COCO | M35: Dos vistas. Revisión trimestral (Andrés) | N35: Trimestral
A36: 53 | B36: Customer Success | C36: clientes_inicio | D36: Clientes iniciales | E36: Input | F36: Clientes activos al inicio del periodo | G36: Número | H36: Comercial | I36: CRM / facturación | J36: Mensual | L36: COCO | M36: Base para churn | N36: Mensual
A37: 54 | B37: Customer Success | C37: clientes_nuevos | D37: Clientes nuevos | E37: Input | F37: Clientes ganados en el periodo | G37: Número | H37: Comercial | I37: CRM | J37: Mensual | L37: COCO | M37: Reconcilia con ventas | N37: Mensual
A38: 56 | B38: Customer Success | C38: clientes_final | D38: Clientes finales | E38: KPI | F38: clientes_inicio + clientes_nuevos - clientes_perdidos | G38: Número | H38: Comercial | I38: CRM | J38: Mensual | L38: COCO | M38: Base al cierre | N38: Mensual
A39: 57 | B39: Customer Success | C39: churn_clientes_pct | D39: Churn de clientes | E39: KPI | F39: clientes_perdidos / clientes_inicio | G39: % | H39: Comercial | I39: CRM | J39: Mensual | L39: COCO | M39: Complementa churn de ingresos | N39: Mensual
A40: 58 | B40: Customer Success | C40: clientes_en_riesgo | D40: Clientes en riesgo | E40: Input | F40: Clientes con prob. de churn según CS | G40: Número | H40: Comercial | I40: CRM / health score | J40: Mensual | L40: COCO | M40: Métrica accionable | N40: Mensual
A41: 59 | B41: Customer Success | C41: clientes_riesgo_pct | D41: % clientes en riesgo | E41: KPI | F41: clientes_en_riesgo / clientes_final | G41: % | H41: Comercial | I41: CRM | J41: Mensual | L41: COCO | M41: Alerta temprana | N41: Mensual
A42: 60 | B42: Customer Success | C42: nps | D42: NPS | E42: Input | F42: Resultado de encuesta de recomendación | G42: % | H42: CS | I42: Encuestas | J42: Mensual/trim. | K42: detalle: Promotores / Pasivos / Detractores | L42: COCO | M42: S8. Histórico completo lo envía CS | N42: Mensual
A43: 67 | B43: Internacional | C43: ingresos_internacionales | D43: Ingresos internacionales | E43: KPI | F43: Σ ingresos_totales donde país≠Colombia | G43: COP/USD | H43: Finanzas | I43: Facturación | J43: Mensual | K43: segmento: por país | L43: COCO | M43: Clave para ronda | N43: Mensual
A44: 68 | B44: Internacional | C44: mrr_internacional | D44: MRR internacional | E44: KPI | F44: Σ mrr_final donde país≠Colombia | G44: COP/USD | H44: Finanzas/Intl | I44: Facturación / CRM | J44: Mensual | K44: segmento: por país | L44: COCO | N44: Mensual
...

Sheet BD_Indicadores
A1: BD_Indicadores — tabla de hechos (formato largo). 1 fila = 1 indicador en 1 periodo y dimensiones.
A2: AAAA-MM | B2: lista | C2: lista | D2: lista | E2: lista | F2: lista (Diccionario) | G2: p.ej. Medianos | H2: p.ej. AWS / Comercial | I2: número | J2: COP/USD/%/… | K2: opcional | L2: lista (Diccionario)
A3: periodo | B3: pais | C3: compania | D3: moneda | E3: escenario | F3: codigo_indicador | G3: segmento | H3: detalle | I3: valor | J3: unidad | K3: comentario | L3: area | M3: area_responsable | N3: periodicidad
A4: 2024-01 | B4: Colombia | C4: Coco Colombia | D4: COP | E4: Real | F4: ingresos_totales | I4: 430000000 | J4: COP | L4: =IFERROR(INDEX(Diccionario!$B:$B,MATCH(F4,Diccionario!$C:$C,0)),"") | M4: =IFERROR(INDEX(Diccionario!$H:$H,MATCH(F4,Diccionario!$C:$C,0)),"") | N4: =IFERROR(INDEX(Diccionario!$N:$N,MATCH(F4,Diccionario!$C:$C,0)),"")
A5: 2024-01 | B5: Colombia | C5: Coco Colombia | D5: COP | E5: Real | F5: egresos_totales | I5: 547000000 | J5: COP | L5: =IFERROR(INDEX(Diccionario!$B:$B,MATCH(F5,Diccionario!$C:$C,0)),"") | M5: =IFERROR(INDEX(Diccionario!$H:$H,MATCH(F5,Diccionario!$C:$C,0)),"") | N5: =IFERROR(INDEX(Diccionario!$N:$N,MATCH(F5,Diccionario!$C:$C,0)),"")
A6: 2024-01 | B6: Colombia | C6: Coco Colombia | D6: COP | E6: Real | F6: utilidad_neta | I6: -117000000 | J6: COP | K6: Derivado: ingresos - egresos | L6: =IFERROR(INDEX(Diccionario!$B:$B,MATCH(F6,Diccionario!$C:$C,0)),"") | M6: =IFERROR(INDEX(Diccionario!$H:$H,MATCH(F6,Diccionario!$C:$C,0)),"") | N6: =IFERROR(INDEX(Diccionario!$N:$N,MATCH(F6,Diccionario!$C:$C,0)),"")
A7: 2024-02 | B7: Colombia | C7: Coco Colombia | D7: COP | E7: Real | F7: ingresos_totales | I7: 692000000 | J7: COP | L7: =IFERROR(INDEX(Diccionario!$B:$B,MATCH(F7,Diccionario!$C:$C,0)),"") | M7: =IFERROR(INDEX(Diccionario!$H:$H,MATCH(F7,Diccionario!$C:$C,0)),"") | N7: =IFERROR(INDEX(Diccionario!$N:$N,MATCH(F7,Diccionario!$C:$C,0)),"")
A8: 2024-02 | B8: Colombia | C8: Coco Colombia | D8: COP | E8: Real | F8: egresos_totales | I8: 515000000 | J8: COP | L8: =IFERROR(INDEX(Diccionario!$B:$B,MATCH(F8,Diccionario!$C:$C,0)),"") | M8: =IFERROR(INDEX(Diccionario!$H:$H,MATCH(F8,Diccionario!$C:$C,0)),"") | N8: =IFERROR(INDEX(Diccionario!$N:$N,MATCH(F8,Diccionario!$C:$C,0)),"")
A9: 2024-02 | B9: Colombia | C9: Coco Colombia | D9: COP | E9: Real | F9: utilidad_neta | I9: 177000000 | J9: COP | K9: Derivado: ingresos - egresos | L9: =IFERROR(INDEX(Diccionario!$B:$B,MATCH(F9,Diccionario!$C:$C,0)),"") | M9: =IFERROR(INDEX(Diccionario!$H:$H,MATCH(F9,Diccionario!$C:$C,0)),"") | N9: =IFERROR(INDEX(Diccionario!$N:$N,MATCH(F9,Diccionario!$C:$C,0)),"")
A10: 2024-03 | B10: Colombia | C10: Coco Colombia | D10: COP | E10: Real | F10: ingresos_totales | I10: 582000000 | J10: COP | L10: =IFERROR(INDEX(Diccionario!$B:$B,MATCH(F10,Diccionario!$C:$C,0)),"") | M10: =IFERROR(INDEX(Diccionario!$H:$H,MATCH(F10,Diccionario!$C:$C,0)),"") | N10: =IFERROR(INDEX(Diccionario!$N:$N,MATCH(F10,Diccionario!$C:$C,0)),"")
A11: 2024-03 | B11: Colombia | C11: Coco Colombia | D11: COP | E11: Real | F11: egresos_totales | I11: 571000000 | J11: COP | L11: =IFERROR(INDEX(Diccionario!$B:$B,MATCH(F11,Diccionario!$C:$C,0)),"") | M11: =IFERROR(INDEX(Diccionario!$H:$H,MATCH(F11,Diccionario!$C:$C,0)),"") | N11: =IFERROR(INDEX(Diccionario!$N:$N,MATCH(F11,Diccionario!$C:$C,0)),"")
A12: 2024-03 | B12: Colombia | C12: Coco Colombia | D12: COP | E12: Real | F12: utilidad_neta | I12: 11000000 | J12: COP | K12: Derivado: ingresos - egresos | L12: =IFERROR(INDEX(Diccionario!$B:$B,MATCH(F12,Diccionario!$C:$C,0)),"") | M12: =IFERROR(INDEX(Diccionario!$H:$H,MATCH(F12,Diccionario!$C:$C,0)),"") | N12: =IFERROR(INDEX(Diccionario!$N:$N,MATCH(F12,Diccionario!$C:$C,0)),"")
A13: 2024-04 | B13: Colombia | C13: Coco Colombia | D13: COP | E13: Real | F13: ingresos_totales | I13: 578000000 | J13: COP | L13: =IFERROR(INDEX(Diccionario!$B:$B,MATCH(F13,Diccionario!$C:$C,0)),"") | M13: =IFERROR(INDEX(Diccionario!$H:$H,MATCH(F13,Diccionario!$C:$C,0)),"") | N13: =IFERROR(INDEX(Diccionario!$N:$N,MATCH(F13,Diccionario!$C:$C,0)),"")
A14: 2024-04 | B14: Colombia | C14: Coco Colombia | D14: COP | E14: Real | F14: egresos_totales | I14: 573000000 | J14: COP | L14: =IFERROR(INDEX(Diccionario!$B:$B,MATCH(F14,Diccionario!$C:$C,0)),"") | M14: =IFERROR(INDEX(Diccionario!$H:$H,MATCH(F14,Diccionario!$C:$C,0)),"") | N14: =IFERROR(INDEX(Diccionario!$N:$N,MATCH(F14,Diccionario!$C:$C,0)),"")
A15: 2024-04 | B15: Colombia | C15: Coco Colombia | D15: COP | E15: Real | F15: utilidad_neta | I15: 5000000 | J15: COP | K15: Derivado: ingresos - egresos | L15: =IFERROR(INDEX(Diccionario!$B:$B,MATCH(F15,Diccionario!$C:$C,0)),"") | M15: =IFERROR(INDEX(Diccionario!$H:$H,MATCH(F15,Diccionario!$C:$C,0)),"") | N15: =IFERROR(INDEX(Diccionario!$N:$N,MATCH(F15,Diccionario!$C:$C,0)),"")
A16: 2024-05 | B16: Colombia | C16: Coco Colombia | D16: COP | E16: Real | F16: ingresos_totales | I16: 679000000 | J16: COP | L16: =IFERROR(INDEX(Diccionario!$B:$B,MATCH(F16,Diccionario!$C:$C,0)),"") | M16: =IFERROR(INDEX(Diccionario!$H:$H,MATCH(F16,Diccionario!$C:$C,0)),"") | N16: =IFERROR(INDEX(Diccionario!$N:$N,MATCH(F16,Diccionario!$C:$C,0)),"")
A17: 2024-05 | B17: Colombia | C17: Coco Colombia | D17: COP | E17: Real | F17: egresos_totales | I17: 574000000 | J17: COP | L17: =IFERROR(INDEX(Diccionario!$B:$B,MATCH(F17,Diccionario!$C:$C,0)),"") | M17: =IFERROR(INDEX(Diccionario!$H:$H,MATCH(F17,Diccionario!$C:$C,0)),"") | N17: =IFERROR(INDEX(Diccionario!$N:$N,MATCH(F17,Diccionario!$C:$C,0)),"")
A18: 2024-05 | B18: Colombia | C18: Coco Colombia | D18: COP | E18: Real | F18: utilidad_neta | I18: 105000000 | J18: COP | K18: Derivado: ingresos - egresos | L18: =IFERROR(INDEX(Diccionario!$B:$B,MATCH(F18,Diccionario!$C:$C,0)),"") | M18: =IFERROR(INDEX(Diccionario!$H:$H,MATCH(F18,Diccionario!$C:$C,0)),"") | N18: =IFERROR(INDEX(Diccionario!$N:$N,MATCH(F18,Diccionario!$C:$C,0)),"")
A19: 2024-06 | B19: Colombia | C19: Coco Colombia | D19: COP | E19: Real | F19: ingresos_totales | I19: 684000000 | J19: COP | L19: =IFERROR(INDEX(Diccionario!$B:$B,MATCH(F19,Diccionario!$C:$C,0)),"") | M19: =IFERROR(INDEX(Diccionario!$H:$H,MATCH(F19,Diccionario!$C:$C,0)),"") | N19: =IFERROR(INDEX(Diccionario!$N:$N,MATCH(F19,Diccionario!$C:$C,0)),"")
A20: 2024-06 | B20: Colombia | C20: Coco Colombia | D20: COP | E20: Real | F20: egresos_totales | I20: 611000000 | J20: COP | L20: =IFERROR(INDEX(Diccionario!$B:$B,MATCH(F20,Diccionario!$C:$C,0)),"") | M20: =IFERROR(INDEX(Diccionario!$H:$H,MATCH(F20,Diccionario!$C:$C,0)),"") | N20: =IFERROR(INDEX(Diccionario!$N:$N,MATCH(F20,Diccionario!$C:$C,0)),"")
A21: 2024-06 | B21: Colombia | C21: Coco Colombia | D21: COP | E21: Real | F21: utilidad_neta | I21: 73000000 | J21: COP | K21: Derivado: ingresos - egresos | L21: =IFERROR(INDEX(Diccionario!$B:$B,MATCH(F21,Diccionario!$C:$C,0)),"") | M21: =IFERROR(INDEX(Diccionario!$H:$H,MATCH(F21,Diccionario!$C:$C,0)),"") | N21: =IFERROR(INDEX(Diccionario!$N:$N,MATCH(F21,Diccionario!$C:$C,0)),"")
A22: 2024-07 | B22: Colombia | C22: Coco Colombia | D22: COP | E22: Real | F22: ingresos_totales | I22: 642000000 | J22: COP | L22: =IFERROR(INDEX(Diccionario!$B:$B,MATCH(F22,Diccionario!$C:$C,0)),"") | M22: =IFERROR(INDEX(Diccionario!$H:$H,MATCH(F22,Diccionario!$C:$C,0)),"") | N22: =IFERROR(INDEX(Diccionario!$N:$N,MATCH(F22,Diccionario!$C:$C,0)),"")
A23: 2024-07 | B23: Colombia | C23: Coco Colombia | D23: COP | E23: Real | F23: egresos_totales | I23: 555000000 | J23: COP | L23: =IFERROR(INDEX(Diccionario!$B:$B,MATCH(F23,Diccionario!$C:$C,0)),"") | M23: =IFERROR(INDEX(Diccionario!$H:$H,MATCH(F23,Diccionario!$C:$C,0)),"") | N23: =IFERROR(INDEX(Diccionario!$N:$N,MATCH(F23,Diccionario!$C:$C,0)),"")
A24: 2024-07 | B24: Colombia | C24: Coco Colombia | D24: COP | E24: Real | F24: utilidad_neta | I24: 87000000 | J24: COP | K24: Derivado: ingresos - egresos | L24: =IFERROR(INDEX(Diccionario!$B:$B,MATCH(F24,Diccionario!$C:$C,0)),"") | M24: =IFERROR(INDEX(Diccionario!$H:$H,MATCH(F24,Diccionario!$C:$C,0)),"") | N24: =IFERROR(INDEX(Diccionario!$N:$N,MATCH(F24,Diccionario!$C:$C,0)),"")
A25: 2024-08 | B25: Colombia | C25: Coco Colombia | D25: COP | E25: Real | F25: ingresos_totales | I25: 675000000 | J25: COP | L25: =IFERROR(INDEX(Diccionario!$B:$B,MATCH(F25,Diccionario!$C:$C,0)),"") | M25: =IFERROR(INDEX(Diccionario!$H:$H,MATCH(F25,Diccionario!$C:$C,0)),"") | N25: =IFERROR(INDEX(Diccionario!$N:$N,MATCH(F25,Diccionario!$C:$C,0)),"")
A26: 2024-08 | B26: Colombia | C26: Coco Colombia | D26: COP | E26: Real | F26: egresos_totales | I26: 638000000 | J26: COP | L26: =IFERROR(INDEX(Diccionario!$B:$B,MATCH(F26,Diccionario!$C:$C,0)),"") | M26: =IFERROR(INDEX(Diccionario!$H:$H,MATCH(F26,Diccionario!$C:$C,0)),"") | N26: =IFERROR(INDEX(Diccionario!$N:$N,MATCH(F26,Diccionario!$C:$C,0)),"")
A27: 2024-08 | B27: Colombia | C27: Coco Colombia | D27: COP | E27: Real | F27: utilidad_neta | I27: 37000000 | J27: COP | K27: Derivado: ingresos - egresos | L27: =IFERROR(INDEX(Diccionario!$B:$B,MATCH(F27,Diccionario!$C:$C,0)),"") | M27: =IFERROR(INDEX(Diccionario!$H:$H,MATCH(F27,Diccionario!$C:$C,0)),"") | N27: =IFERROR(INDEX(Diccionario!$N:$N,MATCH(F27,Diccionario!$C:$C,0)),"")
A28: 2024-09 | B28: Colombia | C28: Coco Colombia | D28: COP | E28: Real | F28: ingresos_totales | I28: 663000000 | J28: COP | L28: =IFERROR(INDEX(Diccionario!$B:$B,MATCH(F28,Diccionario!$C:$C,0)),"") | M28: =IFERROR(INDEX(Diccionario!$H:$H,MATCH(F28,Diccionario!$C:$C,0)),"") | N28: =IFERROR(INDEX(Diccionario!$N:$N,MATCH(F28,Diccionario!$C:$C,0)),"")
A29: 2024-09 | B29: Colombia | C29: Coco Colombia | D29: COP | E29: Real | F29: egresos_totales | I29: 679000000 | J29: COP | L29: =IFERROR(INDEX(Diccionario!$B:$B,MATCH(F29,Diccionario!$C:$C,0)),"") | M29: =IFERROR(INDEX(Diccionario!$H:$H,MATCH(F29,Diccionario!$C:$C,0)),"") | N29: =IFERROR(INDEX(Diccionario!$N:$N,MATCH(F29,Diccionario!$C:$C,0)),"")
A30: 2024-09 | B30: Colombia | C30: Coco Colombia | D30: COP | E30: Real | F30: utilidad_neta | I30: -16000000 | J30: COP | K30: Derivado: ingresos - egresos | L30: =IFERROR(INDEX(Diccionario!$B:$B,MATCH(F30,Diccionario!$C:$C,0)),"") | M30: =IFERROR(INDEX(Diccionario!$H:$H,MATCH(F30,Diccionario!$C:$C,0)),"") | N30: =IFERROR(INDEX(Diccionario!$N:$N,MATCH(F30,Diccionario!$C:$C,0)),"")
A31: 2024-10 | B31: Colombia | C31: Coco Colombia | D31: COP | E31: Real | F31: ingresos_totales | I31: 672000000 | J31: COP | L31: =IFERROR(INDEX(Diccionario!$B:$B,MATCH(F31,Diccionario!$C:$C,0)),"") | M31: =IFERROR(INDEX(Diccionario!$H:$H,MATCH(F31,Diccionario!$C:$C,0)),"") | N31: =IFERROR(INDEX(Diccionario!$N:$N,MATCH(F31,Diccionario!$C:$C,0)),"")
A32: 2024-10 | B32: Colombia | C32: Coco Colombia | D32: COP | E32: Real | F32: egresos_totales | I32: 716000000 | J32: COP | L32: =IFERROR(INDEX(Diccionario!$B:$B,MATCH(F32,Diccionario!$C:$C,0)),"") | M32: =IFERROR(INDEX(Diccionario!$H:$H,MATCH(F32,Diccionario!$C:$C,0)),"") | N32: =IFERROR(INDEX(Diccionario!$N:$N,MATCH(F32,Diccionario!$C:$C,0)),"")
A33: 2024-10 | B33: Colombia | C33: Coco Colombia | D33: COP | E33: Real | F33: utilidad_neta | I33: -44000000 | J33: COP | K33: Derivado: ingresos - egresos | L33: =IFERROR(INDEX(Diccionario!$B:$B,MATCH(F33,Diccionario!$C:$C,0)),"") | M33: =IFERROR(INDEX(Diccionario!$H:$H,MATCH(F33,Diccionario!$C:$C,0)),"") | N33: =IFERROR(INDEX(Diccionario!$N:$N,MATCH(F33,Diccionario!$C:$C,0)),"")
A34: 2024-11 | B34: Colombia | C34: Coco Colombia | D34: COP | E34: Real | F34: ingresos_totales | I34: 761000000 | J34: COP | L34: =IFERROR(INDEX(Diccionario!$B:$B,MATCH(F34,Diccionario!$C:$C,0)),"") | M34: =IFERROR(INDEX(Diccionario!$H:$H,MATCH(F34,Diccionario!$C:$C,0)),"") | N34: =IFERROR(INDEX(Diccionario!$N:$N,MATCH(F34,Diccionario!$C:$C,0)),"")
A35: 2024-11 | B35: Colombia | C35: Coco Colombia | D35: COP | E35: Real | F35: egresos_totales | I35: 740000000 | J35: COP | L35: =IFERROR(INDEX(Diccionario!$B:$B,MATCH(F35,Diccionario!$C:$C,0)),"") | M35: =IFERROR(INDEX(Diccionario!$H:$H,MATCH(F35,Diccionario!$C:$C,0)),"") | N35: =IFERROR(INDEX(Diccionario!$N:$N,MATCH(F35,Diccionario!$C:$C,0)),"")
A36: 2024-11 | B36: Colombia | C36: Coco Colombia | D36: COP | E36: Real | F36: utilidad_neta | I36: 21000000 | J36: COP | K36: Derivado: ingresos - egresos | L36: =IFERROR(INDEX(Diccionario!$B:$B,MATCH(F36,Diccionario!$C:$C,0)),"") | M36: =IFERROR(INDEX(Diccionario!$H:$H,MATCH(F36,Diccionario!$C:$C,0)),"") | N36: =IFERROR(INDEX(Diccionario!$N:$N,MATCH(F36,Diccionario!$C:$C,0)),"")
A37: 2024-12 | B37: Colombia | C37: Coco Colombia | D37: COP | E37: Real | F37: ingresos_totales | I37: 1279000000 | J37: COP | L37: =IFERROR(INDEX(Diccionario!$B:$B,MATCH(F37,Diccionario!$C:$C,0)),"") | M37: =IFERROR(INDEX(Diccionario!$H:$H,MATCH(F37,Diccionario!$C:$C,0)),"") | N37: =IFERROR(INDEX(Diccionario!$N:$N,MATCH(F37,Diccionario!$C:$C,0)),"")
A38: 2024-12 | B38: Colombia | C38: Coco Colombia | D38: COP | E38: Real | F38: egresos_totales | I38: 810000000 | J38: COP | L38: =IFERROR(INDEX(Diccionario!$B:$B,MATCH(F38,Diccionario!$C:$C,0)),"") | M38: =IFERROR(INDEX(Diccionario!$H:$H,MATCH(F38,Diccionario!$C:$C,0)),"") | N38: =IFERROR(INDEX(Diccionario!$N:$N,MATCH(F38,Diccionario!$C:$C,0)),"")
A39: 2024-12 | B39: Colombia | C39: Coco Colombia | D39: COP | E39: Real | F39: utilidad_neta | I39: 469000000 | J39: COP | K39: Derivado: ingresos - egresos | L39: =IFERROR(INDEX(Diccionario!$B:$B,MATCH(F39,Diccionario!$C:$C,0)),"") | M39: =IFERROR(INDEX(Diccionario!$H:$H,MATCH(F39,Diccionario!$C:$C,0)),"") | N39: =IFERROR(INDEX(Diccionario!$N:$N,MATCH(F39,Diccionario!$C:$C,0)),"")
A40: 2025-01 | B40: Colombia | C40: Coco Colombia | D40: COP | E40: Real | F40: ingresos_totales | I40: 504000000 | J40: COP | L40: =IFERROR(INDEX(Diccionario!$B:$B,MATCH(F40,Diccionario!$C:$C,0)),"") | M40: =IFERROR(INDEX(Diccionario!$H:$H,MATCH(F40,Diccionario!$C:$C,0)),"") | N40: =IFERROR(INDEX(Diccionario!$N:$N,MATCH(F40,Diccionario!$C:$C,0)),"")
...

Sheet PyG_Mensual_Col
A1: P&G Ejecutivo Mensual — Coco Colombia 2026 (COP)
A2: Fuente: estados financieros oficiales. Julio 2026 derivado desde acumulado oficial a julio menos enero-junio.
A4: Concepto | B4: Ene | C4: Feb | D4: Mar | E4: Abr | F4: May | G4: Jun | H4: Jul
A5: Servicio de software | B5: 689690890 | C5: 744218137 | D5: 839105106 | E5: 819197300 | F5: 881948086 | G5: 929451219 | H5: 711900651
A6: (-) Devoluciones | B6: -77443189 | C6: 0 | D6: -52063919 | E6: -68329638 | F6: -55433340 | G6: -177997905 | H6: -32010099
A7: =Ingresos operacionales netos | B7: 612247701 | C7: 744218137 | D7: 787041187 | E7: 750867662 | F7: 826514746 | G7: 751453314 | H7: 679890552
A8: (-) Costo de ventas | B8: 238535794 | C8: 343308791 | D8: 455639201 | E8: 379273594 | F8: 355470523 | G8: 348477606 | H8: 321917837
A9: =Utilidad bruta | B9: 373711907 | C9: 400909346 | D9: 331401986 | E9: 371594068 | F9: 471044223 | G9: 402975708 | H9: 357972713
A10: (-) Gastos de administración | B10: 98722435 | C10: 105633472 | D10: 141811865 | E10: 114280887 | F10: 116808824 | G10: 112288693 | H10: 107932742
A11: (-) Gastos operación / proyectos | B11: 73409852 | C11: 75509638 | D11: 72217138 | E11: 122384514 | F11: 120992711 | G11: 108908060 | H11: 102936374
A12: (-) Gastos de ventas | B12: 131600259 | C12: 173632204 | D12: 139615776 | E12: 130090415 | F12: 120233213 | G12: 146803460 | H12: 117761236
A13: =Utilidad operativa | B13: 69979361 | C13: 46134032 | D13: -22242793 | E13: 4838252 | F13: 113009475 | G13: 34975495 | H13: 29342360
A14: (+) Ingresos no operacionales | B14: 597687 | C14: 13488976 | D14: -10197660 | E14: 906545 | F14: 1366339 | G14: 3920249 | H14: 718311
A15: (-) Gastos financieros | B15: 7091551 | C15: 5574093 | D15: 5497554 | E15: 5038594 | F15: 6000846 | G15: 5552094 | H15: 5353621
A16: =Utilidad neta | B16: 63485497 | C16: 54048915 | D16: -37938007 | E16: 706203 | F16: 108374968 | G16: 33343650 | H16: 24707051

Sheet Subsidiarias_PyG
A1: Estado de Resultados Subsidiarias y Consolidado ? 2026 (USD de presentaci?n; Perú convertido desde PEN)
A2: Julio 2026 actualizado con COCO Colombia, EE.UU., Per? y Costa Rica; cifras en USD de presentaci?n.
A4: periodo | B4: pais | C4: compania | D4: rubro | E4: codigo_indicador | F4: moneda | G4: valor
A5: 2026-04 | B5: EE.UU. | C5: Coco LLC | D5: Ingresos Ordinarios | E5: pyg_ingresos_operacionales | F5: USD | G5: 17616.15
A6: 2026-04 | B6: EE.UU. | C6: Coco LLC | D6: Otros Ingresos | E6: pyg_ingresos_no_operacionales | F6: USD | G6: 0
A7: 2026-04 | B7: EE.UU. | C7: Coco LLC | D7: Costo del servicio | E7: pyg_costo_ventas | F7: USD | G7: 0
A8: 2026-04 | B8: EE.UU. | C8: Coco LLC | D8: Administración | E8: pyg_gasto_administracion | F8: USD | G8: -46372.59
A9: 2026-04 | B9: EE.UU. | C9: Coco LLC | D9: Ventas | E9: pyg_gasto_ventas | F9: USD | G9: 0
A10: 2026-04 | B10: EE.UU. | C10: Coco LLC | D10: Operación | E10: pyg_gasto_proyectos | F10: USD | G10: 0
A11: 2026-04 | B11: EE.UU. | C11: Coco LLC | D11: Gastos financieros | E11: pyg_gastos_financieros | F11: USD | G11: 0
A12: 2026-04 | B12: EE.UU. | C12: Coco LLC | D12: Utilidad | E12: pyg_utilidad_neta | F12: USD | G12: -28756.44
A13: 2026-04 | B13: Perú | C13: Coco Perú | D13: Ingresos Ordinarios | E13: pyg_ingresos_operacionales | F13: USD | G13: 2988.97
A14: 2026-04 | B14: Perú | C14: Coco Perú | D14: Otros Ingresos | E14: pyg_ingresos_no_operacionales | F14: USD | G14: 0
A15: 2026-04 | B15: Perú | C15: Coco Perú | D15: Costo del servicio | E15: pyg_costo_ventas | F15: USD | G15: 0
A16: 2026-04 | B16: Perú | C16: Coco Perú | D16: Administración | E16: pyg_gasto_administracion | F16: USD | G16: 0
... A193: 2026-07 | B193: Costa Rica | C193: Coco Costa Rica | D193: Utilidad | E193: pyg_utilidad_neta | F193: USD | G193: 131027.06

Sheet PyG_Oficial
A1: P&G Oficial y Consolidación — vista de solo lectura
A2: Regenerada con EEFF julio 2026 el 2026-08-12 ? Colombia julio derivado del acumulado oficial.
A4: periodo | B4: pais | C4: compania | D4: moneda | E4: escenario | F4: codigo_indicador | G4: segmento | H4: detalle | I4: valor | J4: unidad | K4: comentario | L4: area_responsable | M4: periodicidad
A5: 2026-01 | B5: Colombia | C5: Coco Colombia | D5: COP | E5: Real | F5: pyg_costo_ventas | I5: 238535794 | J5: COP | K5: P&G ejecutivo oficial (estados financieros mensuales) | L5: Finanzas | M5: Mensual
A6: 2026-01 | B6: Colombia | C6: Coco Colombia | D6: COP | E6: Real | F6: pyg_devoluciones | I6: -77443189 | J6: COP | K6: P&G ejecutivo oficial (estados financieros mensuales) | L6: Finanzas | M6: Mensual
A7: 2026-01 | B7: Colombia | C7: Coco Colombia | D7: COP | E7: Real | F7: pyg_gasto_administracion | I7: 98722435 | J7: COP | K7: P&G ejecutivo oficial (estados financieros mensuales) | L7: Finanzas | M7: Mensual
A8: 2026-01 | B8: Colombia | C8: Coco Colombia | D8: COP | E8: Real | F8: pyg_gasto_proyectos | I8: 73409852 | J8: COP | K8: P&G ejecutivo oficial (estados financieros mensuales) | L8: Finanzas | M8: Mensual
A9: 2026-01 | B9: Colombia | C9: Coco Colombia | D9: COP | E9: Real | F9: pyg_gasto_ventas | I9: 131600259 | J9: COP | K9: P&G ejecutivo oficial (estados financieros mensuales) | L9: Finanzas | M9: Mensual
A10: 2026-01 | B10: Colombia | C10: Coco Colombia | D10: COP | E10: Real | F10: pyg_gastos_financieros | I10: 7091551 | J10: COP | K10: P&G ejecutivo oficial (estados financieros mensuales) | L10: Finanzas | M10: Mensual
A11: 2026-01 | B11: Colombia | C11: Coco Colombia | D11: COP | E11: Real | F11: pyg_ingresos_no_operacionales | I11: 597687 | J11: COP | K11: P&G ejecutivo oficial (estados financieros mensuales) | L11: Finanzas | M11: Mensual
A12: 2026-01 | B12: Colombia | C12: Coco Colombia | D12: COP | E12: Real | F12: pyg_ingresos_operacionales | I12: 612247701 | J12: COP | K12: P&G ejecutivo oficial (estados financieros mensuales) | L12: Finanzas | M12: Mensual
A13: 2026-01 | B13: Colombia | C13: Coco Colombia | D13: COP | E13: Real | F13: pyg_servicio_software | I13: 689690890 | J13: COP | K13: P&G ejecutivo oficial (estados financieros mensuales) | L13: Finanzas | M13: Mensual
A14: 2026-01 | B14: Colombia | C14: Coco Colombia | D14: COP | E14: Real | F14: pyg_utilidad_bruta | I14: 373711907 | J14: COP | K14: P&G ejecutivo oficial (estados financieros mensuales) | L14: Finanzas | M14: Mensual
A15: 2026-01 | B15: Colombia | C15: Coco Colombia | D15: COP | E15: Real | F15: pyg_utilidad_neta | I15: 63485497 | J15: COP | K15: P&G ejecutivo oficial (estados financieros mensuales) | L15: Finanzas | M15: Mensual
A16: 2026-01 | B16: Colombia | C16: Coco Colombia | D16: COP | E16: Real | F16: pyg_utilidad_operativa | I16: 69979361 | J16: COP | K16: P&G ejecutivo oficial (estados financieros mensuales) | L16: Finanzas | M16: Mensual
... A40: 2026-03 | B40: Colombia | C40: Coco Colombia | D40: COP | E40: Real | F40: pyg_utilidad_operativa | I40: -22242793 | J40: COP | K40: P&G ejecutivo oficial (estados financieros mensuales) | L40: Finanzas | M40: Mensual
A41: 2026-04 | B41: Perú | C41: Coco Perú | D41: USD | E41: Real | F41: proinnovate_gastos | G41: PROINNOVATE | I41: 6982.98 | J41: USD | K41: Programa PROINNOVATE Perú (no incluido en consolidado P&G) | L41: Finanzas | M41: Mensual
A42: 2026-04 | B42: Perú | C42: Coco Perú | D42: USD | E42: Real | F42: proinnovate_ingresos | G42: PROINNOVATE | I42: 22965.15 | J42: USD | K42: Programa PROINNOVATE Perú (no incluido en consolidado P&G) | L42: Finanzas | M42: Mensual
A43: 2026-04 | B43: Perú | C43: Coco Perú | D43: USD | E43: Real | F43: proinnovate_resultado | G43: PROINNOVATE | I43: 15982.17 | J43: USD | K43: Programa PROINNOVATE Perú (no incluido en consolidado P&G) | L43: Finanzas | M43: Mensual
A44: 2026-04 | B44: Colombia | C44: Coco Colombia | D44: COP | E44: Real | F44: pyg_costo_ventas | I44: 379273594 | J44: COP | K44: P&G ejecutivo oficial (estados financieros mensuales) | L44: Finanzas | M44: Mensual
A45: 2026-04 | B45: Colombia | C45: Coco Colombia | D45: USD | E45: Real | F45: pyg_costo_ventas | G45: Consolidación USD | I45: 104843.58 | J45: USD | K45: Consolidación subsidiarias (USD). Colombia derivado del P&G oficial / TRM del mes. | L45: Finanzas | M45: Mensual
A46: 2026-04 | B46: Consolidado | C46: Coco Consolidado | D46: USD | E46: Real | F46: pyg_costo_ventas | G46: Consolidación USD | I46: 104843.58 | J46: USD | K46: Consolidado = suma de EE.UU.+Perú+Costa Rica+Colombia (USD). | L46: Finanzas | M46: Mensual
A47: 2026-04 | B47: Costa Rica | C47: Coco Costa Rica | D47: USD | E47: Real | F47: pyg_costo_ventas | G47: Consolidación USD | I47: 0 | J47: USD | K47: Consolidación subsidiarias (USD). Colombia derivado del P&G oficial / TRM del mes. | L47: Finanzas | M47: Mensual
A48: 2026-04 | B48: EE.UU. | C48: Coco LLC | D48: USD | E48: Real | F48: pyg_costo_ventas | G48: Consolidación USD | I48: 0 | J48: USD | K48: Consolidación subsidiarias (USD). Colombia derivado del P&G oficial / TRM del mes. | L48: Finanzas | M48: Mensual
A49: 2026-04 | B49: Perú | C49: Coco Perú | D49: USD | E49: Real | F49: pyg_costo_ventas | G49: Consolidación USD | I49: 0 | J49: USD | K49: Consolidación subsidiarias (USD). Colombia derivado del P&G oficial / TRM del mes. | L49: Finanzas | M49: Mensual
A50: 2026-04 | B50: Colombia | C50: Coco Colombia | D50: COP | E50: Real | F50: pyg_devoluciones | I50: -68329638 | J50: COP | K50: P&G ejecutivo oficial (estados financieros mensuales) | L50: Finanzas | M50: Mensual
A51: 2026-04 | B51: Colombia | C51: Coco Colombia | D51: COP | E51: Real | F51: pyg_gasto_administracion | I51: 114280887 | J51: COP | K51: P&G ejecutivo oficial (estados financieros mensuales) | L51: Finanzas | M51: Mensual
A52: 2026-04 | B52: Colombia | C52: Coco Colombia | D52: USD | E52: Real | F52: pyg_gasto_administracion | G52: Consolidación USD | I52: 31590.96 | J52: USD | K52: Consolidación subsidiarias (USD). Colombia derivado del P&G oficial / TRM del mes. | L52: Finanzas | M52: Mensual
A53: 2026-04 | B53: Consolidado | C53: Coco Consolidado | D53: USD | E53: Real | F53: pyg_gasto_administracion | G53: Consolidación USD | I53: -32101.85 | J53: USD | K53: Consolidado = suma de EE.UU.+Perú+Costa Rica+Colombia (USD). | L53: Finanzas | M53: Mensual
A54: 2026-04 | B54: Costa Rica | C54: Coco Costa Rica | D54: USD | E54: Real | F54: pyg_gasto_administracion | G54: Consolidación USD | I54: -17320.22 | J54: USD | K54: Consolidación subsidiarias (USD). Colombia derivado del P&G oficial / TRM del mes. | L54: Finanzas | M54: Mensual
A55: 2026-04 | B55: EE.UU. | C55: Coco LLC | D55: USD | E55: Real | F55: pyg_gasto_administracion | G55: Consolidación USD | I55: -46372.59 | J55: USD | K55: Consolidación subsidiarias (USD). Colombia derivado del P&G oficial / TRM del mes. | L55: Finanzas | M55: Mensual
A56: 2026-04 | B56: Perú | C56: Coco Perú | D56: USD | E56: Real | F56: pyg_gasto_administracion | G56: Consolidación USD | I56: 0 | J56: USD | K56: Consolidación subsidiarias (USD). Colombia derivado del P&G oficial / TRM del mes. | L56: Finanzas | M56: Mensual
A57: 2026-04 | B57: Colombia | C57: Coco Colombia | D57: COP | E57: Real | F57: pyg_gasto_proyectos | I57: 122384514 | J57: COP | K57: P&G ejecutivo oficial (estados financieros mensuales) | L57: Finanzas | M57: Mensual
A58: 2026-04 | B58: Colombia | C58: Coco Colombia | D58: USD | E58: Real | F58: pyg_gasto_proyectos | G58: Consolidación USD | I58: 33831.07 | J58: USD | K58: Consolidación subsidiarias (USD). Colombia derivado del P&G oficial / TRM del mes. | L58: Finanzas | M58: Mensual
A59: 2026-04 | B59: Consolidado | C59: Coco Consolidado | D59: USD | E59: Real | F59: pyg_gasto_proyectos | G59: Consolidación USD | I59: 33831.07 | J59: USD | K59: Consolidado = suma de EE.UU.+Perú+Costa Rica+Colombia (USD). | L59: Finanzas | M59: Mensual
A60: 2026-04 | B60: Costa Rica | C60: Coco Costa Rica | D60: USD | E60: Real | F60: pyg_gasto_proyectos | G60: Consolidación USD | I60: 0 | J60: USD | K60: Consolidación subsidiarias (USD). Colombia derivado del P&G oficial / TRM del mes. | L60: Finanzas | M60: Mensual
A61: 2026-04 | B61: EE.UU. | C61: Coco LLC | D61: USD | E61: Real | F61: pyg_gasto_proyectos | G61: Consolidación USD | I61: 0 | J61: USD | K61: Consolidación subsidiarias (USD). Colombia derivado del P&G oficial / TRM del mes. | L61: Finanzas | M61: Mensual
A62: 2026-04 | B62: Perú | C62: Coco Perú | D62: USD | E62: Real | F62: pyg_gasto_proyectos | G62: Consolidación USD | I62: 0 | J62: USD | K62: Consolidación subsidiarias (USD). Colombia derivado del P&G oficial / TRM del mes. | L62: Finanzas | M62: Mensual
A63: 2026-04 | B63: Colombia | C63: Coco Colombia | D63: COP | E63: Real | F63: pyg_gasto_ventas | I63: 130090415 | J63: COP | K63: P&G ejecutivo oficial (estados financieros mensuales) | L63: Finanzas | M63: Mensual
A64: 2026-04 | B64: Colombia | C64: Coco Colombia | D64: USD | E64: Real | F64: pyg_gasto_ventas | G64: Consolidación USD | I64: 35961.23 | J64: USD | K64: Consolidación subsidiarias (USD). Colombia derivado del P&G oficial / TRM del mes. | L64: Finanzas | M64: Mensual
...

Sheet Finanzas
A1: Finanzas — vista de solo lectura
A2: Regenerada desde BD_Indicadores el 2026-07-13 · 186 filas · Editar en BD_Indicadores.
A4: periodo | B4: pais | C4: compania | D4: moneda | E4: escenario | F4: codigo_indicador | G4: segmento | H4: detalle | I4: valor | J4: unidad | K4: comentario | L4: area_responsable | M4: periodicidad
A5: 2023-12 | B5: Colombia | C5: Coco Colombia | E5: Real | F5: distribucion_ingresos | H5: Implementaciones | I5: 0 | J5: % | K5: Año 2023 | L5: Finanzas | M5: =IFERROR(INDEX(Diccionario!$N:$N,MATCH(F1226,Diccionario!$C:$C,0)),"")
A6: 2023-12 | B6: Colombia | C6: Coco Colombia | E6: Real | F6: distribucion_ingresos | H6: Internacional | I6: 0 | J6: % | K6: Año 2023 | L6: Finanzas | M6: =IFERROR(INDEX(Diccionario!$N:$N,MATCH(F1229,Diccionario!$C:$C,0)),"")
A7: 2023-12 | B7: Colombia | C7: Coco Colombia | E7: Real | F7: distribucion_ingresos | H7: Recurrente | I7: 84 | J7: % | K7: Año 2023 | L7: Finanzas | M7: =IFERROR(INDEX(Diccionario!$N:$N,MATCH(F1220,Diccionario!$C:$C,0)),"")
A8: 2023-12 | B8: Colombia | C8: Coco Colombia | E8: Real | F8: distribucion_ingresos | H8: Variable | I8: 16 | J8: % | K8: Año 2023 | L8: Finanzas | M8: =IFERROR(INDEX(Diccionario!$N:$N,MATCH(F1223,Diccionario!$C:$C,0)),"")
A9: 2024-01 | B9: Colombia | C9: Coco Colombia | D9: COP | E9: Real | F9: egresos_totales | I9: 547000000 | J9: COP | L9: Finanzas | M9: =IFERROR(INDEX(Diccionario!$N:$N,MATCH(F5,Diccionario!$C:$C,0)),"")
A10: 2024-01 | B10: Colombia | C10: Coco Colombia | D10: COP | E10: Real | F10: ingresos_no_recurrentes | I10: 24800000 | J10: COP | L10: Finanzas | M10: =IFERROR(INDEX(Diccionario!$N:$N,MATCH(F1055,Diccionario!$C:$C,0)),"")
A11: 2024-01 | B11: Colombia | C11: Coco Colombia | D11: COP | E11: Real | F11: ingresos_recurrentes | I11: 393759551 | J11: COP | L11: Finanzas | M11: =IFERROR(INDEX(Diccionario!$N:$N,MATCH(F1026,Diccionario!$C:$C,0)),"")
A12: 2024-01 | B12: Colombia | C12: Coco Colombia | D12: COP | E12: Real | F12: ingresos_totales | I12: 430000000 | J12: COP | L12: Finanzas | M12: =IFERROR(INDEX(Diccionario!$N:$N,MATCH(F4,Diccionario!$C:$C,0)),"")
A13: 2024-01 | B13: Colombia | C13: Coco Colombia | D13: COP | E13: Real | F13: utilidad_neta | I13: -117000000 | J13: COP | K13: Derivado: ingresos - egresos | L13: Finanzas | M13: =IFERROR(INDEX(Diccionario!$N:$N,MATCH(F6,Diccionario!$C:$C,0)),"")
A14: 2024-02 | B14: Colombia | C14: Coco Colombia | D14: COP | E14: Real | F14: egresos_totales | I14: 515000000 | J14: COP | L14: Finanzas | M14: =IFERROR(INDEX(Diccionario!$N:$N,MATCH(F8,Diccionario!$C:$C,0)),"")
A15: 2024-02 | B15: Colombia | C15: Coco Colombia | D15: COP | E15: Real | F15: ingresos_no_recurrentes | I15: 118729053 | J15: COP | L15: Finanzas | M15: =IFERROR(INDEX(Diccionario!$N:$N,MATCH(F1056,Diccionario!$C:$C,0)),"")
A16: 2024-02 | B16: Colombia | C16: Coco Colombia | D16: COP | E16: Real | F16: ingresos_recurrentes | I16: 546983304 | J16: COP | L16: Finanzas | M16: =IFERROR(INDEX(Diccionario!$N:$N,MATCH(F1027,Diccionario!$C:$C,0)),"")
A17: 2024-02 | B17: Colombia | C17: Coco Colombia | D17: COP | E17: Real | F17: ingresos_totales | I17: 692000000 | J17: COP | L17: Finanzas | M17: =IFERROR(INDEX(Diccionario!$N:$N,MATCH(F7,Diccionario!$C:$C,0)),"")
A18: 2024-02 | B18: Colombia | C18: Coco Colombia | D18: COP | E18: Real | F18: utilidad_neta | I18: 177000000 | J18: COP | K18: Derivado: ingresos - egresos | L18: Finanzas | M18: =IFERROR(INDEX(Diccionario!$N:$N,MATCH(F9,Diccionario!$C:$C,0)),"")
A19: 2024-03 | B19: Colombia | C19: Coco Colombia | D19: COP | E19: Real | F19: egresos_totales | I19: 571000000 | J19: COP | L19: Finanzas | M19: =IFERROR(INDEX(Diccionario!$N:$N,MATCH(F11,Diccionario!$C:$C,0)),"")
A20: 2024-03 | B20: Colombia | C20: Coco Colombia | D20: COP | E20: Real | F20: ingresos_no_recurrentes | I20: 12750000 | J20: COP | L20: Finanzas | M20: =IFERROR(INDEX(Diccionario!$N:$N,MATCH(F1057,Diccionario!$C:$C,0)),"")
A21: 2024-03 | B21: Colombia | C21: Coco Colombia | D21: COP | E21: Real | F21: ingresos_recurrentes | I21: 543692148 | J21: COP | L21: Finanzas | M21: =IFERROR(INDEX(Diccionario!$N:$N,MATCH(F1028,Diccionario!$C:$C,0)),"")
A22: 2024-03 | B22: Colombia | C22: Coco Colombia | D22: COP | E22: Real | F22: ingresos_totales | I22: 582000000 | J22: COP | L22: Finanzas | M22: =IFERROR(INDEX(Diccionario!$N:$N,MATCH(F10,Diccionario!$C:$C,0)),"")
A23: 2024-03 | B23: Colombia | C23: Coco Colombia | D23: COP | E23: Real | F23: utilidad_neta | I23: 11000000 | J23: COP | K23: Derivado: ingresos - egresos | L23: Finanzas | M23: =IFERROR(INDEX(Diccionario!$N:$N,MATCH(F12,Diccionario!$C:$C,0)),"")
A24: 2024-04 | B24: Colombia | C24: Coco Colombia | D24: COP | E24: Real | F24: egresos_totales | I24: 573000000 | J24: COP | L24: Finanzas | M24: =IFERROR(INDEX(Diccionario!$N:$N,MATCH(F14,Diccionario!$C:$C,0)),"")
A25: 2024-04 | B25: Colombia | C25: Coco Colombia | D25: COP | E25: Real | F25: ingresos_no_recurrentes | I25: 39644578 | J25: COP | L25: Finanzas | M25: =IFERROR(INDEX(Diccionario!$N:$N,MATCH(F1058,Diccionario!$C:$C,0)),"")
A26: 2024-04 | B26: Colombia | C26: Coco Colombia | D26: COP | E26: Real | F26: ingresos_recurrentes | I26: 529778177 | J26: COP | L26: Finanzas | M26: =IFERROR(INDEX(Diccionario!$N:$N,MATCH(F1029,Diccionario!$C:$C,0)),"")
A27: 2024-04 | B27: Colombia | C27: Coco Colombia | D27: COP | E27: Real | F27: ingresos_totales | I27: 578000000 | J27: COP | L27: Finanzas | M27: =IFERROR(INDEX(Diccionario!$N:$N,MATCH(F13,Diccionario!$C:$C,0)),"")
A28: 2024-04 | B28: Colombia | C28: Coco Colombia | D28: COP | E28: Real | F28: utilidad_neta | I28: 5000000 | J28: COP | K28: Derivado: ingresos - egresos | L28: Finanzas | M28: =IFERROR(INDEX(Diccionario!$N:$N,MATCH(F15,Diccionario!$C:$C,0)),"")
A29: 2024-05 | B29: Colombia | C29: Coco Colombia | D29: COP | E29: Real | F29: egresos_totales | I29: 574000000 | J29: COP | L29: Finanzas | M29: =IFERROR(INDEX(Diccionario!$N:$N,MATCH(F17,Diccionario!$C:$C,0)),"")
A30: 2024-05 | B30: Colombia | C30: Coco Colombia | D30: COP | E30: Real | F30: ingresos_no_recurrentes | I30: 43120258 | J30: COP | L30: Finanzas | M30: =IFERROR(INDEX(Diccionario!$N:$N,MATCH(F1059,Diccionario!$C:$C,0)),"")
A31: 2024-05 | B31: Colombia | C31: Coco Colombia | D31: COP | E31: Real | F31: ingresos_recurrentes | I31: 605227323 | J31: COP | L31: Finanzas | M31: =IFERROR(INDEX(Diccionario!$N:$N,MATCH(F1030,Diccionario!$C:$C,0)),"")
A32: 2024-05 | B32: Colombia | C32: Coco Colombia | D32: COP | E32: Real | F32: ingresos_totales | I32: 679000000 | J32: COP | L32: Finanzas | M32: =IFERROR(INDEX(Diccionario!$N:$N,MATCH(F16,Diccionario!$C:$C,0)),"")
A33: 2024-05 | B33: Colombia | C33: Coco Colombia | D33: COP | E33: Real | F33: utilidad_neta | I33: 105000000 | J33: COP | K33: Derivado: ingresos - egresos | L33: Finanzas | M33: =IFERROR(INDEX(Diccionario!$N:$N,MATCH(F18,Diccionario!$C:$C,0)),"")
A34: 2024-06 | B34: Colombia | C34: Coco Colombia | D34: COP | E34: Real | F34: egresos_totales | I34: 611000000 | J34: COP | L34: Finanzas | M34: =IFERROR(INDEX(Diccionario!$N:$N,MATCH(F20,Diccionario!$C:$C,0)),"")
A35: 2024-06 | B35: Colombia | C35: Coco Colombia | D35: COP | E35: Real | F35: ingresos_no_recurrentes | I35: 104205606 | J35: COP | L35: Finanzas | M35: =IFERROR(INDEX(Diccionario!$N:$N,MATCH(F1060,Diccionario!$C:$C,0)),"")
A36: 2024-06 | B36: Colombia | C36: Coco Colombia | D36: COP | E36: Real | F36: ingresos_recurrentes | I36: 547523725 | J36: COP | L36: Finanzas | M36: =IFERROR(INDEX(Diccionario!$N:$N,MATCH(F1031,Diccionario!$C:$C,0)),"")
A37: 2024-06 | B37: Colombia | C37: Coco Colombia | D37: COP | E37: Real | F37: ingresos_totales | I37: 684000000 | J37: COP | L37: Finanzas | M37: =IFERROR(INDEX(Diccionario!$N:$N,MATCH(F19,Diccionario!$C:$C,0)),"")
A38: 2024-06 | B38: Colombia | C38: Coco Colombia | D38: COP | E38: Real | F38: utilidad_neta | I38: 73000000 | J38: COP | K38: Derivado: ingresos - egresos | L38: Finanzas | M38: =IFERROR(INDEX(Diccionario!$N:$N,MATCH(F21,Diccionario!$C:$C,0)),"")
A39: 2024-07 | B39: Colombia | C39: Coco Colombia | D39: COP | E39: Real | F39: egresos_totales | I39: 555000000 | J39: COP | L39: Finanzas | M39: =IFERROR(INDEX(Diccionario!$N:$N,MATCH(F23,Diccionario!$C:$C,0)),"")
A40: 2024-07 | B40: Colombia | C40: Coco Colombia | D40: COP | E40: Real | F40: ingresos_no_recurrentes | I40: 38194640 | J40: COP | L40: Finanzas | M40: =IFERROR(INDEX(Diccionario!$N:$N,MATCH(F1061,Diccionario!$C:$C,0)),"")
A41: 2024-07 | B41: Colombia | C41: Coco Colombia | D41: COP | E41: Real | F41: ingresos_recurrentes | I41: 578363325 | J41: COP | L41: Finanzas | M41: =IFERROR(INDEX(Diccionario!$N:$N,MATCH(F1032,Diccionario!$C:$C,0)),"")
...

Sheet Contabilidad
A1: Contabilidad — vista de solo lectura
A2: Regenerada desde BD_Indicadores el 2026-07-13 · 1030 filas · Editar en BD_Indicadores.
A4: periodo | B4: pais | C4: compania | D4: moneda | E4: escenario | F4: codigo_indicador | G4: segmento | H4: detalle | I4: valor | J4: unidad | K4: comentario | L4: area_responsable | M4: periodicidad
A5: 2024-01 | B5: Colombia | C5: Coco Colombia | D5: COP | E5: Real | F5: costo_operacion | H5: Honorario | I5: 7000000 | J5: COP | L5: Contabilidad | M5: =IFERROR(INDEX(Diccionario!$N:$N,MATCH(F597,Diccionario!$C:$C,0)),"")
A6: 2024-01 | B6: Colombia | C6: Coco Colombia | D6: COP | E6: Real | F6: costo_operacion | H6: Personal | I6: 44000000 | J6: COP | L6: Contabilidad | M6: =IFERROR(INDEX(Diccionario!$N:$N,MATCH(F596,Diccionario!$C:$C,0)),"")
A7: 2024-01 | B7: Colombia | C7: Coco Colombia | D7: COP | E7: Real | F7: costo_operacion | H7: Servicios | I7: 5000000 | J7: COP | L7: Contabilidad | M7: =IFERROR(INDEX(Diccionario!$N:$N,MATCH(F598,Diccionario!$C:$C,0)),"")
A8: 2024-01 | B8: Colombia | C8: Coco Colombia | D8: COP | E8: Real | F8: costo_proveedor | H8: AWS | I8: 25000000 | J8: COP | L8: Contabilidad | M8: =IFERROR(INDEX(Diccionario!$N:$N,MATCH(F458,Diccionario!$C:$C,0)),"")
A9: 2024-01 | B9: Colombia | C9: Coco Colombia | D9: COP | E9: Real | F9: costo_proveedor | H9: B2Chat | I9: 1000000 | J9: COP | L9: Contabilidad | M9: =IFERROR(INDEX(Diccionario!$N:$N,MATCH(F459,Diccionario!$C:$C,0)),"")
A10: 2024-01 | B10: Colombia | C10: Coco Colombia | D10: COP | E10: Real | F10: costo_proveedor | H10: IVA | I10: 0 | J10: COP | L10: Contabilidad | M10: =IFERROR(INDEX(Diccionario!$N:$N,MATCH(F457,Diccionario!$C:$C,0)),"")
A11: 2024-01 | B11: Colombia | C11: Coco Colombia | D11: COP | E11: Real | F11: costo_proveedor | H11: Infobip | I11: 85000000 | J11: COP | L11: Contabilidad | M11: =IFERROR(INDEX(Diccionario!$N:$N,MATCH(F456,Diccionario!$C:$C,0)),"")
A12: 2024-01 | B12: Colombia | C12: Coco Colombia | D12: COP | E12: Real | F12: costo_proveedor | H12: Otros | I12: 22000000 | J12: COP | L12: Contabilidad | M12: =IFERROR(INDEX(Diccionario!$N:$N,MATCH(F460,Diccionario!$C:$C,0)),"")
A13: 2024-01 | B13: Colombia | C13: Coco Colombia | D13: COP | E13: Real | F13: gasto_admin | H13: Arrendamiento | I13: 22000000 | J13: COP | L13: Contabilidad | M13: =IFERROR(INDEX(Diccionario!$N:$N,MATCH(F256,Diccionario!$C:$C,0)),"")
A14: 2024-01 | B14: Colombia | C14: Coco Colombia | D14: COP | E14: Real | F14: gasto_admin | H14: Diversos | I14: 3000000 | J14: COP | L14: Contabilidad | M14: =IFERROR(INDEX(Diccionario!$N:$N,MATCH(F260,Diccionario!$C:$C,0)),"")
A15: 2024-01 | B15: Colombia | C15: Coco Colombia | D15: COP | E15: Real | F15: gasto_admin | H15: Honorarios | I15: 14000000 | J15: COP | L15: Contabilidad | M15: =IFERROR(INDEX(Diccionario!$N:$N,MATCH(F255,Diccionario!$C:$C,0)),"")
A16: 2024-01 | B16: Colombia | C16: Coco Colombia | D16: COP | E16: Real | F16: gasto_admin | H16: Personal | I16: 43000000 | J16: COP | L16: Contabilidad | M16: =IFERROR(INDEX(Diccionario!$N:$N,MATCH(F254,Diccionario!$C:$C,0)),"")
A17: 2024-01 | B17: Colombia | C17: Coco Colombia | D17: COP | E17: Real | F17: gasto_admin | H17: Seguros | I17: 3000000 | J17: COP | L17: Contabilidad | M17: =IFERROR(INDEX(Diccionario!$N:$N,MATCH(F257,Diccionario!$C:$C,0)),"")
A18: 2024-01 | B18: Colombia | C18: Coco Colombia | D18: COP | E18: Real | F18: gasto_admin | H18: Servicios | I18: 6000000 | J18: COP | L18: Contabilidad | M18: =IFERROR(INDEX(Diccionario!$N:$N,MATCH(F258,Diccionario!$C:$C,0)),"")
A19: 2024-01 | B19: Colombia | C19: Coco Colombia | D19: COP | E19: Real | F19: gasto_admin | H19: Viajes | I19: 20000000 | J19: COP | L19: Contabilidad | M19: =IFERROR(INDEX(Diccionario!$N:$N,MATCH(F259,Diccionario!$C:$C,0)),"")
A20: 2024-01 | B20: Colombia | C20: Coco Colombia | D20: COP | E20: Real | F20: gasto_area | H20: Administración | I20: 109000000 | J20: COP | L20: Contabilidad | M20: =IFERROR(INDEX(Diccionario!$N:$N,MATCH(F118,Diccionario!$C:$C,0)),"")
A21: 2024-01 | B21: Colombia | C21: Coco Colombia | D21: COP | E21: Real | F21: gasto_area | H21: Comercial | I21: 125000000 | J21: COP | L21: Contabilidad | M21: =IFERROR(INDEX(Diccionario!$N:$N,MATCH(F117,Diccionario!$C:$C,0)),"")
A22: 2024-01 | B22: Colombia | C22: Coco Colombia | D22: COP | E22: Real | F22: gasto_area | H22: Financieros | I22: 3000000 | J22: COP | L22: Contabilidad | M22: =IFERROR(INDEX(Diccionario!$N:$N,MATCH(F114,Diccionario!$C:$C,0)),"")
A23: 2024-01 | B23: Colombia | C23: Coco Colombia | D23: COP | E23: Real | F23: gasto_area | H23: Proveedores | I23: 133000000 | J23: COP | L23: Contabilidad | M23: =IFERROR(INDEX(Diccionario!$N:$N,MATCH(F116,Diccionario!$C:$C,0)),"")
A24: 2024-01 | B24: Colombia | C24: Coco Colombia | D24: COP | E24: Real | F24: gasto_area | H24: TI | I24: 175000000 | J24: COP | L24: Contabilidad | M24: =IFERROR(INDEX(Diccionario!$N:$N,MATCH(F115,Diccionario!$C:$C,0)),"")
A25: 2024-01 | B25: Colombia | C25: Coco Colombia | D25: COP | E25: Real | F25: gasto_comercial | H25: Diversos | I25: 6000000 | J25: COP | L25: Contabilidad | M25: =IFERROR(INDEX(Diccionario!$N:$N,MATCH(F833,Diccionario!$C:$C,0)),"")
A26: 2024-01 | B26: Colombia | C26: Coco Colombia | D26: COP | E26: Real | F26: gasto_comercial | H26: Honorario | I26: 6000000 | J26: COP | L26: Contabilidad | M26: =IFERROR(INDEX(Diccionario!$N:$N,MATCH(F829,Diccionario!$C:$C,0)),"")
A27: 2024-01 | B27: Colombia | C27: Coco Colombia | D27: COP | E27: Real | F27: gasto_comercial | H27: Personal | I27: 85000000 | J27: COP | L27: Contabilidad | M27: =IFERROR(INDEX(Diccionario!$N:$N,MATCH(F828,Diccionario!$C:$C,0)),"")
A28: 2024-01 | B28: Colombia | C28: Coco Colombia | D28: COP | E28: Real | F28: gasto_comercial | H28: Seguros | I28: 3000000 | J28: COP | L28: Contabilidad | M28: =IFERROR(INDEX(Diccionario!$N:$N,MATCH(F830,Diccionario!$C:$C,0)),"")
A29: 2024-01 | B29: Colombia | C29: Coco Colombia | D29: COP | E29: Real | F29: gasto_comercial | H29: Servicios | I29: 17000000 | J29: COP | L29: Contabilidad | M29: =IFERROR(INDEX(Diccionario!$N:$N,MATCH(F831,Diccionario!$C:$C,0)),"")
A30: 2024-01 | B30: Colombia | C30: Coco Colombia | D30: COP | E30: Real | F30: gasto_comercial | H30: Viajes | I30: 10000000 | J30: COP | L30: Contabilidad | M30: =IFERROR(INDEX(Diccionario!$N:$N,MATCH(F832,Diccionario!$C:$C,0)),"")
A31: 2024-01 | B31: Colombia | C31: Coco Colombia | D31: COP | E31: Real | F31: gasto_desarrollo | H31: Honorarios | I31: 6000000 | J31: COP | L31: Contabilidad | M31: =IFERROR(INDEX(Diccionario!$N:$N,MATCH(F717,Diccionario!$C:$C,0)),"")
A32: 2024-01 | B32: Colombia | C32: Coco Colombia | D32: COP | E32: Real | F32: gasto_desarrollo | H32: Personal | I32: 102000000 | J32: COP | L32: Contabilidad | M32: =IFERROR(INDEX(Diccionario!$N:$N,MATCH(F716,Diccionario!$C:$C,0)),"")
A33: 2024-01 | B33: Colombia | C33: Coco Colombia | D33: COP | E33: Real | F33: gasto_desarrollo | H33: Servicios | I33: 9000000 | J33: COP | L33: Contabilidad | M33: =IFERROR(INDEX(Diccionario!$N:$N,MATCH(F718,Diccionario!$C:$C,0)),"")
A34: 2024-01 | B34: Colombia | C34: Coco Colombia | D34: COP | E34: Real | F34: gasto_desarrollo | H34: Viajes | I34: 1000000 | J34: COP | L34: Contabilidad | M34: =IFERROR(INDEX(Diccionario!$N:$N,MATCH(F719,Diccionario!$C:$C,0)),"")
A35: 2024-02 | B35: Colombia | C35: Coco Colombia | D35: COP | E35: Real | F35: costo_operacion | H35: Honorario | I35: 0 | J35: COP | L35: Contabilidad | M35: =IFERROR(INDEX(Diccionario!$N:$N,MATCH(F600,Diccionario!$C:$C,0)),"")
A36: 2024-02 | B36: Colombia | C36: Coco Colombia | D36: COP | E36: Real | F36: costo_operacion | H36: Personal | I36: 45000000 | J36: COP | L36: Contabilidad | M36: =IFERROR(INDEX(Diccionario!$N:$N,MATCH(F599,Diccionario!$C:$C,0)),"")
A37: 2024-02 | B37: Colombia | C37: Coco Colombia | D37: COP | E37: Real | F37: costo_operacion | H37: Servicios | I37: 6000000 | J37: COP | L37: Contabilidad | M37: =IFERROR(INDEX(Diccionario!$N:$N,MATCH(F601,Diccionario!$C:$C,0)),"")
A38: 2024-02 | B38: Colombia | C38: Coco Colombia | D38: COP | E38: Real | F38: costo_proveedor | H38: AWS | I38: 17000000 | J38: COP | L38: Contabilidad | M38: =IFERROR(INDEX(Diccionario!$N:$N,MATCH(F463,Diccionario!$C:$C,0)),"")
A39: 2024-02 | B39: Colombia | C39: Coco Colombia | D39: COP | E39: Real | F39: costo_proveedor | H39: B2Chat | I39: 1000000 | J39: COP | L39: Contabilidad | M39: =IFERROR(INDEX(Diccionario!$N:$N,MATCH(F464,Diccionario!$C:$C,0)),"")
A40: 2024-02 | B40: Colombia | C40: Coco Colombia | D40: COP | E40: Real | F40: costo_proveedor | H40: IVA | I40: 0 | J40: COP | L40: Contabilidad | M40: =IFERROR(INDEX(Diccionario!$N:$N,MATCH(F462,Diccionario!$C:$C,0)),"")
A41: 2024-02 | B41: Colombia | C41: Coco Colombia | D41: COP | E41: Real | F41: costo_proveedor | H41: Infobip | I41: 92000000 | J41: COP | L41: Contabilidad | M41: =IFERROR(INDEX(Diccionario!$N:$N,MATCH(F461,Diccionario!$C:$C,0)),"")
...

Sheet SaaS_Revenue
A1: SaaS / Revenue — vista de solo lectura
A2: Regenerada desde BD_Indicadores el 2026-07-13 · 2 filas · Editar en BD_Indicadores.
A4: periodo | B4: pais | C4: compania | D4: moneda | E4: escenario | F4: codigo_indicador | G4: segmento | H4: detalle | I4: valor | J4: unidad | K4: comentario | L4: area_responsable | M4: periodicidad
A5: 2026-05 | B5: Colombia | C5: Coco Colombia | D5: COP | E5: Real | F5: arr | I5: 3706946282 | J5: COP | K5: 'Ventas Totales (ARR)' reportado por contabilidad | L5: Finanzas | M5: =IFERROR(INDEX(Diccionario!$N:$N,MATCH(F103,Diccionario!$C:$C,0)),"")
A6: 2026-06 | B6: Colombia | C6: Coco Colombia | D6: COP | E6: Real | F6: arr | I6: 4480477715 | J6: COP | K6: 'Ventas Totales (ARR)' reportado por contabilidad | L6: Finanzas | M6: Mensual

Sheet Ventas
A1: Ventas — vista de solo lectura
A2: Regenerada desde BD_Indicadores el 2026-07-13 · 60 filas · Editar en BD_Indicadores.
A4: periodo | B4: pais | C4: compania | D4: moneda | E4: escenario | F4: codigo_indicador | G4: segmento | H4: detalle | I4: valor | J4: unidad | K4: comentario | L4: area_responsable | M4: periodicidad
A5: 2025-05 | B5: Colombia | C5: Coco Colombia | E5: Real | F5: distribucion_facturacion_tamano | H5: Grandes | I5: 33.9 | J5: % | L5: Comercial | M5: =IFERROR(INDEX(Diccionario!$N:$N,MATCH(F1173,Diccionario!$C:$C,0)),"")
A6: 2025-05 | B6: Colombia | C6: Coco Colombia | E6: Real | F6: distribucion_facturacion_tamano | H6: Medianos | I6: 51.53 | J6: % | L6: Comercial | M6: =IFERROR(INDEX(Diccionario!$N:$N,MATCH(F1186,Diccionario!$C:$C,0)),"")
A7: 2025-05 | B7: Colombia | C7: Coco Colombia | E7: Real | F7: distribucion_facturacion_tamano | H7: Pequeños | I7: 14.57 | J7: % | L7: Comercial | M7: =IFERROR(INDEX(Diccionario!$N:$N,MATCH(F1199,Diccionario!$C:$C,0)),"")
A8: 2025-06 | B8: Colombia | C8: Coco Colombia | E8: Real | F8: distribucion_facturacion_tamano | H8: Grandes | I8: 40 | J8: % | L8: Comercial | M8: =IFERROR(INDEX(Diccionario!$N:$N,MATCH(F1174,Diccionario!$C:$C,0)),"")
A9: 2025-06 | B9: Colombia | C9: Coco Colombia | E9: Real | F9: distribucion_facturacion_tamano | H9: Medianos | I9: 56 | J9: % | L9: Comercial | M9: =IFERROR(INDEX(Diccionario!$N:$N,MATCH(F1187,Diccionario!$C:$C,0)),"")
A10: 2025-06 | B10: Colombia | C10: Coco Colombia | E10: Real | F10: distribucion_facturacion_tamano | H10: Pequeños | I10: 4 | J10: % | L10: Comercial | M10: =IFERROR(INDEX(Diccionario!$N:$N,MATCH(F1200,Diccionario!$C:$C,0)),"")
A11: 2025-07 | B11: Colombia | C11: Coco Colombia | E11: Real | F11: distribucion_facturacion_tamano | H11: Grandes | I11: 37 | J11: % | L11: Comercial | M11: =IFERROR(INDEX(Diccionario!$N:$N,MATCH(F1175,Diccionario!$C:$C,0)),"")
A12: 2025-07 | B12: Colombia | C12: Coco Colombia | E12: Real | F12: distribucion_facturacion_tamano | H12: Medianos | I12: 59 | J12: % | L12: Comercial | M12: =IFERROR(INDEX(Diccionario!$N:$N,MATCH(F1188,Diccionario!$C:$C,0)),"")
A13: 2025-07 | B13: Colombia | C13: Coco Colombia | E13: Real | F13: distribucion_facturacion_tamano | H13: Pequeños | I13: 4 | J13: % | L13: Comercial | M13: =IFERROR(INDEX(Diccionario!$N:$N,MATCH(F1201,Diccionario!$C:$C,0)),"")
A14: 2025-08 | B14: Colombia | C14: Coco Colombia | E14: Real | F14: distribucion_facturacion_tamano | H14: Grandes | I14: 37 | J14: % | L14: Comercial | M14: =IFERROR(INDEX(Diccionario!$N:$N,MATCH(F1176,Diccionario!$C:$C,0)),"")
A15: 2025-08 | B15: Colombia | C15: Coco Colombia | E15: Real | F15: distribucion_facturacion_tamano | H15: Medianos | I15: 49.6 | J15: % | L15: Comercial | M15: =IFERROR(INDEX(Diccionario!$N:$N,MATCH(F1189,Diccionario!$C:$C,0)),"")
A16: 2025-08 | B16: Colombia | C16: Coco Colombia | E16: Real | F16: distribucion_facturacion_tamano | H16: Pequeños | I16: 13.1 | J16: % | L16: Comercial | M16: =IFERROR(INDEX(Diccionario!$N:$N,MATCH(F1202,Diccionario!$C:$C,0)),"")
A17: 2025-09 | B17: Colombia | C17: Coco Colombia | E17: Real | F17: distribucion_facturacion_tamano | H17: Grandes | I17: 20.9 | J17: % | L17: Comercial | M17: =IFERROR(INDEX(Diccionario!$N:$N,MATCH(F1177,Diccionario!$C:$C,0)),"")
A18: 2025-09 | B18: Colombia | C18: Coco Colombia | E18: Real | F18: distribucion_facturacion_tamano | H18: Medianos | I18: 61.7 | J18: % | L18: Comercial | M18: =IFERROR(INDEX(Diccionario!$N:$N,MATCH(F1190,Diccionario!$C:$C,0)),"")
A19: 2025-09 | B19: Colombia | C19: Coco Colombia | E19: Real | F19: distribucion_facturacion_tamano | H19: Pequeños | I19: 17.37 | J19: % | L19: Comercial | M19: =IFERROR(INDEX(Diccionario!$N:$N,MATCH(F1203,Diccionario!$C:$C,0)),"")
A20: 2025-10 | B20: Colombia | C20: Coco Colombia | E20: Real | F20: distribucion_facturacion_tamano | H20: Grandes | I20: 21 | J20: % | L20: Comercial | M20: =IFERROR(INDEX(Diccionario!$N:$N,MATCH(F1178,Diccionario!$C:$C,0)),"")
